Workbook

Sheet 表紙
D3: ヒロセ電機株式会社
D4: 4S デジタルトランスフォーメーション・プラットフォーム構築
G7: インタフェース処理方式設計書
G12: =INDEX(改版履歴!B4:B32,COUNTA(改版履歴!B4:B32)) -> 1.1
AH31: =MAX(改版履歴!D4:D32) -> 44610
Z33: 株式会社 ＪＳＯＬ

Sheet 改版履歴
B1: 改版履歴
B3: 版数 | C3: 改版者 | D3: 改版日 | E3: 改版頁 | F3: 改版履歴
B4: 1 | C4: JSOL牟田園 | D4: 43256 | E4: - | F4: 新規作成
B5: 1.1 | C5: JSOL牟田園 | D5: 43328 | E5: 1.S3連携 2.HOPICS連携 3.中間DB連携 4.GPDMドキュメント連携 5.Hybris Marketing連携 6.Aperza連携 7.i-search連携 8.環境システム連携 10.MaxMind(GeoIP)連携 | F5: 記載が必要な方式に関して、 「通信時のエラー制御に関して」 「SCP環境でのWhitelist設定」 「■リトライ制御」 の記載を追記した。
B6: 1.2 | C6: JSOL牟田園 | D6: 43476 | E6: 1.S3連携 2.IU-Base連携 3.GPDM DB連携 4.GPDMドキュメント連携 8.環境システム連携 | F6: AWS連携基盤の導入に伴い、左記連携方式の記載を最新化。
B7: 1.3 | C7: JSOL牟田園 | D7: 43477 | E7: 11.Live Chat連携 | F7: 「11. Live Chat連携」を新規作成
B8: 1.4 | C8: JSOL辻本 | D8: 43858 | E8: 12.intra-mart連携 | F8: 4S-2030 PCN対応 「12.intra-mart連携」を新規作成
B9: 1.5 | C9: JSOL神田 | D9: 44008 | E9: 8.環境システム連携 | F9: 【4S-2322：環境証明書退避処理追加】 ・IU-Base、HOPICSの文言が存在するため修正 ※誤記修正
B10: 1.6 | C10: JSOL菊地 | D10: 44287 | E10: 参考_3.CCV2_GPDM_ネットワーク図 | F10: CCV2 Migration案件にて、ネットワーク経路が変わるため、資料追加（4S-2510）
B11: 1.7 | C11: JSOL菊地 | D11: 44311 | E11: 参考_3.CCV2_GPDM_ネットワーク図 | F11: GPDM検証環境(受入れ環境)を反映。（4S-2510）
B12: 1.8 | C12: JSOL神田 | D12: 44533 | E12: 13.Octopart連携 | F12: 【BackLog：4S-2626】 Octopart APIがV3からV4に変更したため修正
B13: 1.9 | C13: JSOL金 | D13: 44606 | E13: 14.SCPI連携 | F13: 4S-2700_MA連携方式の見直し
B14: 1.1 | C14: JSOL神田 | D14: 44610 | E14: 14.SCPI連携 | F14: 【BackLog：4S-2700_MA連携方式の見直し】 ・14.SCPI連携に「14．2．統合WEBからSCPIへの連携（画面）」の記載を追記

Sheet 1.S3連携
A1: インタフェース処理方式設計 | L1: システム名 | U1: 作成者 | AA1: 作成日 | AG1: 更新者 | AM1: 更新日
L2: =表紙!D4 -> 4S デジタルトランスフォーメーション・プラットフォーム構築 | U2: =改版履歴!C4 -> JSOL牟田園 | AA2: =改版履歴!D4 -> 43256 | AG2: =INDEX(改版履歴!C4:C32,COUNTA(改版履歴!C4:C32)) -> JSOL神田 | AM2: =INDEX(改版履歴!D4:D32,COUNTA(改版履歴!D4:D32)) -> 44610
B4: １．S3連携
C6: １．１．統合WEBからS3への連携
D7: 以下に、統合WEB から Amazon S3 へのインターフェース処理方式を図示する。
D8: 具体的なユースケースとしては、統合WEBから、Amazon S3 にファイルをアップロードする場合に当たる。
D9: 統合WEBでは、セキュリティの観点から、AWS SDK for Javaを利用する方法を採用する。
C11: （AWS SDK for Javaを利用した連携パターン）
C41: １．２．S3から統合WEBへの連携
D42: 以下に、Amazon S3 から 統合WEB へのインターフェース処理方式を図示する。
D43: 具体的なユースケースとしては、統合WEBにて、Amazon S3 からファイルをダウンロードする場合に当たる。
D44: また、Amazon S3からのファイルダウンロードに関しては、AWS SDK for Javaを利用する方法（ファイルをFileオブジェクトとして取得する） と GET URL を利用する方法（直リンクするイメージ）があるが、
D45: 統合WEBでは、セキュリティの観点から、原則、AWS SDK for Javaを利用する方法を採用する。
C48: （AWS SDK for Javaを利用した連携パターン）
C78: （GET URL を利用した連携パターン）
B108: ■リトライ制御
B109: ・ | C109: Hybris の Amazon S3 連携部品では、AWS SDK for Java の ClientConfiguration の上書きを行っていないため、
C110: ClientConfiguration の デフォルト値 にて、リトライ制御を行うものとする。
C111: ⇒ | D111: https://docs.aws.amazon.com/AWSJavaSDK/latest/javadoc/constant-values.html#com.amazonaws.ClientConfiguration.DEFAULT_CACHE_RESPONSE_METADATA
B112: ・ | C112: また、その際の connection timeout は 10,000(msec)、read timeoutは50,000(msec)、リトライ回数は1回となる。
B115: ■連携時のエラー制御に関して
B116: ・ | C116: Amazon S3 とのインターフェイス連携は、原則、AWS SDK for Java を介して行われる事となるため、
C117: 通信時のエラー制御に関しては、AWS SDK for Java の 例外処理機構に従う。
C118: ⇒ | D118: https://docs.aws.amazon.com/ja_jp/sdk-for-java/v1/developer-guide/java-dg-exceptions.html
B120: ■SCP環境でのWhitelist設定
B121: ・ | C121: amazon S3 に関しては、複数のURLパターンが存在するが、AWS SDK for Java でのリクエストURLパターンを考慮し、
C122: 以下の形式のURLをwhitelist設定するものとする。
D123: ${s3_backet_name}.s3-${s3_region}.amazonaws.com
B125: ・ | C125: 以下のWhitelist の追加を行う。
C126: <Outbound >
D127: Destination : Amazon S3, Protocol : HTTP(S)
B129: ■共通機能化候補
C130: 上述のS3連携方式の検討の結果、共通機能化の候補となる機能は、以下の通りとなる。
C132: 機能名 | M132: 機能概要 | AL132: 備考
C133: S3ファイルダウンロード機能 | M133: AWS SDK for Java（AmazonS3Client)を利用し、指定されたファイルをS3からFileオブジェクトとして取得する。 | AL133: Hybrisにも、S3 との連携をサポートする機能実装があるため、その再利用性をPOCで検証の上、アドオンの要否を検討する。
C135: S3ファイルアップロード機能 | M135: AWS SDK for Java（AmazonS3Client)を利用し、指定されたFileオブジェクトをS3 にアップロードする。 | AL135: Hybrisにも、S3 との連携をサポートする機能実装があるため、その再利用性をPOCで検証の上、アドオンの要否を検討する。

Sheet 2.IU-Base連携
A1: インタフェース処理方式設計 | L1: システム名 | U1: 作成者 | AA1: 作成日 | AG1: 更新者 | AM1: 更新日
L2: =表紙!D4 -> 4S デジタルトランスフォーメーション・プラットフォーム構築 | U2: =改版履歴!C4 -> JSOL牟田園 | AA2: =改版履歴!D4 -> 43256 | AG2: =INDEX(改版履歴!C4:C32,COUNTA(改版履歴!C4:C32)) -> JSOL神田 | AM2: =INDEX(改版履歴!D4:D32,COUNTA(改版履歴!D4:D32)) -> 44610
B4: ２．IU-Base連携
C6: ２．１．IU-Base（HOPICS）から統合WEBへの連携
D7: 以下に、IU-Base（HOPICS）から 統合WEB へのインターフェース処理方式を図示する。
D8: 具体的なユースケースとしては、統合WEBにて、HOPICS からの連携ファイルを取得する場合に当たる。
D9: 連携の実態は、AWS基盤を介した連携となる。
C12: （連携パターン）
B42: ■リトライ制御
B43: ・ | C43: Hybris の Amazon S3 連携部品では、AWS SDK for Java の ClientConfiguration の上書きを行っていないため、
C44: ClientConfiguration の デフォルト値 にて、リトライ制御を行うものとする。
C45: ⇒ | D45: https://docs.aws.amazon.com/AWSJavaSDK/latest/javadoc/constant-values.html#com.amazonaws.ClientConfiguration.DEFAULT_CACHE_RESPONSE_METADATA
B46: ・ | C46: また、その際の connection timeout は 10,000(msec)、read timeoutは50,000(msec)、リトライ回数は1回となる。
B48: ■連携時のエラー制御に関して
B49: ・ | C49: 統合WebからAmazon S3 を介したHOPICSとのインターフェイス連携は、原則、AWS SDK for Java を介して行われる事となるため、
C50: 通信時のエラー制御に関しては、AWS SDK for Java の 例外処理機構に従う。
C51: ⇒ | D51: https://docs.aws.amazon.com/ja_jp/sdk-for-java/v1/developer-guide/java-dg-exceptions.html
B52: ・ | C52: また、HOPICSからAmazon EC2へのファイルのput時にはSFTPが利用される想定である。
C53: この際、SFTP通信時のファイル欠損を検知するため、HOPICSからS3へのファイルアップロード時には、「実ファイル」と「（実ファイルのデータ行数を記載した）制御ファイル」をzipアーカイブした上でputし、
C54: 統合Webでは、制御ファイルに記載された行数と実ファイルの行数がマッチするかをチェックし、ファイルの欠損をチェックする。
B55: ・ | C55: 統合Webにて、ファイルの欠損が検知された場合には、その旨、HOPICSの担当者に連絡し、ファイルの再送を依頼する。
B57: ■SCP環境でのWhitelist設定
B58: ・ | C58: 以下のWhitelist の追加を行う。
C59: <Outbound >
D60: Destination : Amazon S3, Protocol : HTTP(S)
B62: ■共通機能化候補
C63: 上述のHOPICS連携方式の検討の結果、共通機能化の候補となる機能は、以下の通りとなる。
C65: 機能名 | M65: 機能概要 | AL65: 備考
C66: なし | M66: なし | AL66: 統合WEBとしては、S3との連携でインタフェースが実現できるため、HOPICS連携独自の共通機能は不要。

Sheet 3.GPDM DB連携
A1: インタフェース処理方式設計 | L1: システム名 | U1: 作成者 | AA1: 作成日 | AG1: 更新者 | AM1: 更新日
L2: =表紙!D4 -> 4S デジタルトランスフォーメーション・プラットフォーム構築 | U2: =改版履歴!C4 -> JSOL牟田園 | AA2: =改版履歴!D4 -> 43256 | AG2: =INDEX(改版履歴!C4:C32,COUNTA(改版履歴!C4:C32)) -> JSOL神田 | AM2: =INDEX(改版履歴!D4:D32,COUNTA(改版履歴!D4:D32)) -> 44610
B4: ３．中間DB連携
C6: ３．１．統合WEBからGPDM DBへの連携
D7: 以下に、 統合WEBから GPDM DBへ連携する際のインターフェース処理方式を図示する。
D8: 具体的なユースケースとしては、統合WEBにて、PDMWEB（中間DB） にデータベースアクセスする場合に当たる。
C10: （連携パターン）
B40: ■連携時のエラー制御に関して
B41: ・ | C41: 統合Webから中間DBへの通信は、OJDBを介して行われる。
C42: よって、統合Webと中間DBのコネクションの有効性に関しては、DBコネクションの有効性の事前検証を行う形を採用する。
B43: ・ | C43: また、統合Webから中間DBへのDBコネクションをプーリングした場合、ネットワークレイヤーでコネクションが切断される可能性があるため、
C44: コネクションプーリングは行わず、統合Webのバッチ起動時に都度コネクションを取得するものとする。
B46: ■SCP環境でのWhitelist設定
B47: ・ | C47: 中間DBはヒロセVPNに存在するため、SCP～ヒロセ間のVPN接続が必要となる。
B48: ・ | C48: また、その際、ヒロセVPN内の中間DBをグローバルIPにて参照する必要があるため、translate ip への変換を行う。
C49: <Outbound >
D50: Destination : 中間DB(translate ip), Protocol : TCP, Port:1521
B52: ■共通機能化候補
C53: 上述の中間DB連携方式の検討の結果、共通機能化の候補となる機能は、以下の通りとなる。
C55: 機能名 | M55: 機能概要 | AL55: 備考
C56: 中間DBアクセス機能 | M56: Hybris外 の データソースである、中間DBにDBアクセスするため、Oracle JDBC の利用を前提に、中間DB への SQL と Java オブジェクト を 紐付ける永続化フレームワークを提供する。 永続化フレームワークとして求められる機能としては、SQL文の実行、定義済みSQL文の実行（PreparedStatement）、バッチでの利用を想定した 検索結果 の 部分リストの取得機能（ページング読み込み）が必要となる。 代表的な永続化フレームワークとしては、Mybatisが挙げられる。 | AL56: 統合WEBから中間DBに対しては、SELECT - SQL しか発行せず、INSERT、UPDATE、DELETE、並びに、DDLの実行は行わない。よって、中間DBに対する、厳密なトランザクション管理は不要となる。 ※あくまでも、統合WEBから中間DBに対しては、Read Onlyとなるイメージ。

Sheet 参考_3.GPDMネットワーク図
A1: インタフェース処理方式設計 | L1: システム名 | U1: 作成者 | AA1: 作成日 | AG1: 更新者 | AM1: 更新日
L2: =表紙!D4 -> 4S デジタルトランスフォーメーション・プラットフォーム構築 | U2: JSOL菊地 | AA2: =改版履歴!D4 -> 43256 | AG2: =INDEX(改版履歴!C4:C32,COUNTA(改版履歴!C4:C32)) -> JSOL神田 | AM2: =INDEX(改版履歴!D4:D32,COUNTA(改版履歴!D4:D32)) -> 44610
B3: ※CCV2環境 移行後の接続環境
B5: ３_1．中間DB連携(CCV2環境下でのネットワーク図)
D6: ※黄色吹き出しは、後述のSAP Cloud Portalの設定値部分
E7: 資料上は、"GPDM開発(hdevpdm01)"となっているが、検証環境(ヒロセ電機受入れ環境 hukepdm01) も存在し、Commerce のSTG環境 と GPDM検証環境(ヒロセ電機受入れ環境)がつながっている。
B43: ３_2．SAP Cloud Portal 上のVPNの設定（管理者権限を付与されると参照可能）
B166: ３_3．SAP Commerce 上の接続情報（STG情報）

Sheet 4.GPDMドキュメント連携
A1: インタフェース処理方式設計 | L1: システム名 | U1: 作成者 | AA1: 作成日 | AG1: 更新者 | AM1: 更新日
L2: =表紙!D4 -> 4S デジタルトランスフォーメーション・プラットフォーム構築 | U2: =改版履歴!C4 -> JSOL牟田園 | AA2: =改版履歴!D4 -> 43256 | AG2: =INDEX(改版履歴!C4:C32,COUNTA(改版履歴!C4:C32)) -> JSOL神田 | AM2: =INDEX(改版履歴!D4:D32,COUNTA(改版履歴!D4:D32)) -> 44610
B4: ４．GPDMドキュメント連携
C6: ４．１．GPDMから統合WEBへのドキュメント連携
D7: 以下に、GPDM から 統合WEB へのインターフェース処理方式を図示する。
D8: 具体的なユースケースとしては、統合WEBにて、GPDM からの連携ファイルを取得する場合に当たる。
C10: （連携パターン）
B43: ■連携時のエラー制御に関して
B44: ・ | C44: GPDMからAmazon EC2へのドキュメント連携は、sambaを介して行われる。
C45: GPDMから連携されたファイルに何らかの欠損があった場合は、該当ファイルをGPDMに連絡、再配置した上で、再取込を行う。
B47: ■SCP環境でのWhitelist設定
B48: ・ | C48: 以下のWhitelist の追加を行う。
C49: <Outbound >
D50: Destination : 中間DB(translate ip), Protocol : TCP, Port:1521
D51: Destination : Amazon S3, Protocol : HTTP(S)
B53: ■共通機能化候補
C54: 上述のGPDM連携方式の検討の結果、共通機能化の候補となる機能は、以下の通りとなる。
C56: 機能名 | M56: 機能概要 | AL56: 備考
C57: なし | M57: なし | AL57: 他の連携方式で既に定義済み。

Sheet 5.Hybris Marketing連携
A1: インタフェース処理方式設計 | L1: システム名 | U1: 作成者 | AA1: 作成日 | AG1: 更新者 | AM1: 更新日
L2: =表紙!D4 -> 4S デジタルトランスフォーメーション・プラットフォーム構築 | U2: =改版履歴!C4 -> JSOL牟田園 | AA2: =改版履歴!D4 -> 43256 | AG2: =INDEX(改版履歴!C4:C32,COUNTA(改版履歴!C4:C32)) -> JSOL神田 | AM2: =INDEX(改版履歴!D4:D32,COUNTA(改版履歴!D4:D32)) -> 44610
B4: ５．Hybris Marketing連携
C6: ５．１．統合WEBからHybris Marketingへの連携（画面）
D7: 以下に、統合WEBの画面機能 から Hybris Marketing へのインターフェース処理方式を図示する。
D8: 具体的なユースケースとしては、統合WEBの「会員情報」と、画面の閲覧、ドキュメントの表示といった会員の「行動情報」を、マーケティング活動のためにをHybris Marketingに連携する場合に当たる。
D9: 代表のユースケースとして、会員情報の連携を以下に示す。
C11: （連携パターン：会員情報）
C43: ５．２．統合WEBからHybris Marketingへの連携（バッチ）
D44: 以下に、統合WEBのバッチ から Hybris Marketing へのインターフェース処理方式を図示する。
D45: 具体的なユースケースとしては、統合WEBの「製品情報」、「シリーズ情報」、「受注情報」を、マーケティング活動のためにをHybris Marketingに連携する場合に当たる。
D46: 代表のユースケースとして、製品情報の連携を以下に示す。
C48: （連携パターン：製品情報）
B77: ■リトライ制御
B78: ・ | C78: HybrisMarketing との Odata 連携時 の リトライ制御に関しては、Hybrisの共通部品である ODataServiceにてリトライ制御が行われる。
C79: その際の タイムアウト設定は 300,000(msec)、リトライ回数は 1回となる。
B81: ■連携時のエラー制御に関して
B82: ・ | C82: 統合WebからHybris Marketing への連携は、Hybrisが内包する ODataAPI（ODataService）を介して行われる。
B83: ・ | C83: Odata通信時のエラー（Odataの必須プロパティの欠落）に関しては、ODataServiceが例外処理を行うため、この例外処理に準拠する。
B84: ・ | C84: また、Hybris Marketing での Odata の取込に関しは、非同期スレッドにて処理が行われるため、データ取込の成否は 統合Webには返却されない。
C85: すなわち、HybrisMarketingから統合Web側にレスポンスとして返却されるのは、あくまでもOdata通信（request）の成否のみとなる。
B86: ・ | C86: よって、Hybris Marketging でのデータ取込時のエラーに関しては、Hybris Marketgingにてエラーを検知し、必要に応じてデータパッチを行い再取込を行う。
B88: ■SCP環境でのWhitelist設定
B89: ・ | C89: 以下のWhitelist の追加を行う。
C90: <Outbound >
D91: Destination : HybrisMarketing, Protocol : HTTP(S)
B93: ■共通機能化候補
C94: 上述のHybris Marketing連携方式の検討の結果、共通機能化の候補となる機能は、以下の通りとなる。
C96: 機能名 | M96: 機能概要 | AL96: 備考
C97: Hybris Marketing 用 Client | M97: Hybris Marketing に対し、HTTP(POST)にて hybris標準の ODataService の呼び出しを行う Client ラッパー。 連携先API名（Interractions etc）と連携値を受け取り、共通的なヘッダ構築、連携先URLの構築、ODataの生成、Hybris Marketingへのリクエストを行う。 | AL97: リクエスト処理はODataService<sapymktcommon extension>が行う。

Sheet 14.SCPI連携
A1: インタフェース処理方式設計 | L1: システム名 | U1: 作成者 | AA1: 作成日 | AG1: 更新者 | AM1: 更新日
L2: =表紙!D4 -> 4S デジタルトランスフォーメーション・プラットフォーム構築 | U2: JSOL金 | AA2: 44606 | AG2: JSOL金 | AM2: =INDEX(改版履歴!D4:D32,COUNTA(改版履歴!D4:D32)) -> 44610
B4: 14．SCPI連携
C6: 14．1．統合WEBからSCPIへの連携（バッチ）
D7: 以下に、統合WEBのバッチ から SCPI へのインターフェース処理方式を図示する。
D8: 具体的なユースケースとしては、統合WEBの「会員情報」、「製品情報」、「シリーズ情報」を、マーケティング活動のためにをSCPIに連携する場合に当たる。
D9: 代表のユースケースとして、会員情報の連携を以下に示す。
C11: （連携パターン：会員情報）
C40: 14．2．統合WEBからSCPIへの連携（画面）
D41: 以下に、統合WEBの画面 から SCPI へのインターフェース処理方式を図示する。
D42: 具体的なユースケースとしては、統合WEBの「Interaction情報」を、マーケティング活動のためにをSCPIに連携する場合に当たる。
D43: 代表のユースケースとして、画面遷移時のInteraction情報の連携を以下に示す。
C45: （連携パターン：画面遷移）
C74: 14．3．SCPIから統合WEBへの連携（API）
D75: 以下に、SCPI から 統合WEB へのインターフェース処理方式を図示する。
D76: 具体的なユースケースとしては、SCPIの「Web通知情報」を、会員へ通知するためにを統合WEBに連携する場合に当たる。
D77: 代表のユースケースとして、Web通知情報の連携を以下に示す。
B108: ■リトライ制御
B109: ＜14．1．統合WEBからSCPIへの連携（バッチ）＞
C110: ・ | D110: SCPI との oData 連携時 の リトライ制御に関しては、HAC画面(Platform > Configuration)にて行う。
D111: デフォルトでリトライ回数は５となる。（KEY=outboundsync.max.retriesで管理、定義なしの場合リトライ回数は０となる）
B113: ＜14．2．統合WEBからSCPIへの連携（画面）＞
C114: ・ | D114: SCPI との Odata 連携時 の リトライ制御に関しては、Hybrisの共通部品である ODataServiceにてリトライ制御が行われる。
D115: その際の タイムアウト設定は 300,000(msec)、リトライ回数は 1回となる。
B117: ＜14．3．SCPIから統合WEBへの連携（API）＞
C118: ・ | D118: リトライ制御は実装しない。
B120: ■連携時のエラー制御に関して
B121: ＜14．1．統合WEBからSCPIへの連携（バッチ）＞
C122: ・ | D122: 統合WebからSCPI への連携は、Hybrisが内包する OutboundSyncCronJob を介して行われる。
C123: ・ | D123: oData通信時のエラー（統合Webで送信失敗した場合）に関しては、統合Web側でリランを行うことで対処する。
C124: ・ | D124: 統合Webからの送信が成功したが、SCPI側でエラーが発生した場合は、統合Web側の検知はできない。
D125: すなわち、統合Web側で監視できるのは、あくまでoData通信（request）の成否のみとなる。
C126: ・ | D126: よって、SCPI側のエラーに関しては、SCPI側にてエラーを検知し、必要に応じて対処を行う。
B127: ＜14．2．統合WEBからSCPIへの連携（画面）＞
C128: ・ | D128: 統合WebからSCPI への連携は、Hybrisが内包する ODataAPI（ODataService）を介して行われる。
C129: ・ | D129: Odata通信時のエラー（Odataの必須プロパティの欠落）に関しては、ODataServiceが例外処理を行うため、この例外処理に準拠する。
C130: ・ | D130: また、SCPI での Odata の取込に関しは、非同期スレッドにて処理が行われるため、データ取込の成否は 統合Webには返却されない。
D131: すなわち、SCPIから統合Web側にレスポンスとして返却されるのは、あくまでもOdata通信（request）の成否のみとなる。
C132: ・ | D132: よって、SCPI でのデータ取込時のエラーに関しては、SCPIにてエラーを検知し、必要に応じてデータパッチを行い再取込を行う。
B133: ＜14．3．SCPIから統合WEBへの連携（API）＞
...

Sheet 6.Aperza連携
A1: インタフェース処理方式設計 | L1: システム名 | U1: 作成者 | AA1: 作成日 | AG1: 更新者 | AM1: 更新日
L2: =表紙!D4 -> 4S デジタルトランスフォーメーション・プラットフォーム構築 | U2: =改版履歴!C4 -> JSOL牟田園 | AA2: =改版履歴!D4 -> 43256 | AG2: =INDEX(改版履歴!C4:C32,COUNTA(改版履歴!C4:C32)) -> JSOL神田 | AM2: =INDEX(改版履歴!D4:D32,COUNTA(改版履歴!D4:D32)) -> 44610
B4: ６．Aperza連携
C6: ６．１．統合WEBからAperzaへの連携
D7: 以下に、統合WEB から Aperza へのインターフェース処理方式を図示する。
D8: 具体的なユースケースとしては、統合WEBの在庫照会画面にて、Aperzaの 在庫情報画面を include して 表示する場合に当たる。
C11: （連携パターン）
B40: ■SCP環境でのWhitelist設定
B41: ・ | C41: 以下のWhitelist の追加を行う。
C42: <Outbound >
D43: Destination : Aperza, Protocol : HTTP(S)
B45: ■共通機能化候補
C46: 上述のAperza連携方式の検討の結果、共通機能化の候補となる機能は、以下の通りとなる。
C48: 機能名 | M48: 機能概要 | AL48: 備考
C49: なし | M49: なし | AL49: Aperza提供のadw-tag.jsにて連携が実現できるため、 統合WEB独自の共通機能の作成は不要。

Sheet 7.i-search連携
A1: インタフェース処理方式設計 | L1: システム名 | U1: 作成者 | AA1: 作成日 | AG1: 更新者 | AM1: 更新日
L2: =表紙!D4 -> 4S デジタルトランスフォーメーション・プラットフォーム構築 | U2: =改版履歴!C4 -> JSOL牟田園 | AA2: =改版履歴!D4 -> 43256 | AG2: =INDEX(改版履歴!C4:C32,COUNTA(改版履歴!C4:C32)) -> JSOL神田 | AM2: =INDEX(改版履歴!D4:D32,COUNTA(改版履歴!D4:D32)) -> 44610
B4: ７．i-search連携
C6: ７．１．統合WEBからi-searchへの連携
D7: 以下に、統合WEB から i-search へのインターフェース処理方式を図示する。
D8: 具体的なユースケースとしては、統合WEBの全文検索にて、i-searchの 全文検索機能を 呼び出す場合に当たる。
C11: （連携パターン）
B40: ■SCP環境でのWhitelist設定
B41: ・ | C41: 以下のWhitelist の追加を行う。
C42: <Outbound >
D43: Destination : i-search, Protocol : HTTP(S)
C44: <Intbound > ※システムリリース前の事前クローリング期間のみ
D45: Source : i-search, Protocol : HTTP(S)
B47: ■共通機能化候補
C48: 上述のi-search連携方式の検討の結果、共通機能化の候補となる機能は、以下の通りとなる。
C50: 機能名 | M50: 機能概要 | AL50: 備考
C51: i-search 用 Rest Client | M51: i-search に対し、HTTP(GET)にて RestTemplate の呼び出しを行う Rest Client。 JSON形式の検索結果を Javaオブジェクトにマッピングして、呼び出し元に返却する。 | AL51: Spring の 提供する、RestTemplate の利用が想定される。
C54: i-search 用 javascript | M54: 全文検索結果が返却される、サムネイル画像（URL）を、 ブラウザ上でポップアップ表示するためのjavascript。 | AL54: 既存システム（WEB55）で利用している i-search.js の流用を前提に、 共通機能化の検討を行う。

Sheet 8.環境システム連携
A1: インタフェース処理方式設計 | L1: システム名 | U1: 作成者 | AA1: 作成日 | AG1: 更新者 | AM1: 更新日
L2: =表紙!D4 -> 4S デジタルトランスフォーメーション・プラットフォーム構築 | U2: =改版履歴!C4 -> JSOL牟田園 | AA2: =改版履歴!D4 -> 43256 | AG2: =INDEX(改版履歴!C4:C32,COUNTA(改版履歴!C4:C32)) -> JSOL神田 | AM2: =INDEX(改版履歴!D4:D32,COUNTA(改版履歴!D4:D32)) -> 44610
B4: ８．環境システム連携
C6: ８．１．統合WEBから環境システムへの連携
D7: 以下に、統合WEB から 環境システム（GreenMeister） へのインターフェース処理方式を図示する。
D8: 具体的なユースケースとしては、統合WEBから、環境システム（GreenMeister）に対して、環境証明書の出力を依頼する場合に当たる。
C10: （連携パターン）
C40: ８．２．環境システムから統合WEBへの連携
D41: 以下に、環境システム（GreenMeister）から 統合WEB へのインターフェース処理方式を図示する。
D42: 具体的なユースケースとしては、統合WEBにて、環境システム（GreenMeister）からの環境証明書ファイル一式を取得する場合に当たる。
C45: （連携パターン）
B76: ■連携時のエラー制御に関して
B77: ・ | C77: 統合Webと環境システム間のインタフェース連携時には、ファイルの配信側が「実ファイル」と「制御ファイル」をセットでputする形とする。
C78: よって、転送ファイルの整合性は、配信側で担保する形となる
B79: ・ | C79: ファイルの配信側にて、実ファイルの転送完了を確認した後、制御ファイルを転送し、受信側にファイルの取込を要求する。
C80: 受信側では、制御ファイルを軸にファイルのポーリングを行い、制御ファイルの検知と共に実ファイルの取込を行う。
C81: 制御ファイルなしの実ファイルに関しては、転送が完了していないものとして取り扱い、受信側では該当ファイルの取込は行わない。
B83: ■SCP環境でのWhitelist設定
B84: ・ | C84: 以下のWhitelist の追加を行う。
C85: <Outbound >
D86: Destination : Amazon S3, Protocol : HTTP(S)
B88: ■共通機能化候補
C89: 上述の環境システム連携方式の検討の結果、共通機能化の候補となる機能は、以下の通りとなる。
C91: 機能名 | M91: 機能概要 | AL91: 備考
C92: なし | M92: なし | AL92: 他の連携方式で既に定義済み。

Sheet 9.ドキュメントリンク連携
A1: インタフェース処理方式設計 | L1: システム名 | U1: 作成者 | AA1: 作成日 | AG1: 更新者 | AM1: 更新日
L2: =表紙!D4 -> 4S デジタルトランスフォーメーション・プラットフォーム構築 | U2: =改版履歴!C4 -> JSOL牟田園 | AA2: =改版履歴!D4 -> 43256 | AG2: =INDEX(改版履歴!C4:C32,COUNTA(改版履歴!C4:C32)) -> JSOL神田 | AM2: =INDEX(改版履歴!D4:D32,COUNTA(改版履歴!D4:D32)) -> 44610
B4: ９．ドキュメントリンク連携
C6: ９．１．ドキュメントリンク連携
D7: 以下に、degikeyなどの外部サイト から 統合WEB へのインターフェース処理方式を図示する。
D8: 具体的なユースケースとしては、degikeyなどの外部サイト から 統合WEBに対して、ドキュメントをダウンロードする依頼する場合に当たる。
C11: （連携パターン）
B28: ■共通機能化候補
C29: 上述のドキュメントリンク連携方式の検討の結果、共通機能化の候補となる機能は、以下の通りとなる。
C31: 機能名 | M31: 機能概要 | AL31: 備考
C32: ドキュメントリンクAPI | M32: 統合WEB内に配置するAPI。 パラメータに応じて該当するドキュメントをストリームで返却し、外部サイトでダウンロードさせる。 | AL32: 外部サイトでリンク切れを起こさないために、API仕様はWeb55のドキュメントリンク機能と同等のものにする。

Sheet 10.MaxMind(GeoIP)連携
A1: インタフェース処理方式設計 | L1: システム名 | U1: 作成者 | AA1: 作成日 | AG1: 更新者 | AM1: 更新日
L2: =表紙!D4 -> 4S デジタルトランスフォーメーション・プラットフォーム構築 | U2: =改版履歴!C4 -> JSOL牟田園 | AA2: =改版履歴!D4 -> 43256 | AG2: =INDEX(改版履歴!C4:C32,COUNTA(改版履歴!C4:C32)) -> JSOL神田 | AM2: =INDEX(改版履歴!D4:D32,COUNTA(改版履歴!D4:D32)) -> 44610
B4: １０．MaxMind(GeoIP)連携
C6: １０．１．統合WEBからMaxMind(GeoIP)連携への連携
D7: 以下に、統合WEB から MaxMind(GeoIP)連携 へのインターフェース処理方式を図示する。
D8: 具体的なユースケースとしては、統合WEBのセッション初期化処理において、MaxMindのGeoIPを呼び出し、接続元のIPアドレスからCountryの情報を取得する場合に当たる。
C11: （連携パターン）
B40: ■リトライ制御
B41: ・ | C41: GeoIP2 Java API では、タイムアウト時のリトライ制御tは行われない。
C42: また、その際の connection timeout は 3,000(msec)、read timeoutは20,000(msec)となる。
B44: ■SCP環境でのWhitelist設定
B45: ・ | C45: 以下のWhitelist の追加を行う。
C46: <Outbound >
D47: Destination : MaxMind(GeoIP), Protocol : HTTP(S)
B49: ■共通機能化候補
C50: 上述のi-search連携方式の検討の結果、共通機能化の候補となる機能は、以下の通りとなる。
C52: 機能名 | M52: 機能概要 | AL52: 備考
C53: IPアドレス判定Filter | M53: 接続元のIPアドレスを引数に GeoIP2 Java API を呼び出し、 接続元IPアドレスの Countyの判定を行う。 また、判定結果をセッションに格納する。 | AL53: GeoIP2 の 公式サイトは、以下の通り。 https://www.maxmind.com/ja/geoip2-precision-services GeoIP の 公式Developerサイトは、以下の通り。 https://dev.maxmind.com/geoip/

Sheet 11.Live Chat連携
A1: インタフェース処理方式設計 | L1: システム名 | U1: 作成者 | AA1: 作成日 | AG1: 更新者 | AM1: 更新日
L2: =表紙!D4 -> 4S デジタルトランスフォーメーション・プラットフォーム構築 | U2: =改版履歴!C4 -> JSOL牟田園 | AA2: =改版履歴!D4 -> 43256 | AG2: =INDEX(改版履歴!C4:C32,COUNTA(改版履歴!C4:C32)) -> JSOL神田 | AM2: =INDEX(改版履歴!D4:D32,COUNTA(改版履歴!D4:D32)) -> 44610
B4: １１．Live Chat連携
C6: １１．１．統合WEBからLiveChatへの連携
D7: 以下に、統合WEB から LiveChat へのインターフェース処理方式を図示する。
C10: （連携パターン）
B54: ■Live Chat Widget の 管理
B55: ・ | C55: Live Chat Widget の javascript コードは、Live Chat のアカウント情報に基づき、LiveChat の管理コンソールで自動的に生成される。
D56: Settings ---> Channels ---> Chat widget
B57: ・ | C57: Live Chat の課金は、javascript コードに埋め込まれた license情報にて行われる。
B58: ・ | C58: また、Live Chat の Chat Window のカスタマイズも Live Chat の管理コンソールから行う。
C59: 管理コンソールの設定では、Chat Window の色、形状の設定から、CSSを用いた特殊なカスタイマイズまで行う事ができる。
C60: ※逆に、クライアント側ではスタイル指定などは行わない点に注意。
D61: Settings ---> Chat window ---> Customization
B62: ・ | C62: Live Chat を利用するためには、統合WebのドメインをLive Chat の管理コンソールから、Trusted domains として登録する必要がある。
D63: Settings ---> Security ---> Trusted domains
B65: ■MaxMind(GeoIP2) の 管理
B66: ・ | C66: GeoIP2 JavaScript を利用するためには、統合WebのドメインをGeoIP2 のアカウント管理画面から、GeoIP JavaScript Domains として登録する必要がある。
D67: Services ---> GeoIP JavaScript Domains
B69: ■SCP環境でのWhitelist設定
B70: ・ | C70: Google Tag Manager、GeoIP2、Live Chat への通信は、ブラウザ上から行われるため、
C71: SCP環境でのwhitelist設定は不要。
B74: ■共通機能化候補
C75: 上述のi-search連携方式の検討の結果、共通機能化の候補となる機能は、以下の通りとなる。
C77: 機能名 | AL77: 備考
C78: GoogleTagManager.tag （WEB解析タグ） | M78: ・Google Tag Managerは master.tag に以下のよいに埋め込む。 ①head>～</head>内に共通でGoogle Tag Managerタグ読み込む。 ②<body>直下に共通でGoogle Tag Managerタグの実装を埋め込む。 ・複数テンプレートで使用する可能性を考慮して、①②の実装はそれぞれ xxx.tag のような Tag Library として実装する。 ・実装部においてGoogleへの連携パラメータが必要な場合は、 コントローラでパラメータをJSPに引き渡し、JSPタグおよびjavascriptでパラメータを連携する。

Sheet 12.intra-mart連携
A1: インタフェース処理方式設計 | L1: システム名 | U1: 作成者 | AA1: 作成日 | AG1: 更新者 | AM1: 更新日
L2: =表紙!D4 -> 4S デジタルトランスフォーメーション・プラットフォーム構築 | U2: JSOL辻本 | AA2: 43858 | AG2: JSOL辻本 | AM2: 43858
B4: 12.intra-mart連携
C6: 12．１．統合WEBからintra-martへの連携
D7: 以下に、統合WEB から intra-mart へのインターフェース処理方式を図示する。
D8: 具体的なユースケースとしては、統合WEBから、intra-martに対して、PCNの承認情報を出力する場合が当たる。
C10: （連携パターン）
B40: ■連携時のエラー制御に関して
B41: ・ | C41: 統合WEBからAmazon S3 を介したintra-martとのインターフェイス連携は、原則、AWS SDK for Java を介して行われる事となるため、
C42: 通信時のエラー制御に関しては、AWS SDK for Java の 例外処理機構に従う。
C43: ⇒ | D43: https://docs.aws.amazon.com/ja_jp/sdk-for-java/v1/developer-guide/java-dg-exceptions.html
B44: ・ | C44: ファイルの欠損を確認するため、統合WEB から S3に転送する際に、「実ファイル」をzipアーカイブした上で、転送する。
B45: ・ | C45: intra-mart側にて、ファイルの欠損が検知された場合は、その旨を統合WEB担当者に連絡して、再送を依頼する。
B47: ■SCP環境でのWhitelist設定
B48: ・ | C48: 以下のWhitelist の追加を行う。
C49: <Outbound >
D50: Destination : Amazon S3, Protocol : HTTP(S)
B52: ■共通機能化候補
C53: 上述のintra-mart連携方式の検討の結果、共通機能化の候補となる機能は、以下の通りとなる。
C55: 機能名 | M55: 機能概要 | AL55: 備考
C56: なし | M56: なし | AL56: 他の連携方式で既に定義済み。

Sheet 13.Octopart連携
A1: インタフェース処理方式設計 | L1: システム名 | U1: 作成者 | AA1: 作成日 | AG1: 更新者 | AM1: 更新日
L2: 4S デジタルトランスフォーメーション・プラットフォーム構築 | U2: JSOL牟田園 | AA2: 43256 | AG2: JSOL菊地 | AM2: 44287
B4: 13．Octopart連携
C6: ６．１．統合WEBからOctopartへの連携
D7: 以下に、統合WEB からOctopart へのインターフェース処理方式を図示する。
D8: 具体的なユースケースとしては、統合WEBの海外代理店在庫情報画面にて、Octopartの 海外在庫情報を取得して表示する場合に当たる。
C11: （連携パターン）
B45: ■共通機能化候補
C46: 上述のAperza連携方式の検討の結果、共通機能化の候補となる機能は、以下の通りとなる。
C48: 機能名 | M48: 機能概要 | AL48: 備考
C49: Octopart 用 Rest Client | M49: Octopart に対し、HTTP(GET)にて RestTemplate の呼び出しを行う Rest Client。 JSON形式の検索結果を Javaオブジェクトにマッピングして、呼び出し元に返却する。 | AL49: Spring の 提供する、RestTemplate の利用が想定される。
