Workbook
Name txtDatabaseName: "テキスト 8"
Name txtTableName: "テキスト 2"
Name txtUserName: "テキスト 4"

Sheet 表紙
B22: =TEXT(変更来歴!AT2,"yyyy年 mm月 dd日") & " " & 変更来歴!AT3 -> 2026年 05月 18日 r1.2
C28: アメージングアクティビティ(株) | F28: HRS殿
C29: 作成 | D29: 照査 | E29: 承認 | F29: 照査 | G29: 承認

Sheet 変更来歴
A1: 文書名： | I1: 顧客名 | M1: ヒロセ電機株式会社 | X1: システム | AA1: 化学物質データ申請 | AK1: 作成者 | AN1: 古竹 | AQ1: 作成日 | AT1: =AL7 -> 46125 | AX1: 書類番号
A2: intra-mart Accel Platform | I2: プロジェクト | AK2: 修正者 | AN2: 古竹 | AQ2: 修正日 | AT2: 46160 | AX2: IMWF-53
A3: 画面設計書 | I3: 内容 | X3: 画面名 | AA3: 化学物質データ申請完了 | AQ3: Rev | AT3: =INDIRECT("A" & COUNTA(A7:A39) + 6) -> r1.2
A5: 変更来歴
A6: Rev. | C6: 変更内容 | Q6: 変更・追加箇所 | AL6: 提出日 | AP6: 作成者 | AS6: 承認者 | AV6: 備考
A7: ｒ1.0 | C7: 新規作成 | AL7: 46125 | AP7: 古竹
A8: r1.1 | C8: 化学物質データ申請完了画面の内容を日英併記に変更 | Q8: 「化学物質データ申請完了画面」シート | AL8: 46134 | AP8: 古竹
A9: r1.2 | C9: タイトルを日英併記に変更 | Q9: 「化学物質データ申請完了画面」シート | AL9: 46160 | AP9: 古竹

Sheet 化学物質データ申請完了画面
A1: 文書名： | I1: 顧客名 | M1: =変更来歴!M1 -> ヒロセ電機株式会社 | X1: システム | AA1: =変更来歴!AA1 -> 化学物質データ申請 | AK1: 作成者 | AN1: =変更来歴!AP7 -> 古竹 | AS1: 作成日 | AV1: =変更来歴!AL7 -> 46125 | AZ1: 書類番号
A2: intra-mart Accel Platform | I2: プロジェクト | M2: =変更来歴!M2 | AK2: 修正者 | AN2: =INDIRECT("変更来歴!AP" & COUNTA(変更来歴!AP7:'変更来歴'!AP39) + 6) -> 古竹 | AS2: 修正日 | AV2: =INDIRECT("変更来歴!AL" & COUNTA(変更来歴!AL7:'変更来歴'!AL39) + 6) -> 46160 | AZ2: =変更来歴!AX2 -> IMWF-53
A3: =変更来歴!A3 -> 画面設計書 | I3: 内容 | M3: =RIGHT(CELL("filename",A1),LEN(CELL("filename",A1))-FIND("]",CELL("filename",A1))) -> 化学物質データ申請完了画面 | X3: 画面名 | AA3: =MID(CELL("filename"),FIND("]",CELL("filename"))+1,LEN(CELL("filename"))) & "画面" -> 画面項目画面 | AS3: Rev | AV3: =INDIRECT("変更来歴!A" & COUNTA(変更来歴!A7:'変更来歴'!A39) + 6) -> r1.2
A5: ="画面レイアウト"&"("&MID(CELL("filename"),FIND("]",CELL("filename"))+1,LEN(CELL("filename")))&")" -> 画面レイアウト(画面項目) | BB5: Rev.
B6: 1 | C6: 2 | D6: 3 | E6: 4 | F6: 5 | G6: 6 | H6: 7 | I6: 8 | J6: 9 | K6: 10 | L6: 11 | M6: 12 | N6: 13 | O6: 14 | P6: 15 | Q6: 16 | R6: 17 | S6: 18 | T6: 19 | U6: 20 | V6: 21 | W6: 22 | X6: 23 | Y6: 24 | Z6: 25 | AA6: 26 | AB6: 27 | AC6: 28 | AD6: 29 | AE6: 30 | AF6: 31 | AG6: 32 | AH6: 33 | AI6: 34 | AJ6: 35 | AK6: 36 | AL6: 37 | AM6: 38 | AN6: 39 | AO6: 40 | AP6: 41 | AQ6: 42 | AR6: 43 | AS6: 44 | AT6: 45 | AU6: 46 | AV6: 47 | AW6: 48 | AX6: 49 | AY6: 50 | AZ6: 51
C7: ホーム / 化学物質データ | BE7: 機能仕様
BE8: 1. パンくずリストエリア
D9: 化学物質データ / Chemical substance data | BF9: 1.1 パンくずリスト
BG10: 以下のようにパンくずリストを表示する。
BG11: 『製品トップ > 化学物質データ申請完了』
D12: 申請完了
BE13: 2. 申請完了表示エリア
BF14: 言語情報が"jp"の場合は日本語のコンテンツを、それ
D15: <受付番号：2016-00043> 化学物質データの申請が完了しました。 | BF15: 以外の場合は英語のコンテンツを表示する。
D16: <Application NO:2016-0043> Application of the chemical substance data has been completed.
BF17: 2.1 申請完了情報
D18: 申請完了メールを登録メールアドレスへ送信致しました。ご確認ください。 | BG18: 受付番号：
D19: Could you confirm the acceptance confirmation e-mail? | BG19: 申請データをyCommerceに登録する際に、
D20: ・登録メールアドレス : user@mail.com | BG20: hybrisのGeneratorを利用して生成されるシーケンス値。
D21: Registered e-mail address : user@mail.com | BG21: 書式：暦年-シーケンス番号
D22: ・送信メールアドレス : GM_no-reply@hirose.com | BG22: *採番については、2018年だけ2018-50000から採番する。
D23: Source e-mail address : GM_no-reply@hirose.com | BG23: 2019年以後は20xx-00000という形で採番される。
D24: ・メール件名 : <HRS:2016-000043> 化学物質データ申請完了
D25: Subject : <HRS:2016-000043> Chemical substance data application completion | BF25: 2.2 登録メールアドレス
BG26: 申請者のアドレスが表示される。申請完了時のメールは、
D27: ※ データを作成するのに時間がかかる場合がございます。データの作成が完了しましたら、完了メールを送信致します。 | BG27: このアドレス宛に送信される
D28: 申請されたデータは、まとめてzipファイルで出力致します。
D29: * It take some time to output the data.Once the data is now complete, we will send the completion mail. | BF29: 2.3 送信メールアドレス
D30: We will output the data that has been filed in the ZIP file. | BG30: 送信メールアドレスは固定（汎用マスタから取得）。
BG31: 申請者宛に送信されるメールの"from"として本アドレス
BG32: が設定される。
BF34: 2.4 化学物質データ画面へ戻る
BG35: 押下すると、一括申請リスト（化学物質データ画面）
BG36: へ移動する

Sheet 化学物質データ申請完了画面(仮)
A1: 文書名： | I1: 顧客名 | M1: =変更来歴!M1 -> ヒロセ電機株式会社 | X1: システム | AA1: =変更来歴!AA1 -> 化学物質データ申請 | AK1: 作成者 | AN1: =変更来歴!AP7 -> 古竹 | AS1: 作成日 | AV1: =変更来歴!AL7 -> 46125 | AZ1: 書類番号
A2: intra-mart Accel Platform | I2: プロジェクト | M2: =変更来歴!M2 | AK2: 修正者 | AN2: =INDIRECT("変更来歴!AP" & COUNTA(変更来歴!AP7:'変更来歴'!AP39) + 6) -> 古竹 | AS2: 修正日 | AV2: =INDIRECT("変更来歴!AL" & COUNTA(変更来歴!AL7:'変更来歴'!AL39) + 6) -> 46160 | AZ2: =変更来歴!AX2 -> IMWF-53
A3: =変更来歴!A3 -> 画面設計書 | I3: 内容 | M3: =RIGHT(CELL("filename",A1),LEN(CELL("filename",A1))-FIND("]",CELL("filename",A1))) -> 化学物質データ申請完了画面(仮) | X3: 画面名 | AA3: =MID(CELL("filename"),FIND("]",CELL("filename"))+1,LEN(CELL("filename"))) & "画面" -> 画面項目画面 | AS3: Rev | AV3: =INDIRECT("変更来歴!A" & COUNTA(変更来歴!A7:'変更来歴'!A39) + 6) -> r1.2
A5: ="画面レイアウト"&"("&MID(CELL("filename"),FIND("]",CELL("filename"))+1,LEN(CELL("filename")))&")" -> 画面レイアウト(画面項目) | BB5: Rev.
B6: 1 | C6: 2 | D6: 3 | E6: 4 | F6: 5 | G6: 6 | H6: 7 | I6: 8 | J6: 9 | K6: 10 | L6: 11 | M6: 12 | N6: 13 | O6: 14 | P6: 15 | Q6: 16 | R6: 17 | S6: 18 | T6: 19 | U6: 20 | V6: 21 | W6: 22 | X6: 23 | Y6: 24 | Z6: 25 | AA6: 26 | AB6: 27 | AC6: 28 | AD6: 29 | AE6: 30 | AF6: 31 | AG6: 32 | AH6: 33 | AI6: 34 | AJ6: 35 | AK6: 36 | AL6: 37 | AM6: 38 | AN6: 39 | AO6: 40 | AP6: 41 | AQ6: 42 | AR6: 43 | AS6: 44 | AT6: 45 | AU6: 46 | AV6: 47 | AW6: 48 | AX6: 49 | AY6: 50 | AZ6: 51
C7: ホーム / 化学物質データ | BE7: 機能仕様
BE8: 1. パンくずリストエリア
W9: 化学物質データ | BF9: 1.1 パンくずリスト
BG10: 以下のようにパンくずリストを表示する。
BG11: 『製品トップ > 化学物質データ申請完了』
D12: 申請完了
BE13: 2. 申請完了表示エリア
BF14: 言語情報が"jp"の場合は日本語のコンテンツを、それ
D15: <受付番号：2016-00043> 化学物質データの申請が完了しました。 | BF15: 以外の場合は英語のコンテンツを表示する。
D17: 申請完了メールを登録メールアドレスへ送信致しました。ご確認ください。 | BF17: 2.1 申請完了情報
D18: ・登録メールアドレス : user@mail.com | BG18: 受付番号：
D19: ・送信メールアドレス : GM_no-reply@hirose.com | BG19: 申請データをyCommerceに登録する際に、
D20: ・メール件名 : <HRS:2016-000043> 化学物質データ申請完了 | BG20: hybrisのGeneratorを利用して生成されるシーケンス値。
BG21: 書式：暦年-シーケンス番号
D22: ※ データを作成するのに時間がかかる場合がございます。データの作成が完了しましたら、完了メールを送信致します。 | BG22: *採番については、2018年だけ2018-50000から採番する。
D23: 申請されたデータは、まとめてzipファイルで出力致します。 | BG23: 2019年以後は20xx-00000という形で採番される。
BF25: 2.2 登録メールアドレス
BG26: 申請者のアドレスが表示される。申請完了時のメールは、
BG27: このアドレス宛に送信される
BF29: 2.3 送信メールアドレス
BG30: 送信メールアドレスは固定（汎用マスタから取得）。
BG31: 申請者宛に送信されるメールの"from"として本アドレス
C32: 参考：サイト言語が日本語ではない場合に表示される英語コンテンツ | BG32: が設定される。
BF34: 2.4 化学物質データ画面へ戻る
D35: Application Completion | BG35: 押下すると、一括申請リスト（化学物質データ画面）
BG36: へ移動する
D38: <Application NO:2016-0043> Application of the chemical substance data has been completed.
D40: Could you confirm the acceptance confirmation e-mail?
D41: ・Registered e-mail address : user@mail.com
D42: ・Source e-mail address : GM_no-reply@hirose.com
D43: ・Subject : <HRS:2016-000043> Chemical substance data application completion
D45: * It take some time to output the data.Once the data is now complete, we will send the completion mail.
D46: We will output the data that has been filed in the ZIP file.

Sheet 画面項目
A1: 画面項目(Screen Items)
A2: 必須記入 | AF2: OOTB以外
A3: 項番 (No) | C3: 項目名(Item Name) | Q3: 論理項目種別 (Logical Item Type) | X3: 固定/可変 (Fixed/Variable) | AB3: I/O | AD3: OOTB | AF3: 入力桁数 (Input Digits) | AJ3: 表示ラベルキー （Display Label Key) | AP3: 初期値 (Default Value) | BA3: 備考 (Comment)
C4: エリア （Area） | J4: 項目名 (Item Name)
A5: 1 | C5: パンくずリストエリア
A6: 1.1 | J6: パンくずリスト | Q6: Anchor Text | X6: Fixed | AB6: O | AD6: ○ | AF6: - | AP6: -
A7: 2 | C7: 申請完了表示エリア
A8: 2.1 | J8: 受付番号 | Q8: Text Output | X8: Variable | AB8: O | AD8: × | AP8: -
A9: 2.2 | J9: 登録メールアドレス | Q9: Text Output | X9: Variable | AB9: O | AD9: × | AF9: - | AP9: -
A10: 2.3 | J10: 送信メールアドレス | Q10: Text Output | X10: Variable | AB10: O | AD10: × | AF10: - | AP10: -
A11: 2.4 | J11: 化学物質データ画面へ戻る | Q11: Image Button | X11: Fixed | AB11: O | AD11: × | AF11: - | AP11: -
A13: 処理項目(Process Items)
A14: 項番 (No) | C14: 処理名 (Process Name) | J14: イベント発生元（論理項目名） (Event Source(Logical Item Name)) | X14: イベント (Event) | AE14: サーバ ／クライアント | AM14: 遷移先画面ID (Transition Destination Screen ID) | AW14: 概要 (Comment)
A16: 1 | C16: 初期画面表示 | Q16: 本画面に遷移 | X16: Onload | AE16: サーバ | AM16: - | AW16: 「セッション言語」によりサイト言語を判定し、サイト言語が日本語の場合は日本語で、日本語ではない場合は英語で、メール本文を表示する
A17: 2 | C17: 化学物質データ画面への遷移 | Q17: 化学物質データ画面へ戻るボタン | X17: Click | AE17: サーバ | AM17: SEFE200_画面要件定義書_化学物質データ画面 | AW17: 化学物質データ画面に戻る
A18: 3
A19: 4
A20: 5
C23: 利用可能な論理項目種別 | P23: 固定/可変 | U23: I/O | Y23: OOTB
C24: Label | P24: Fixed | U24: I | Y24: ○ | AA24: 全て利用
C25: Manual Operation Button | P25: Variable | U25: O | Y25: △ | AA25: 一部利用
C26: Image Button | U26: I/O | Y26: × | AA26: なし（新規作成）
C27: Anchor Text | U27: -
C28: Textbox
C29: Text Box (with spin button)
C30: Password
C31: Text Area
C32: File field
C33: Radio Button
C34: Dropdown List
C35: Checkbox
C36: Calendar
C37: Time Input
C38: Loop Table
C39: Image
... C44: -

Sheet 画面状態
A1: 画面状態 (Screen State)
A2: 項番 (No) | C2: 論理項目名 (Logical Item Name) | Q2: 状態 (State)
Q3: 初期表示
A4: =IF(ISBLANK(画面項目!A5),"",画面項目!A5) -> 1 | C4: パンくずリストエリア
A5: =IF(ISBLANK(画面項目!A6),"",画面項目!A6) -> 1.1 | J5: パンくずリスト | Q5: ○
A6: =IF(ISBLANK(画面項目!A7),"",画面項目!A7) -> 2 | C6: =IF(ISBLANK(画面項目!C7),"",画面項目!C7) -> 申請完了表示エリア
A7: =IF(ISBLANK(画面項目!A8),"",画面項目!A8) -> 2.1 | J7: =IF(ISBLANK(画面項目!J8),"",画面項目!J8) -> 受付番号 | Q7: ○
A8: =IF(ISBLANK(画面項目!A9),"",画面項目!A9) -> 2.2 | J8: =IF(ISBLANK(画面項目!J9),"",画面項目!J9) -> 登録メールアドレス | Q8: ○
A9: =IF(ISBLANK(画面項目!A11),"",画面項目!A11) -> 2.4 | J9: =IF(ISBLANK(画面項目!J11),"",画面項目!J11) -> 化学物質データ画面へ戻る | Q9: ○
D14: Legend Name | K14: Legend Value
D15: Display(Active) | K15: ○
D16: Display(In-Active) | K16: ●
D17: Hidden | K17: ×

Sheet 外貨(コリア原計)
A1: 文書名： | I1: 顧客名 | M1: =変更来歴!M1 -> ヒロセ電機株式会社 | X1: システム | AA1: =変更来歴!AA1 -> 化学物質データ申請 | AK1: 作成者 | AN1: =変更来歴!AP7 -> 古竹 | AS1: 作成日 | AV1: =変更来歴!AL7 -> 46125 | AZ1: 書類番号
A2: intra-mart Accel Platform | I2: プロジェクト | M2: =変更来歴!M2 | AK2: 修正者 | AN2: =INDIRECT("変更来歴!AP" & COUNTA(変更来歴!AP7:'変更来歴'!AP39) + 6) -> 古竹 | AS2: 修正日 | AV2: =INDIRECT("変更来歴!AL" & COUNTA(変更来歴!AL7:'変更来歴'!AL39) + 6) -> 46160 | AZ2: =変更来歴!AX2 -> IMWF-53
A3: =変更来歴!A3 -> 画面設計書 | I3: 内容 | M3: =RIGHT(CELL("filename",A1),LEN(CELL("filename",A1))-FIND("]",CELL("filename",A1))) -> 外貨(コリア原計) | X3: 画面名 | AA3: =MID(CELL("filename"),FIND("]",CELL("filename"))+1,LEN(CELL("filename"))) & "画面" -> 画面項目画面 | AS3: Rev | AV3: =INDIRECT("変更来歴!A" & COUNTA(変更来歴!A7:'変更来歴'!A39) + 6) -> r1.2
A5: ="画面レイアウト"&"("&MID(CELL("filename"),FIND("]",CELL("filename"))+1,LEN(CELL("filename")))&")" -> 画面レイアウト(画面項目) | BB5: Rev.
B6: 1 | C6: 2 | D6: 3 | E6: 4 | F6: 5 | G6: 6 | H6: 7 | I6: 8 | J6: 9 | K6: 10 | L6: 11 | M6: 12 | N6: 13 | O6: 14 | P6: 15 | Q6: 16 | R6: 17 | S6: 18 | T6: 19 | U6: 20 | V6: 21 | W6: 22 | X6: 23 | Y6: 24 | Z6: 25 | AA6: 26 | AB6: 27 | AC6: 28 | AD6: 29 | AE6: 30 | AF6: 31 | AG6: 32 | AH6: 33 | AI6: 34 | AJ6: 35 | AK6: 36 | AL6: 37 | AM6: 38 | AN6: 39 | AO6: 40 | AP6: 41 | AQ6: 42 | AR6: 43 | AS6: 44 | AT6: 45 | AU6: 46 | AV6: 47 | AW6: 48 | AX6: 49 | AY6: 50 | AZ6: 51
B7: 単価上申(円販売一般品) | N7: 案件番号： | R7: SA-PR123456
E8: 過去の申請から内容コピー
C10: 起票日 | F10: ： | H10: 2022/09/29
C11: 所属 | F11: ： | H11: ヒロセ電機株式会社/管理本部/ＩＴ統括部/情報システム企画課
C12: 社員番号 | F12: ： | H12: hirose | L12: 氏名 ： | O12: システム担当者
B13: 1 | C13: 2 | D13: 3 | E13: 4 | F13: 5 | G13: 6 | H13: 7 | I13: 8 | J13: 9 | K13: 10 | L13: 11 | M13: 12 | N13: 13 | O13: 14 | P13: 15 | Q13: 16 | R13: 17 | S13: 18 | T13: 19 | U13: 20 | V13: 21 | W13: 22 | X13: 23 | Y13: 24 | Z13: 25 | AA13: 26 | AB13: 27 | AC13: 28 | AD13: 29 | AE13: 30 | AF13: 31 | AG13: 32 | AH13: 33 | AI13: 34 | AJ13: 35 | AK13: 36 | AL13: 37 | AM13: 38 | AN13: 39 | AO13: 40 | AQ13: 41 | AR13: 42 | AS13: 43 | AT13: 44 | AU13: 45 | AV13: 46 | AW13: 47
B14: 2 | C14: 申請内容
C16: 起票区分 | H16: ◎ 単価上申書
B17: 3 | C17: タイトル*
C18: 得意先コード | T18: 得意先名* | AK18: 客先担当者名
C19: 案件種類* | P19: ▼ | T19: 希望承認期限* | Y19: 2022/9/29
C20: 口銭率 | K20: 0.05 | L20: ☑ 口銭申請有り
B23: 2 | C23: プロジェクト情報
C25: 工事金額 | O25: 万円/月 | T25: 継続期間* | AG25: ヵ月 | AK25: 総工事金額 | AX25: 万円
C26: 海外販社 | T26: SFDC工事番号
C27: 大分類 | H27: 大分類A | P27: ▼ | T27: 中分類 | Y27: 中分類B | AG27: ▼
C28: レップ社名 | T28: 量産時期 | AJ28: 用途(アプリケーション)
C29: 競合名 | P29: ▼ | T29: 生産セット台数 | AJ29: プロジェクトピーク金額 | AW29: 円/月
C30: 申請理由* | AX30: ▲
AX31: ▼
C32: 値引補填工事 | H32: 値引きしなければならない理由を記載してください | AX32: ▲
AX33: ▼
C34: 備考欄 | AX34: ▲
AX35: ▼
B38: 5 | C38: 精算通貨
C40: レートタイプ* | G40: ○経営計画レート ○ 顧客契約レート ◎ その他のレート
B41: 6 | C41: No | D41: 通貨 | H41: レート
B42: 8 | C42: 1 | D42: USD | H42: 110
B43: 9 | C43: 2 | D43: EUR | H43: 125
B45: 10
B46: 5 | C46: 申請価格入力
D48: 原計タイプ* | H48: ○ 技術原計 ○ PPM原計 ◎ コリア原計
B49: 6 | C49: No | D49: CL | H49: 品名* | N49: 形* | R49: 月間数量* | V49: 原計通貨* | Z49: 純原価 | AE49: 申請通貨* | AI49: FOB価格 | AM49: 従来FOB価格* | AQ49: 物流コスト率 | AU49: 販社売価 | AY49: 代理店売価 | BC49: 得意先 | BG49: ピン@FOB | BJ49: 競合名 | BN49: 備考
B50: 7 | AQ50: (%) | AU50: (外貨) | AY50: (外貨) | BC50: 要求価格 | BG50: 価格基準
B51: 8 | C51: 1 | D51: 4800215830 | H51: TF38-20S-0.5SV(830) | N51: KFH | Q51: ▼ | R51: 70000 | V51: USD | Y51: ▼ | Z51: 0.0673 | AE51: USD | AH51: ▼ | AI51: 0.1211 | AM51: 0.12 | AQ51: 0.01 | AU51: 0.1359 | AY51: 0.151 | BC51: 0.151 | BG51: 0.0061 | BJ51: JAE
...
