Workbook
Name txtDatabaseName: "テキスト 8"
Name txtTableName: "テキスト 2"
Name txtUserName: "テキスト 4"

Sheet 表紙
B22: =TEXT(変更来歴!AT2,"yyyy年 mm月 dd日") & " " & 変更来歴!AT3 -> 2026年 06月 17日 dr1.5
C28: アメージングアクティビティ(株) | F28: HRS殿
C29: 作成 | D29: 照査 | E29: 承認 | F29: 照査 | G29: 承認

Sheet 変更来歴
A1: 文書名： | I1: 顧客名 | M1: ヒロセ電機株式会社 | X1: システム | AA1: 化学物質データ申請 | AK1: 作成者 | AN1: 古竹 | AQ1: 作成日 | AT1: =AL7 -> 46125 | AX1: 書類番号
A2: 新環境証明書システム | I2: プロジェクト | M2: 新環境証明書システム移行 | AK2: 修正者 | AN2: 古竹 | AQ2: 修正日 | AT2: 46190 | AX2: IMWF-53
A3: 画面設計書 | I3: 内容 | X3: 画面名 | AA3: 化学物質データ申請確認 | AQ3: Rev | AT3: =INDIRECT("A" & COUNTA(A7:A39) + 6) -> dr1.5
A5: 変更来歴
A6: Rev. | C6: 変更内容 | Q6: 変更・追加箇所 | AL6: 提出日 | AP6: 作成者 | AS6: 承認者 | AV6: 備考
A7: dr1.0 | C7: 新規作成 | AL7: 46125 | AP7: 古竹
A8: dr1.1 | C8: 「化学物質データ申請確認画面」シート | Q8: 化学物質データ申請確認画面の内容を日英併記に変更 | AL8: 46134 | AP8: 古竹
A9: dr1.2 | C9: 「化学物質データ申請確認画面」シート | Q9: 英語表記を現行の英語表記に変更、項目変更 | AL9: 46162 | AP9: 古竹
A10: dr1.3 | C10: 「化学物質データ申請確認画面」シート、「処理詳細」シート | Q10: ・エラーメッセージエリアを削除 ・共通ヘッダーを追加 ・処理詳細のフロー図で不要個所をグレーアウト | AL10: 46177 | AP10: 古竹
A11: dr1.4 | C11: 「画面項目」シート | Q11: ・HRSロゴとパンくずリストのリンクを押下した際の遷移先を修正 ・テーブル情報変更に伴い修正 | AL11: 46184 | AP11: 古竹
A12: dr1.5 | C12: 「化学物質データ申請確認画面」シート、「画面項目」シート、「処理詳細」シート | Q12: 課題リストの回答をもとに修正 | AL12: 46190 | AP12: 古竹

Sheet 化学物質データ申請確認画面
A1: 文書名： | I1: 顧客名 | M1: =変更来歴!M1 -> ヒロセ電機株式会社 | X1: システム | AA1: =変更来歴!AA1 -> 化学物質データ申請 | AK1: 作成者 | AN1: =変更来歴!AP7 -> 古竹 | AS1: 作成日 | AV1: =変更来歴!AL7 -> 46125 | AZ1: 書類番号
A2: intra-mart Accel Platform | I2: プロジェクト | M2: =変更来歴!M2 -> 新環境証明書システム移行 | AK2: 修正者 | AN2: =INDIRECT("変更来歴!AP" & COUNTA(変更来歴!AP7:'変更来歴'!AP39) + 6) -> 古竹 | AS2: 修正日 | AV2: =INDIRECT("変更来歴!AL" & COUNTA(変更来歴!AL7:'変更来歴'!AL39) + 6) -> 46190 | AZ2: =変更来歴!AX2 -> IMWF-53
A3: =変更来歴!A3 -> 画面設計書 | I3: 内容 | M3: =RIGHT(CELL("filename",A1),LEN(CELL("filename",A1))-FIND("]",CELL("filename",A1))) -> 化学物質データ申請確認画面 | X3: 画面名 | AA3: =MID(CELL("filename"),FIND("]",CELL("filename"))+1,LEN(CELL("filename"))) & "画面" -> 表紙画面 | AS3: Rev | AV3: =INDIRECT("変更来歴!A" & COUNTA(変更来歴!A7:'変更来歴'!A39) + 6) -> dr1.5
A5: ="画面レイアウト"&"("&MID(CELL("filename"),FIND("]",CELL("filename"))+1,LEN(CELL("filename")))&")" -> 画面レイアウト(表紙) | BB5: Rev.
B6: 1 | C6: 2 | D6: 3 | E6: 4 | F6: 5 | G6: 6 | H6: 7 | I6: 8 | J6: 9 | K6: 10 | L6: 11 | M6: 12 | N6: 13 | O6: 14 | P6: 15 | Q6: 16 | R6: 17 | S6: 18 | T6: 19 | U6: 20 | V6: 21 | W6: 22 | X6: 23 | Y6: 24 | Z6: 25 | AA6: 26 | AB6: 27 | AC6: 28 | AD6: 29 | AE6: 30 | AF6: 31 | AG6: 32 | AH6: 33 | AI6: 34 | AJ6: 35 | AK6: 36 | AL6: 37 | AM6: 38 | AN6: 39 | AO6: 40 | AP6: 41 | AQ6: 42 | AR6: 43 | AS6: 44 | AT6: 45 | AU6: 46 | AV6: 47 | AW6: 48 | AX6: 49 | AY6: 50 | AZ6: 51
C8: ホーム / 化学物質データ申請確認 | BF8: 機能仕様
BF9: 1. パンくずリストエリア
W10: 化学物質データ/Chemical substance data | BG10: 1.1 パンくずリスト
C11: 製品選択フォーム Product selection form | BH11: 以下のようにパンくずリストを表示する。
BH12: 『製品トップ > 化学物質データ申請確認』
C14: 申請した製品数: 5 件 Number of products applied: 5 products | BF14: 2.申請確認エリア
BF15: 申請内容に不備があった場合のエラーメッセージは
BF16: ポップアップで表示
E18: Items | P18: 日本語 | AB18: English
E19: Non-compliant | P19: 非適合の為、提出できません。 | AB19: We can't submit the certificate for non-compliant.
E20: Request | P20: ヒロセ営業担当へご連絡、または環境各種要求書を発行 | AB20: Please contact to Hirose sales or request on the environment data base.
E21: グレー背景 Gray background | P21: 重複した製品 | AB21: Duplicate products
E22: 赤背景 Red background | P22: システムに製品の該当なし | AB22: Products are not registered in the system.
E26: 提出先企業名 Submission_company | R26: 123456
E29: エンドユーザー End user | R29: A社
G33: 製品名 Product name | J33: CL | M33: 新製品区分 New Product Class | P33: 製品販売 状況 Product Sales Status | S33: PCN番号 PCN No | V33: RoHS証明書 RoHS Certificate | Y33: ハロゲンフリー証明書 Certificate of Halogen Free | AB33: 成分表 Product Chemical Substances Table | AE33: 高精度分析データ(ICP) Analysis Data(ICP) | AH33: SDS | AK33: chemSHERPA | AN33: SVHC調査報告書 Report of SVHC
E36: ☑ | G36: NameA | J36: CL0123- 4567-8-90 | M36: オリジナル Original | P36: 生産終了 予定品 Products to be discontinued | S36: 2024-01 | V36: YES | Y36: YES | AB36: YES | AE36: YES | AH36: YES | AK36: YES | AN36: YES
G39: NameA | J39: CL0123- 4567-8-90 | M39: オリジナル Original | P39: 生産終了 予定品 Products to be discontinued | S39: 2024-01 | V39: YES | Y39: YES | AB39: YES | AE39: YES | AH39: YES | AK39: YES | AN39: YES
E42: ☑ | G42: NameB | J42: CL0123- 4567-8-91 | M42: オリジナル (特定社) Original(Specified company) | P42: 生産終了 予定品 Products to be discontinued | S42: 2023-12 | V42: Non-complia nt | Y42: Non-complia nt | AB42: YES | AE42: YES | AH42: Request | AK42: YES | AN42: YES
E45: ☑ | G45: NameC | J45: CL0123- 4567-8-92 | M45: カスタム(他 社販売可) Custom(Can be sold by other companies) | P45: 新規設計 非推奨 New designs are not recommended | S45: - | V45: Non-complia nt | Y45: YES | AB45: YES | AE45: YES | AH45: Request | AK45: Request | AN45: Request
E48: ☑ | G48: NameD | J48: CL0123- 4567-8-93 | M48: カスタム(他 社販売可) Custom(Can be sold by other companies) | P48: 新規設計 非推奨 New designs are not recommended | S48: 2023-11 | V48: YES | Y48: Non-complia nt | AB48: YES | AE48: YES | AH48: YES | AK48: YES | AN48: YES
G51: NameF | J51: CL0123- 4567-8-95 | M51: カスタム(他 社販売不可) Custom(Cannot be sold by other companies) | P51: 販売品 Items for sales | S51: 2023-10 | V51: Request | Y51: Request | AB51: Request | AE51: Request | AH51: Request | AK51: Request | AN51: Request
G54: - | J54: CL0123- 4567-8-96 | M54: - | P54: - | S54: -
E65: 申請確認ダイアログ
E66: Application confirmation dialog
G69: 化学物質データ新規申請を行いますか
J70: (○○ 件)
E71: Do you want to apply?
J72: (○○ Items)

Sheet 画面項目
A1: 画面項目(Screen Items)
A2: 必須記入
A3: 項番 (No) | C3: 項目名(Item Name) | Q3: 初期値 (Default Value) | AB3: フォーマット (Format) | AI3: 導出元 (Source) | AR3: 備考 (Comment)
C4: エリア （Area） | J4: 項目名 (Item Name)
A5: 0 | C5: 共通ヘッダー
A6: 0.1 | J6: ヒロセ電機ロゴ | Q6: - | AR6: 「化学物質データ画面」～「化学物質データ申請完了画面」共通 ロゴを押下するとヒロセ電機HPトップページに遷移する。
A7: 1 | C7: パンくずリストエリア
A8: 1.1 | J8: パンくずリスト | Q8: - | AR8: ホーム画面: ホーム (リンクなし)
A9: 2 | C9: 申請確認エリア | Q9: -
A10: 2.1 | J10: 初期申請製品数 | Q10: 申請確認画面で表示された製品数 ※重複、製品データ該当なしの件数も含む | AI10: 申請画面のHTTPパラメータ
A11: 2.2 | J11: 申請に対するチェック結果の説明 | Q11: -
A12: 2.3 | J12: 提出先企業名 | Q12: 申請画面からフォーム送信される「提出先企業名」パラメータの値 | AI12: 申請画面のHTTPパラメータ
A13: 2.4 | J13: エンドユーザー | Q13: 申請画面からフォーム送信される「エンドユーザー」パラメータの値 | AI13: 申請画面のHTTPパラメータ
A14: 2.5 | J14: CSVダウンロードボタン | Q14: -
A15: 2.6 | J15: 申請チェックボックス | Q15: 申請可否の情報 | AI15: 処理項目：項番1参照 | AR15: ※画面表示フォーマットは「処理詳細」シートの「■A－１－７－２．製品証明書情報取得処理よりエラーハンドリングフォーマット」を参照する
A16: 2.7 | J16: 製品名 | Q16: 申請画面からフォーム送信される「製品名/CL-No」の配列パラメータの値、または、「環境証明書申請製品情報」の「製品名」の値 | AI16: 申請可能製品情報マスタ 製品名 | AR16: <表示内容>（製品名とCLコード） ①申請画面からフォーム送信される「製品名/CL-No」を基に「環境証明書申請製品情報」を取得できた場合 ・画面項目.製品名：データ「環境証明書申請製品情報」の「製品名」を表示する ・画面項目.CLコード：データ「環境証明書申請製品情報」の「CLコード」を表示する ②上記①でない場合 1）申請画面からフォーム送信される「製品名/CL-No」の配列パラメータ値が 「HrsNo形式」（数値11桁）、または、「CLコード形式」（CL9999-9999-9-99）の場合 ・画面項目.製品名："-"（ハイフン）を表示する ・画面項目.CLコード：申請画面からフォーム送信される「製品名/CL-No」の配列パラメータ値を表示する。 2）上記1）でない場合 ・画面項目.製品名：申請画面からフォーム送信される「製品名/CL-No」の配列パラメータ値を表示する。 ・画面項目.CLコード："-"（ハイフン）を表示する ※値がないときは"-"（ハイフン）を表示する。 （値がないときとはレコードなしや値がnullの場合を指す。従って、例えば値がスペースなどのときは、スペースという値があると判定）
A17: 2.8 | J17: CL（製品番号） | Q17: 申請画面からフォーム送信される「製品名/CL-No」の配列パラメータの値、または、「環境証明書申請製品情報」の「CLコード」の値 | AI17: 申請可能製品情報マスタ CLコード | AR17: <表示内容> 上記の「製品名」の「<表示内容>（製品名とCLコード）」を参照 ※画面表示フォーマットは「処理詳細」シートの「■A－１－７－２．製品証明書情報取得処理よりエラーハンドリングフォーマット」を参照する
A18: 2.9 | J18: 申請された証明書種類 | Q18: 申請画面からフォーム送信される「化学物質データ選択」配列パラメータの値 | AI18: 申請画面のHTTPパラメータ | AR18: 既存項目の「AIS」は本改修で削除
A19: 2.10 | J19: 製品毎の申請可否チェック結果 | Q19: 2.8の製品番号に対応する証明書毎のチェック結果 | AR19: ■区分値（証明書単位）のセット仕様 ・YES : 申請可能 ・Non-compliant : 申請不可 ・Request : 別途問合せしてください、の意味 ・Contact：既存の問い合わせルートでの申請に促す ■行（製品単位）のセット仕様： ・グレー背景色：重複した製品名/CL番号 ・赤背景色：システムに製品の該当なし ※画面表示フォーマットは「処理詳細」シートの「■A－１－７－２．製品証明書情報取得処理よりエラーハンドリングフォーマット」を参照する
A20: 2.11 | J20: 戻る | Q20: -
A21: 2.12 | J21: 申請 | Q21: - | AR21: ■チェックボックスが一つも選択されない場合、 「申請」ボタンは非活性となる。 ■チェックボックスが一つ以上選択さてている場合、 「申請確認ダイアログ」がポップアップで表示される。
A22: 2.13 | J22: いいえボタン | Q22: - | AR22: 申請確認ダイアログをクローズして、申請処理は実行しない。
A23: 2.14 | J23: はいボタン | Q23: - | AR23: 申請確認ダイアログをクローズする。 ※処理詳細の「Ａ－３．申請について」を参照する。 ※「申請処理」エラー時 ・入力チェックエラーが発生する場合、該当のエラーメッセージを2.19の画面項目に表示する。 ※「入力チェック」シート参照 ・処理エラーが発生する場合、message.E.F.000031で定義されているエラーメッセージを2.19の画面項目に表示する。
A24: 2.15 | J24: 申請製品数 | Q24: - | AR24: 選択された製品の件数を表示する。
Q25: -

Sheet 処理詳細
A1: 処理詳細
B3: １－１．画面初期表示について
E5: ※以下のフロー図を参照する
E70: １－１－１． | I70: 申請画面からのHTTPパラメータで製品名/CLコードリスト取得
E72: １－１－２． | I72: 製品名/CLコードより証明書の情報取得
F74: テーブル | O74: 申請テーブル
F75: 抽出条件（OR） | O75: 申請可能製品情報マスタ CLコード=入力リスト.製品名/CLコード ※1
O76: 申請可能製品情報マスタ 製品名=入力リスト.製品名/CLコード ※2
F77: ※1 入力値の形式がHRS-No（数字11桁）の場合はCLコードの形式（CL9999-9999-9-99）に変換
F78: ※2 入力値に以下の全角記号が含まれる場合は半角に変換
H79: － → -
H80: （ → (
H81: ） → )
H82: ＋ → +
H83: ＊ → *
H84: ／ → /
F86: ■１－１－２－１．申請製品情報マスタ（HrsChemicalSubstanceProduct）
F88: No | G88: 修飾子 | O88: 項目名
F89: 1 | G89: clCode | O89: CLコード
F90: 2 | G90: hrsNo | O90: HRS No
F91: 3 | G91: partNo | O91: 製品名
F92: 4 | G92: available | O92: 申請可能
F93: 5 | G93: request | O93: Request
F94: 6 | G94: nonCompliant | O94: Non-compliant
F95: 7 | G95: version | O95: バージョン
F97: ■１－１－２－２．取得した製品照明書の情報と画面表示のマッピング
E124: １－１－３． | I124: 製品名/CLコードの重複チェック
F126: ・１－１－２．で環境証明書申請製品情報を取得できた場合 | Y126: ： | Z126: 環境証明書申請製品情報の「CLコード」を基に重複チェックを実施
F127: ・１－１－２．で環境証明書申請製品情報を取得できなかった場合 | Y127: ： | Z127: 入力リスト.製品名/CLコードを基に重複チェックを実施
E130: １－１－７．申請可能チェック結果取得
F131: ■１－１－７－１．判断結果より処理について
H133: 社員と販売と代理店権限 | AL133: 代理店権限
H134: １－１－４．CLコードより一致する製品証明書の情報を取得 まで処理結果 | AL134: １－１－６．申請可能チェック結果OK | AR134: １－１－６．申請可能チェック結果NG
H135: 申請製品情報マスタに存在する | W135: すべての証明書が（Non-compliant ）申請不可 | AL135: なにもしない | AR135: なにもしない
W136: 証明書は１件以上申請可能 ※「YES : 申請可能」または「Request : 問い合わせ可否はシステムで判断できない」） | AL136: なにもしない | AR136: 「Contact」に書き直す
H137: 申請製品情報マスタに存在しない | AL137: なにもしない | AR137: なにもしない
H138: 製品が重複する | AL138: なにもしない | AR138: なにもしない
F140: ■１－１－７－２．製品証明書情報取得処理よりエラーハンドリングフォーマット
F142: 社員と販売と代理店権限
F143: １－１－４．CLコードより一致する製品証明書の情報を取得 まで処理結果 | AJ143: 背景色 | AM143: 文字列 | AR143: チェックボックス | AU143: パターン
...

Sheet 出力編集仕様
A1: 出力編集仕様
A2: 化学物質データの環境証明書申請内容をデータベースに登録する。
A5: タイプ | J5: 証明書申請テーブル, 証明書申請入力テーブル
A6: 説明 | J6: 申請ボタンを押下する時 INSERT（UPDATEは発生しない） | AD6: 備考
A8: No | B8: 修飾子
B9: 申請テーブル
A10: 1 | B10: 受付番号 | J10: 暦年と5桁の追番の間にハイフン（例：2018-00001） ※追番はhybrisのGeneratorの機構で生成する値（hrsChemicalSubstanceAppNoSeq） | AD10: 画面項目の2.8毎に処理
A11: 2 | B11: 申請者アカウントID | J11: ログインユーザのHrsCustomer.uid
A12: 3 | B12: 申請日時 | J12: システムの日付
A13: 4 | B13: ステータス | J13: 画面.提出先企業名 | AD13: 画面項目の2.3
A14: 5 | B14: エンドユーザ名 | J14: 画面.エンドユーザ | AD14: 画面項目の2.4
A15: 6 | B15: ステータス | J15: 未処理（ChemicalSubstanceStatus.unprocessed） | AD15: 申請ファイル取り込みバッチで更新できる
A16: 7 | B16: 有効期限 | J16: - | AD16: 申請ファイル取り込みバッチで更新する
A17: 8 | B17: ファイルサイズ | J17: - | AD17: 同上
A18: 9 | B18: フォルダ数 | J18: - | AD18: 同上
A19: 10 | B19: ファイル数 | J19: - | AD19: 同上
A22: 備考
A23: ※1 | C23: 登録対象の言語は画面で選択可能な7言語（英語、日本語、韓国語、中国語、フランス語、ドイツ語、ロシア語）
C24: 基本的に、登録元の「製品マスター情報.新製品区分」にはGPDMから連携された言語のみ値が設定されている想定
C25: 値が設定されていない言語の場合は、英語の値（フォールバック値）を設定（該当言語の内容に翻訳などはしない）

Sheet ダウンロードCSVファイルについて
A1: ダウンロードCSV
A2: 化学物質データ申請確認画面で「CSVダウンロード」ボタンを押下すると該当するファイルを生成する
B5: ◆出力項目について
C7: ■RoHS、ハロゲンフリー、成分表、JAMP、SDS、chemSHERPA、SVHC調査報告書を申請する場合
D9: 例：
D10: Part No | K10: CLコード | R10: New Product Class | Y10: Product Sales Status Class | AF10: PCN No | AM10: CL check | AT10: Name of company to be submitted | BA10: End customer | BH10: Certificate of RoHS Conformity | BO10: Certificate of Halogen Free | BV10: Product Chemical Substances Table | CC10: JAMP AIS | CJ10: SDS | CQ10: chemSHERPA | CX10: SVHC
D11: NameA | K11: CL0123-4567-8-90 | R11: オリジナル | Y11: 生産終了予定品 | AF11: 2024-01 | AT11: B社 | BA11: A社 | BH11: YES | BO11: YES | BV11: YES | CC11: YES | CJ11: YES | CQ11: YES | CX11: YES
D12: NameA | K12: CL0123-4567-8-90 | R12: オリジナル | Y12: 生産終了予定品 | AF12: 2024-01 | AM12: 重複
D13: NameB | K13: CL0123-4567-8-91 | R13: オリジナル(特定社) | Y13: 生産終了品 | AF13: 2023-12 | AT13: B社 | BA13: A社 | BH13: Non-compliant | BO13: Non-compliant | BV13: YES | CC13: YES | CJ13: Request | CQ13: YES | CX13: YES
D14: NameC | K14: CL0123-4567-8-92 | R14: カスタム(他社販売可) | Y14: 新規設計非推奨 | AF14: - | AT14: B社 | BA14: A社 | BH14: YES | BO14: YES | BV14: YES | CC14: YES | CJ14: Request | CQ14: Request | CX14: Request
D15: NameE | K15: CL0123-4567-8-94 | R15: カスタム(他社販売不可) | Y15: 販売品 | AF15: - | AT15: B社 | BA15: A社 | BH15: YES | BO15: YES | BV15: YES | CC15: YES | CJ15: YES | CQ15: YES | CX15: YES
D16: - | K16: CL0123-4567-8-96 | R16: - | Y16: - | AF16: - | AM16: 該当なし | AT16: B社 | BA16: A社 | BH16: Request | BO16: Request | BV16: Request | CC16: Request | CJ16: Request | CQ16: Request | CX16: Request
C19: ■RoHS、ハロゲンフリー、成分表、JAMPを申請する場合
D21: 例：
D22: Part No | K22: CLコード | R22: New Product Class | Y22: Product Sales Status Class | AF22: PCN No | AM22: CL check | AT22: Name of company to be submitted | BA22: End customer | BH22: Certificate of RoHS Conformity | BO22: Certificate of Halogen Free | BV22: Product Chemical Substances Table | CC22: JAMP AIS
D23: NameA | K23: CL0123-4567-8-90 | R23: オリジナル | Y23: 生産終了予定品 | AF23: 2024-01 | AT23: B社 | BA23: A社 | BH23: YES | BO23: YES | BV23: YES | CC23: YES
D24: NameA | K24: CL0123-4567-8-90 | R24: オリジナル | Y24: 生産終了予定品 | AF24: 2024-01 | AM24: 重複
D25: NameB | K25: CL0123-4567-8-91 | R25: オリジナル(特定社) | Y25: 生産終了品 | AF25: 2023-12 | AT25: B社 | BA25: A社 | BH25: Non-compliant | BO25: Non-compliant | BV25: YES | CC25: YES
D26: NameC | K26: CL0123-4567-8-92 | R26: カスタム(他社販売可) | Y26: 新規設計非推奨 | AF26: - | AT26: B社 | BA26: A社 | BH26: YES | BO26: YES | BV26: YES | CC26: YES
D27: NameE | K27: CL0123-4567-8-94 | R27: カスタム(他社販売不可) | Y27: 販売品 | AF27: - | AT27: B社 | BA27: A社 | BH27: YES | BO27: YES | BV27: YES | CC27: YES
D28: - | K28: CL0123-4567-8-96 | R28: - | Y28: - | AF28: - | AM28: 該当なし | AT28: B社 | BA28: A社 | BH28: Request | BO28: Request | BV28: Request | CC28: Request
B30: ※ | C30: ①該当するCSVの内容は画面で表示されるCL製品一覧の項目＋上記の点線で囲まれた項目である。
C31: ②画面でチェックボックスを選択してないデータ、重複したデータまたはNon-compliantのデータもすべて出力される。
C32: ③製品名の昇順、CLコードの昇順（値がない場合は末尾）にて出力する（当画面の表示順と同じ仕様にする）
C33: ④画面から引き渡されているCLコード、提出先企業名、エンドユーザーなどの項目以外について（詳細は別ブック「SERP110_帳票定義書_環境証明書申請製品一覧.xlsx」を参照）、「CSV DOWNLOAD」ボタン押下時に再度出力内容を取得している。

Sheet 選択画面
A1: 文書名： | I1: 顧客名 | M1: =変更来歴!M1 -> ヒロセ電機株式会社 | X1: システム | AA1: =変更来歴!AA1 -> 化学物質データ申請 | AK1: 作成者 | AN1: =変更来歴!AP7 -> 古竹 | AS1: 作成日 | AV1: =変更来歴!AL7 -> 46125 | AZ1: 書類番号
A2: intra-mart Accel Platform | I2: プロジェクト | M2: =変更来歴!M2 -> 新環境証明書システム移行 | AK2: 修正者 | AN2: =INDIRECT("変更来歴!AP" & COUNTA(変更来歴!AP7:'変更来歴'!AP39) + 6) -> 古竹 | AS2: 修正日 | AV2: =INDIRECT("変更来歴!AL" & COUNTA(変更来歴!AL7:'変更来歴'!AL39) + 6) -> 46190 | AZ2: =変更来歴!AX2 -> IMWF-53
A3: =変更来歴!A3 -> 画面設計書 | I3: 内容 | M3: =RIGHT(CELL("filename",A1),LEN(CELL("filename",A1))-FIND("]",CELL("filename",A1))) -> 選択画面 | X3: 画面名 | AA3: =MID(CELL("filename"),FIND("]",CELL("filename"))+1,LEN(CELL("filename"))) & "画面" -> 表紙画面 | AS3: Rev | AV3: =INDIRECT("変更来歴!A" & COUNTA(変更来歴!A7:'変更来歴'!A39) + 6) -> dr1.5
A5: ="画面レイアウト"&"("&MID(CELL("filename"),FIND("]",CELL("filename"))+1,LEN(CELL("filename")))&")" -> 画面レイアウト(表紙) | BB5: Rev.
B6: 1 | C6: 2 | D6: 3 | E6: 4 | F6: 5 | G6: 6 | H6: 7 | I6: 8 | J6: 9 | K6: 10 | L6: 11 | M6: 12 | N6: 13 | O6: 14 | P6: 15 | Q6: 16 | R6: 17 | S6: 18 | T6: 19 | U6: 20 | V6: 21 | W6: 22 | X6: 23 | Y6: 24 | Z6: 25 | AA6: 26 | AB6: 27 | AC6: 28 | AD6: 29 | AE6: 30 | AF6: 31 | AG6: 32 | AH6: 33 | AI6: 34 | AJ6: 35 | AK6: 36 | AL6: 37 | AM6: 38 | AN6: 39 | AO6: 40 | AP6: 41 | AQ6: 42 | AR6: 43 | AS6: 44 | AT6: 45 | AU6: 46 | AV6: 47 | AW6: 48 | AX6: 49 | AY6: 50 | AZ6: 51
B7: 単価上申(円販売一般品) | N7: 案件番号： | R7: CD-1234567
C10: Step １： 起票区分を選択してください
D12: ◎ | E12: 販売単価上申書
B13: 1 | C13: 2 | G13: 6 | H13: 7 | I13: 8 | J13: 9 | K13: 10 | L13: 11 | M13: 12 | N13: 13 | O13: 14 | P13: 15 | Q13: 16 | R13: 17 | S13: 18 | T13: 19 | U13: 20 | V13: 21 | W13: 22 | X13: 23 | Y13: 24 | Z13: 25 | AA13: 26 | AB13: 27 | AC13: 28 | AD13: 29 | AE13: 30 | AF13: 31 | AG13: 32 | AH13: 33 | AI13: 34 | AJ13: 35 | AK13: 36 | AL13: 37 | AM13: 38 | AN13: 39 | AO13: 40 | AQ13: 41 | AR13: 42 | AS13: 43 | AT13: 44 | AU13: 45 | AV13: 46 | AW13: 47
B14: 2 | C14: Step ２： 一般品またはカスタムのいずれかを選択してください
D16: ○ | E16: 一般品
B17: 3
D18: ○ | E18: カスタム
C20: Step ３： 円販売または外貨販売のいずれかを選択してください
D22: ○ | E22: 円販売
B23: 2
D24: ○ | E24: 外貨販売
B36: 4
B38: 36
B39: 37

Sheet 円(PPM)
A1: 文書名： | I1: 顧客名 | M1: =変更来歴!M1 -> ヒロセ電機株式会社 | X1: システム | AA1: =変更来歴!AA1 -> 化学物質データ申請 | AK1: 作成者 | AN1: =変更来歴!AP7 -> 古竹 | AS1: 作成日 | AV1: =変更来歴!AL7 -> 46125 | AZ1: 書類番号
A2: intra-mart Accel Platform | I2: プロジェクト | M2: =変更来歴!M2 -> 新環境証明書システム移行 | AK2: 修正者 | AN2: =INDIRECT("変更来歴!AP" & COUNTA(変更来歴!AP7:'変更来歴'!AP39) + 6) -> 古竹 | AS2: 修正日 | AV2: =INDIRECT("変更来歴!AL" & COUNTA(変更来歴!AL7:'変更来歴'!AL39) + 6) -> 46190 | AZ2: =変更来歴!AX2 -> IMWF-53
A3: =変更来歴!A3 -> 画面設計書 | I3: 内容 | M3: =RIGHT(CELL("filename",A1),LEN(CELL("filename",A1))-FIND("]",CELL("filename",A1))) -> 円(PPM) | X3: 画面名 | AA3: =MID(CELL("filename"),FIND("]",CELL("filename"))+1,LEN(CELL("filename"))) & "画面" -> 表紙画面 | AS3: Rev | AV3: =INDIRECT("変更来歴!A" & COUNTA(変更来歴!A7:'変更来歴'!A39) + 6) -> dr1.5
A5: ="画面レイアウト"&"("&MID(CELL("filename"),FIND("]",CELL("filename"))+1,LEN(CELL("filename")))&")" -> 画面レイアウト(表紙) | BB5: Rev.
B6: 1 | C6: 2 | D6: 3 | E6: 4 | F6: 5 | G6: 6 | H6: 7 | I6: 8 | J6: 9 | K6: 10 | L6: 11 | M6: 12 | N6: 13 | O6: 14 | P6: 15 | Q6: 16 | R6: 17 | S6: 18 | T6: 19 | U6: 20 | V6: 21 | W6: 22 | X6: 23 | Y6: 24 | Z6: 25 | AA6: 26 | AB6: 27 | AC6: 28 | AD6: 29 | AE6: 30 | AF6: 31 | AG6: 32 | AH6: 33 | AI6: 34 | AJ6: 35 | AK6: 36 | AL6: 37 | AM6: 38 | AN6: 39 | AO6: 40 | AP6: 41 | AQ6: 42 | AR6: 43 | AS6: 44 | AT6: 45 | AU6: 46 | AV6: 47 | AW6: 48 | AX6: 49 | AY6: 50 | AZ6: 51
B7: 単価上申(円販売一般品) | N7: 案件番号： | R7: SA-PR123456
E8: 過去の申請から内容コピー
C10: 起票日 | F10: ： | H10: 2022/09/29
C11: 所属 | F11: ： | H11: ヒロセ電機株式会社/管理本部/ＩＴ統括部/情報システム企画課
C12: 社員番号 | F12: ： | H12: hirose | L12: 氏名 ： | O12: システム担当者
B13: 1 | C13: 2 | D13: 3 | E13: 4 | F13: 5 | G13: 6 | H13: 7 | I13: 8 | J13: 9 | K13: 10 | L13: 11 | M13: 12 | N13: 13 | O13: 14 | P13: 15 | Q13: 16 | R13: 17 | S13: 18 | T13: 19 | U13: 20 | V13: 21 | W13: 22 | X13: 23 | Y13: 24 | Z13: 25 | AA13: 26 | AB13: 27 | AC13: 28 | AD13: 29 | AE13: 30 | AF13: 31 | AG13: 32 | AH13: 33 | AI13: 34 | AJ13: 35 | AK13: 36 | AL13: 37 | AM13: 38 | AN13: 39 | AO13: 40 | AQ13: 41 | AR13: 42 | AS13: 43 | AT13: 44 | AU13: 45 | AV13: 46 | AW13: 47
B14: 2 | C14: 申請内容
C16: 起票区分 | H16: ◎ 単価上申書
B17: 3 | C17: タイトル*
C18: 得意先コード | T18: 得意先名* | AK18: 客先担当者名
C19: 案件種類* | P19: ▼ | T19: 希望承認期限* | Y19: 2022/9/29
C20: 口銭率 | L20: ☑ 口銭申請有り
B23: 2 | C23: プロジェクト情報
C25: 工事金額 | O25: 万円/月 | T25: 継続期間* | AG25: ヵ月 | AK25: 総工事金額 | AX25: 万円
C26: MFC PJ番号 | R26: MFC OPPORTUNITY番号
C27: 大分類* | H27: 大分類A | P27: ▼ | T27: 中分類* | Y27: 中分類B | AG27: ▼ | AK27: 機種* | AP27: 機種A | AX27: ▼
C28: 量産時期* | T28: 平均生産予定数量 | AG28: /月 | AK28: 競合名 | AX28: ▼
C29: 申請理由* | AX29: ▲
AX30: ▼
C31: 値引補填工事 | H31: 値引きしなければならない理由を記載してください | AX31: ▲
AX32: ▼
C33: 備考欄 | AX33: ▲
AX34: ▼
B37: 5 | C37: 申請価格入力 | AV37: 通貨：JPY
C39: 1行目の[貢献率]の桁数が異常です。入力内容を確認して下さい。
D40: 原計タイプ* | H40: ○ 技術原計 ◎ PPM原計 ○ コリア原計
B41: 6 | C41: No | D41: CL | H41: 品名* | N41: 形* | R41: 月間数量* | V41: 得意先要求 | Z41: 従来価格* | AD41: 申請価格* | AH41: PPM直接コスト* | AM41: 代理店売価 | AQ41: ピン@ | AT41: 競合名 | AX41: 備考
B42: 7 | V42: 価格
B43: 8 | C43: 1 | D43: 1130511471 | H43: RP17-13RA-12SD(71) | N43: R | Q43: ▼ | R43: 5000 | V43: 122.5 | Z43: 125 | AD43: 124 | AH43: 94.52 | AM43: 125 | AQ43: 10.3 | AT43: SMK
B44: 9 | C44: 2 | D44: 1135042200 | H44: RP34-8R-3PDL | N44: R | Q44: ▼ | R44: 5000 | V44: 39 | Z44: 40 | AD44: 40 | AH44: 36.89 | AM44: 41 | AQ44: 12.3 | AT44: 中国
B45: 10
B46: 11
B47: 12
B48: 13
B49: 14
...

Sheet 円(技術原計)
A1: 文書名： | I1: 顧客名 | M1: =変更来歴!M1 -> ヒロセ電機株式会社 | X1: システム | AA1: =変更来歴!AA1 -> 化学物質データ申請 | AK1: 作成者 | AN1: =変更来歴!AP7 -> 古竹 | AS1: 作成日 | AV1: =変更来歴!AL7 -> 46125 | AZ1: 書類番号
A2: intra-mart Accel Platform | I2: プロジェクト | M2: =変更来歴!M2 -> 新環境証明書システム移行 | AK2: 修正者 | AN2: =INDIRECT("変更来歴!AP" & COUNTA(変更来歴!AP7:'変更来歴'!AP39) + 6) -> 古竹 | AS2: 修正日 | AV2: =INDIRECT("変更来歴!AL" & COUNTA(変更来歴!AL7:'変更来歴'!AL39) + 6) -> 46190 | AZ2: =変更来歴!AX2 -> IMWF-53
A3: =変更来歴!A3 -> 画面設計書 | I3: 内容 | M3: =RIGHT(CELL("filename",A1),LEN(CELL("filename",A1))-FIND("]",CELL("filename",A1))) -> 円(技術原計) | X3: 画面名 | AA3: =MID(CELL("filename"),FIND("]",CELL("filename"))+1,LEN(CELL("filename"))) & "画面" -> 表紙画面 | AS3: Rev | AV3: =INDIRECT("変更来歴!A" & COUNTA(変更来歴!A7:'変更来歴'!A39) + 6) -> dr1.5
A5: ="画面レイアウト"&"("&MID(CELL("filename"),FIND("]",CELL("filename"))+1,LEN(CELL("filename")))&")" -> 画面レイアウト(表紙) | BB5: Rev.
B6: 1 | C6: 2 | D6: 3 | E6: 4 | F6: 5 | G6: 6 | H6: 7 | I6: 8 | J6: 9 | K6: 10 | L6: 11 | M6: 12 | N6: 13 | O6: 14 | P6: 15 | Q6: 16 | R6: 17 | S6: 18 | T6: 19 | U6: 20 | V6: 21 | W6: 22 | X6: 23 | Y6: 24 | Z6: 25 | AA6: 26 | AB6: 27 | AC6: 28 | AD6: 29 | AE6: 30 | AF6: 31 | AG6: 32 | AH6: 33 | AI6: 34 | AJ6: 35 | AK6: 36 | AL6: 37 | AM6: 38 | AN6: 39 | AO6: 40 | AP6: 41 | AQ6: 42 | AR6: 43 | AS6: 44 | AT6: 45 | AU6: 46 | AV6: 47 | AW6: 48 | AX6: 49 | AY6: 50 | AZ6: 51
B7: 単価上申(円販売一般品) | N7: 案件番号： | R7: SA-PR123456
E8: 過去の申請から内容コピー
C10: 起票日 | F10: ： | H10: 2022/09/29
C11: 所属 | F11: ： | H11: ヒロセ電機株式会社/管理本部/ＩＴ統括部/情報システム企画課
C12: 社員番号 | F12: ： | H12: hirose | L12: 氏名 ： | O12: システム担当者
B13: 1 | C13: 2 | D13: 3 | E13: 4 | F13: 5 | G13: 6 | H13: 7 | I13: 8 | J13: 9 | K13: 10 | L13: 11 | M13: 12 | N13: 13 | O13: 14 | P13: 15 | Q13: 16 | R13: 17 | S13: 18 | T13: 19 | U13: 20 | V13: 21 | W13: 22 | X13: 23 | Y13: 24 | Z13: 25 | AA13: 26 | AB13: 27 | AC13: 28 | AD13: 29 | AE13: 30 | AF13: 31 | AG13: 32 | AH13: 33 | AI13: 34 | AJ13: 35 | AK13: 36 | AL13: 37 | AM13: 38 | AN13: 39 | AO13: 40 | AQ13: 41 | AR13: 42 | AS13: 43 | AT13: 44 | AU13: 45 | AV13: 46 | AW13: 47
B14: 2 | C14: 申請内容
C16: 起票区分 | H16: ◎ 単価上申書
B17: 3 | C17: タイトル*
C18: 得意先コード | T18: 得意先名* | AK18: 客先担当者名
C19: 案件種類* | P19: ▼ | T19: 希望承認期限* | Y19: 2022/9/29
C20: 口銭率 | L20: ☑ 口銭申請有り
B23: 2 | C23: プロジェクト情報
C25: 工事金額 | O25: 万円/月 | T25: 継続期間* | AG25: ヵ月 | AK25: 総工事金額 | AX25: 万円
C26: MFC PJ番号 | R26: MFC OPPORTUNITY番号
C27: 大分類* | H27: 大分類A | P27: ▼ | T27: 中分類* | Y27: 中分類B | AG27: ▼ | AK27: 機種* | AP27: 機種A | AX27: ▼
C28: 量産時期* | T28: 平均生産予定数量 | AG28: /月 | AK28: 競合名 | AX28: ▼
C29: 申請理由* | AX29: ▲
AX30: ▼
C31: 値引補填工事 | H31: 値引きしなければならない理由を記載してください | AX31: ▲
AX32: ▼
C33: 備考欄 | AX33: ▲
AX34: ▼
B36: 4
B37: 5 | C37: 申請価格入力 | AV37: 通貨：JPY
D39: 原計タイプ* | H39: ◎ 技術原計 ○ PPM原計 ○ コリア原計
B40: 6 | C40: No | D40: CL | H40: 品名* | N40: 形* | R40: 月間数量* | V40: 得意先要求 | Z40: 従来価格* | AD40: 申請価格* | AH40: 製造原価* | AM40: 総原価* | AQ40: 代理店売価 | AU40: ピン@ | AX40: 競合名 | BB40: 備考
B41: 7 | V41: 価格
B42: 8 | C42: 1 | D42: 1250103874 | H42: HR25-9TP-16P(74) | N42: R | Q42: ▼ | R42: 1000 | V42: 980 | Z42: 1610 | AD42: 1035 | AH42: 510.27 | AM42: 796.03 | AU42: 64.7 | AX42: サンウー
B43: 9 | C43: 2 | D43: 1250109471 | H43: HR25-9TR-16S(71) | N43: R | Q43: ▼ | R43: 500 | V43: 500 | Z43: 794 | AD43: 630 | AH43: 247.92 | AM43: 483.47 | AU43: 39.4 | AX43: サンウー
B44: 10
B45: 11
B46: 12
B47: 13
B48: 14
...

Sheet 円(コリア原計)
A1: 文書名： | I1: 顧客名 | M1: =変更来歴!M1 -> ヒロセ電機株式会社 | X1: システム | AA1: =変更来歴!AA1 -> 化学物質データ申請 | AK1: 作成者 | AN1: =変更来歴!AP7 -> 古竹 | AS1: 作成日 | AV1: =変更来歴!AL7 -> 46125 | AZ1: 書類番号
A2: intra-mart Accel Platform | I2: プロジェクト | M2: =変更来歴!M2 -> 新環境証明書システム移行 | AK2: 修正者 | AN2: =INDIRECT("変更来歴!AP" & COUNTA(変更来歴!AP7:'変更来歴'!AP39) + 6) -> 古竹 | AS2: 修正日 | AV2: =INDIRECT("変更来歴!AL" & COUNTA(変更来歴!AL7:'変更来歴'!AL39) + 6) -> 46190 | AZ2: =変更来歴!AX2 -> IMWF-53
A3: =変更来歴!A3 -> 画面設計書 | I3: 内容 | M3: =RIGHT(CELL("filename",A1),LEN(CELL("filename",A1))-FIND("]",CELL("filename",A1))) -> 円(コリア原計) | X3: 画面名 | AA3: =MID(CELL("filename"),FIND("]",CELL("filename"))+1,LEN(CELL("filename"))) & "画面" -> 表紙画面 | AS3: Rev | AV3: =INDIRECT("変更来歴!A" & COUNTA(変更来歴!A7:'変更来歴'!A39) + 6) -> dr1.5
A5: ="画面レイアウト"&"("&MID(CELL("filename"),FIND("]",CELL("filename"))+1,LEN(CELL("filename")))&")" -> 画面レイアウト(表紙) | BB5: Rev.
B6: 1 | C6: 2 | D6: 3 | E6: 4 | F6: 5 | G6: 6 | H6: 7 | I6: 8 | J6: 9 | K6: 10 | L6: 11 | M6: 12 | N6: 13 | O6: 14 | P6: 15 | Q6: 16 | R6: 17 | S6: 18 | T6: 19 | U6: 20 | V6: 21 | W6: 22 | X6: 23 | Y6: 24 | Z6: 25 | AA6: 26 | AB6: 27 | AC6: 28 | AD6: 29 | AE6: 30 | AF6: 31 | AG6: 32 | AH6: 33 | AI6: 34 | AJ6: 35 | AK6: 36 | AL6: 37 | AM6: 38 | AN6: 39 | AO6: 40 | AP6: 41 | AQ6: 42 | AR6: 43 | AS6: 44 | AT6: 45 | AU6: 46 | AV6: 47 | AW6: 48 | AX6: 49 | AY6: 50 | AZ6: 51
B7: 単価上申(円販売一般品) | N7: 案件番号： | R7: SA-PR123456
E8: 過去の申請から内容コピー
C10: 起票日 | F10: ： | H10: 2022/09/29
C11: 所属 | F11: ： | H11: ヒロセ電機株式会社/管理本部/ＩＴ統括部/情報システム企画課
C12: 社員番号 | F12: ： | H12: hirose | L12: 氏名 ： | O12: システム担当者
B13: 1 | C13: 2 | D13: 3 | E13: 4 | F13: 5 | G13: 6 | H13: 7 | I13: 8 | J13: 9 | K13: 10 | L13: 11 | M13: 12 | N13: 13 | O13: 14 | P13: 15 | Q13: 16 | R13: 17 | S13: 18 | T13: 19 | U13: 20 | V13: 21 | W13: 22 | X13: 23 | Y13: 24 | Z13: 25 | AA13: 26 | AB13: 27 | AC13: 28 | AD13: 29 | AE13: 30 | AF13: 31 | AG13: 32 | AH13: 33 | AI13: 34 | AJ13: 35 | AK13: 36 | AL13: 37 | AM13: 38 | AN13: 39 | AO13: 40 | AQ13: 41 | AR13: 42 | AS13: 43 | AT13: 44 | AU13: 45 | AV13: 46 | AW13: 47
B14: 2 | C14: 申請内容
C16: 起票区分 | H16: ◎ 単価上申書
B17: 3 | C17: タイトル*
C18: 得意先コード | T18: 得意先名* | AK18: 客先担当者名
C19: 案件種類* | P19: ▼ | T19: 希望承認期限* | Y19: 2022/9/29
C20: 口銭率 | L20: ☑ 口銭申請有り
B23: 2 | C23: プロジェクト情報
C25: 工事金額 | O25: 万円/月 | T25: 継続期間* | AG25: ヵ月 | AK25: 総工事金額 | AX25: 万円
C26: MFC PJ番号 | R26: MFC OPPORTUNITY番号
C27: 大分類* | H27: 大分類A | P27: ▼ | T27: 中分類* | Y27: 中分類B | AG27: ▼ | AK27: 機種* | AP27: 機種A | AX27: ▼
C28: 量産時期* | T28: 平均生産予定数量 | AG28: /月 | AK28: 競合名 | AX28: ▼
C29: 申請理由* | AX29: ▲
AX30: ▼
C31: 値引補填工事 | H31: 値引きしなければならない理由を記載してください | AX31: ▲
AX32: ▼
C33: 備考欄 | AX33: ▲
AX34: ▼
B37: 5 | C37: 精算通貨
C39: レートタイプ* | G39: ○経営計画レート ○ 顧客契約レート ◎ その他のレート
B40: 6 | C40: No | D40: 通貨 | H40: レート
B41: 8 | C41: 1 | D41: USD | H41: 110
B42: 9 | C42: 2 | D42: EUR | H42: 125
B44: 10
B45: 5 | C45: 申請価格入力
D47: 原計タイプ* | H47: ○ 技術原計 ○ PPM原計 ◎ コリア原計
B48: 6 | C48: No | D48: CL | H48: 品名* | N48: 形* | R48: 月間数量* | V48: 原計通貨* | Z48: 純原価 | AD48: 申請通貨* | AH48: 申請価格* | AL48: 従来価格* | AP48: 物流コスト率% | AT48: 販社売価 | AX48: 代理店売価 | BB48: 得意先要求 | BF48: ピン@FOB | BJ48: 競合名 | BN48: 備考
B49: 7 | AT49: (外貨) | AX49: (外貨) | BB49: 価格 | BF49: 価格基準
B50: 8 | C50: 1 | D50: 4800215830 | H50: TF38-20S-0.5SV(830) | N50: KFH | Q50: ▼ | R50: 70000 | V50: USD | Y50: ▼ | Z50: 0.0673 | AD50: USD | AG50: ▼ | AH50: 0.1211 | AP50: 0.01 | AT50: 0.1359 | AX50: 0.151 | BB50: 0.151 | BF50: 0.0061
B51: 9 | C51: 2 | Q51: ▼ | Y51: ▼ | AG51: ▼
...

Sheet 外貨(PPM)
A1: 文書名： | I1: 顧客名 | M1: =変更来歴!M1 -> ヒロセ電機株式会社 | X1: システム | AA1: =変更来歴!AA1 -> 化学物質データ申請 | AK1: 作成者 | AN1: =変更来歴!AP7 -> 古竹 | AS1: 作成日 | AV1: =変更来歴!AL7 -> 46125 | AZ1: 書類番号
A2: intra-mart Accel Platform | I2: プロジェクト | M2: =変更来歴!M2 -> 新環境証明書システム移行 | AK2: 修正者 | AN2: =INDIRECT("変更来歴!AP" & COUNTA(変更来歴!AP7:'変更来歴'!AP39) + 6) -> 古竹 | AS2: 修正日 | AV2: =INDIRECT("変更来歴!AL" & COUNTA(変更来歴!AL7:'変更来歴'!AL39) + 6) -> 46190 | AZ2: =変更来歴!AX2 -> IMWF-53
A3: =変更来歴!A3 -> 画面設計書 | I3: 内容 | M3: =RIGHT(CELL("filename",A1),LEN(CELL("filename",A1))-FIND("]",CELL("filename",A1))) -> 外貨(PPM) | X3: 画面名 | AA3: =MID(CELL("filename"),FIND("]",CELL("filename"))+1,LEN(CELL("filename"))) & "画面" -> 表紙画面 | AS3: Rev | AV3: =INDIRECT("変更来歴!A" & COUNTA(変更来歴!A7:'変更来歴'!A39) + 6) -> dr1.5
A5: ="画面レイアウト"&"("&MID(CELL("filename"),FIND("]",CELL("filename"))+1,LEN(CELL("filename")))&")" -> 画面レイアウト(表紙) | BB5: Rev.
B6: 1 | C6: 2 | D6: 3 | E6: 4 | F6: 5 | G6: 6 | H6: 7 | I6: 8 | J6: 9 | K6: 10 | L6: 11 | M6: 12 | N6: 13 | O6: 14 | P6: 15 | Q6: 16 | R6: 17 | S6: 18 | T6: 19 | U6: 20 | V6: 21 | W6: 22 | X6: 23 | Y6: 24 | Z6: 25 | AA6: 26 | AB6: 27 | AC6: 28 | AD6: 29 | AE6: 30 | AF6: 31 | AG6: 32 | AH6: 33 | AI6: 34 | AJ6: 35 | AK6: 36 | AL6: 37 | AM6: 38 | AN6: 39 | AO6: 40 | AP6: 41 | AQ6: 42 | AR6: 43 | AS6: 44 | AT6: 45 | AU6: 46 | AV6: 47 | AW6: 48 | AX6: 49 | AY6: 50 | AZ6: 51
B7: 単価上申(外貨販売カスタム品) | O7: 案件番号： | S7: SA-PR123456
E8: 過去の申請から内容コピー
C10: 起票日 | F10: ： | H10: 2022/09/29
C11: 所属 | F11: ： | H11: ヒロセ電機株式会社/管理本部/ＩＴ統括部/情報システム企画課
C12: 社員番号 | F12: ： | H12: hirose | L12: 氏名 ： | O12: システム担当者
B13: 1 | C13: 2 | D13: 3 | E13: 4 | F13: 5 | G13: 6 | H13: 7 | I13: 8 | J13: 9 | K13: 10 | L13: 11 | M13: 12 | N13: 13 | O13: 14 | P13: 15 | Q13: 16 | R13: 17 | S13: 18 | T13: 19 | U13: 20 | V13: 21 | W13: 22 | X13: 23 | Y13: 24 | Z13: 25 | AA13: 26 | AB13: 27 | AC13: 28 | AD13: 29 | AE13: 30 | AF13: 31 | AG13: 32 | AH13: 33 | AI13: 34 | AJ13: 35 | AK13: 36 | AL13: 37 | AM13: 38 | AN13: 39 | AO13: 40 | AQ13: 41 | AR13: 42 | AS13: 43 | AT13: 44 | AU13: 45 | AV13: 46 | AW13: 47
B14: 2 | C14: 申請内容
C16: 起票区分 | H16: ◎ 単価上申書
B17: 3 | C17: タイトル*
C18: 得意先コード | T18: 得意先名* | AK18: 客先担当者名
C19: 案件種類* | P19: ▼ | T19: 希望承認期限* | Y19: 2022/9/29
C20: 口銭率 | K20: 0.05 | L20: ☑ 口銭申請有り
B23: 2 | C23: プロジェクト情報
C25: 工事金額 | O25: 万円/月 | T25: 継続期間* | AG25: ヵ月 | AK25: 総工事金額 | AX25: 万円
C26: 海外販社 | T26: SFDC工事番号
C27: 大分類 | H27: 大分類A | P27: ▼ | T27: 中分類 | Y27: 中分類B | AG27: ▼
C28: レップ社名 | T28: 量産時期 | AJ28: 用途(アプリケーション)
C29: 競合名 | P29: ▼ | T29: 生産セット台数 | AJ29: プロジェクトピーク金額 | AW29: 円/月
C30: 申請理由* | AX30: ▲
AX31: ▼
C32: 値引補填工事 | H32: 値引きしなければならない理由を記載してください | AX32: ▲
AX33: ▼
C34: 備考欄 | AX34: ▲
AX35: ▼
B38: 2 | C38: カスタム品申請情報
C40: 償却期間* | O40: ヵ月
B42: 4
B43: 5 | C43: 精算通貨
C45: レートタイプ* | G45: ○経営計画レート ○ 顧客契約レート ◎ その他のレート
B46: 6 | C46: No | D46: 通貨 | H46: レート
B47: 8 | C47: 1 | D47: USD | H47: 110
B48: 9 | C48: 2 | D48: EUR | H48: 125
B50: 10
B51: 5 | C51: 申請価格入力
D53: 原計タイプ* | H53: ○ 技術原計 ◎ PPM原計 ○ コリア原計
...

Sheet 外貨(技術原計)
A1: 文書名： | I1: 顧客名 | M1: =変更来歴!M1 -> ヒロセ電機株式会社 | X1: システム | AA1: =変更来歴!AA1 -> 化学物質データ申請 | AK1: 作成者 | AN1: =変更来歴!AP7 -> 古竹 | AS1: 作成日 | AV1: =変更来歴!AL7 -> 46125 | AZ1: 書類番号
A2: intra-mart Accel Platform | I2: プロジェクト | M2: =変更来歴!M2 -> 新環境証明書システム移行 | AK2: 修正者 | AN2: =INDIRECT("変更来歴!AP" & COUNTA(変更来歴!AP7:'変更来歴'!AP39) + 6) -> 古竹 | AS2: 修正日 | AV2: =INDIRECT("変更来歴!AL" & COUNTA(変更来歴!AL7:'変更来歴'!AL39) + 6) -> 46190 | AZ2: =変更来歴!AX2 -> IMWF-53
A3: =変更来歴!A3 -> 画面設計書 | I3: 内容 | M3: =RIGHT(CELL("filename",A1),LEN(CELL("filename",A1))-FIND("]",CELL("filename",A1))) -> 外貨(技術原計) | X3: 画面名 | AA3: =MID(CELL("filename"),FIND("]",CELL("filename"))+1,LEN(CELL("filename"))) & "画面" -> 表紙画面 | AS3: Rev | AV3: =INDIRECT("変更来歴!A" & COUNTA(変更来歴!A7:'変更来歴'!A39) + 6) -> dr1.5
A5: ="画面レイアウト"&"("&MID(CELL("filename"),FIND("]",CELL("filename"))+1,LEN(CELL("filename")))&")" -> 画面レイアウト(表紙) | BB5: Rev.
B6: 1 | C6: 2 | D6: 3 | E6: 4 | F6: 5 | G6: 6 | H6: 7 | I6: 8 | J6: 9 | K6: 10 | L6: 11 | M6: 12 | N6: 13 | O6: 14 | P6: 15 | Q6: 16 | R6: 17 | S6: 18 | T6: 19 | U6: 20 | V6: 21 | W6: 22 | X6: 23 | Y6: 24 | Z6: 25 | AA6: 26 | AB6: 27 | AC6: 28 | AD6: 29 | AE6: 30 | AF6: 31 | AG6: 32 | AH6: 33 | AI6: 34 | AJ6: 35 | AK6: 36 | AL6: 37 | AM6: 38 | AN6: 39 | AO6: 40 | AP6: 41 | AQ6: 42 | AR6: 43 | AS6: 44 | AT6: 45 | AU6: 46 | AV6: 47 | AW6: 48 | AX6: 49 | AY6: 50 | AZ6: 51
B7: 単価上申(円販売一般品) | N7: 案件番号： | R7: SA-PR123456
E8: 過去の申請から内容コピー
C10: 起票日 | F10: ： | H10: 2022/09/29
C11: 所属 | F11: ： | H11: ヒロセ電機株式会社/管理本部/ＩＴ統括部/情報システム企画課
C12: 社員番号 | F12: ： | H12: hirose | L12: 氏名 ： | O12: システム担当者
B13: 1 | C13: 2 | D13: 3 | E13: 4 | F13: 5 | G13: 6 | H13: 7 | I13: 8 | J13: 9 | K13: 10 | L13: 11 | M13: 12 | N13: 13 | O13: 14 | P13: 15 | Q13: 16 | R13: 17 | S13: 18 | T13: 19 | U13: 20 | V13: 21 | W13: 22 | X13: 23 | Y13: 24 | Z13: 25 | AA13: 26 | AB13: 27 | AC13: 28 | AD13: 29 | AE13: 30 | AF13: 31 | AG13: 32 | AH13: 33 | AI13: 34 | AJ13: 35 | AK13: 36 | AL13: 37 | AM13: 38 | AN13: 39 | AO13: 40 | AQ13: 41 | AR13: 42 | AS13: 43 | AT13: 44 | AU13: 45 | AV13: 46 | AW13: 47
B14: 2 | C14: 申請内容
C16: 起票区分 | H16: ◎ 単価上申書
B17: 3 | C17: タイトル*
C18: 得意先コード | T18: 得意先名* | AK18: 客先担当者名
C19: 案件種類* | P19: ▼ | T19: 希望承認期限* | Y19: 2022/9/29
C20: 口銭率 | K20: 0.05 | L20: ☑ 口銭申請有り
B23: 2 | C23: プロジェクト情報
C25: 工事金額 | O25: 万円/月 | T25: 継続期間* | AG25: ヵ月 | AK25: 総工事金額 | AX25: 万円
C26: 海外販社 | T26: SFDC工事番号
C27: 大分類 | H27: 大分類A | P27: ▼ | T27: 中分類 | Y27: 中分類B | AG27: ▼
C28: レップ社名 | T28: 量産時期 | AJ28: 用途(アプリケーション)
C29: 競合名 | P29: ▼ | T29: 生産セット台数 | AJ29: プロジェクトピーク金額 | AW29: 円/月
C30: 申請理由* | AX30: ▲
AX31: ▼
C32: 値引補填工事 | H32: 値引きしなければならない理由を記載してください | AX32: ▲
AX33: ▼
C34: 備考欄 | AX34: ▲
AX35: ▼
B38: 5 | C38: 精算通貨
C40: レートタイプ* | G40: ○経営計画レート ○ 顧客契約レート ◎ その他のレート
B41: 6 | C41: No | D41: 通貨 | H41: レート
B42: 8 | C42: 1 | D42: USD | H42: 110
B43: 9 | C43: 2 | D43: EUR | H43: 125
B45: 10
B46: 5 | C46: 申請価格入力
D48: 原計タイプ* | H48: ◎ 技術原計 ○ PPM原計 ○ コリア原計
B49: 6 | C49: No | D49: CL | H49: 品名* | N49: 形* | R49: 月間数量* | V49: 原計通貨* | Z49: 製造原価* | AE49: 総原価 | AJ49: 申請通貨* | AN49: FOB価格 | AR49: 従来FOB価格* | AV49: 物流コスト率 | AZ49: 販社売価 | BD49: 代理店売価 | BH49: 得意先 | BL49: ピン@FOB | BO49: 競合名 | BS49: 備考
B50: 7 | AV50: (%) | AZ50: (外貨) | BD50: (外貨) | BH50: 要求価格 | BL50: 価格基準
B51: 8 | C51: 1 | D51: 8311308000 | H51: BF4MC-(375161-01) | N51: OPT | Q51: ▼ | R51: 200 | V51: JPY | Y51: ▼ | Z51: 34690.32 | AE51: 46831.94 | AJ51: USD | AM51: ▼ | AN51: 547.1195 | AR51: 560 | AV51: 0.045 | AZ51: 674
...

Sheet 外貨(コリア原計)
A1: 文書名： | I1: 顧客名 | M1: =変更来歴!M1 -> ヒロセ電機株式会社 | X1: システム | AA1: =変更来歴!AA1 -> 化学物質データ申請 | AK1: 作成者 | AN1: =変更来歴!AP7 -> 古竹 | AS1: 作成日 | AV1: =変更来歴!AL7 -> 46125 | AZ1: 書類番号
A2: intra-mart Accel Platform | I2: プロジェクト | M2: =変更来歴!M2 -> 新環境証明書システム移行 | AK2: 修正者 | AN2: =INDIRECT("変更来歴!AP" & COUNTA(変更来歴!AP7:'変更来歴'!AP39) + 6) -> 古竹 | AS2: 修正日 | AV2: =INDIRECT("変更来歴!AL" & COUNTA(変更来歴!AL7:'変更来歴'!AL39) + 6) -> 46190 | AZ2: =変更来歴!AX2 -> IMWF-53
A3: =変更来歴!A3 -> 画面設計書 | I3: 内容 | M3: =RIGHT(CELL("filename",A1),LEN(CELL("filename",A1))-FIND("]",CELL("filename",A1))) -> 外貨(コリア原計) | X3: 画面名 | AA3: =MID(CELL("filename"),FIND("]",CELL("filename"))+1,LEN(CELL("filename"))) & "画面" -> 表紙画面 | AS3: Rev | AV3: =INDIRECT("変更来歴!A" & COUNTA(変更来歴!A7:'変更来歴'!A39) + 6) -> dr1.5
A5: ="画面レイアウト"&"("&MID(CELL("filename"),FIND("]",CELL("filename"))+1,LEN(CELL("filename")))&")" -> 画面レイアウト(表紙) | BB5: Rev.
B6: 1 | C6: 2 | D6: 3 | E6: 4 | F6: 5 | G6: 6 | H6: 7 | I6: 8 | J6: 9 | K6: 10 | L6: 11 | M6: 12 | N6: 13 | O6: 14 | P6: 15 | Q6: 16 | R6: 17 | S6: 18 | T6: 19 | U6: 20 | V6: 21 | W6: 22 | X6: 23 | Y6: 24 | Z6: 25 | AA6: 26 | AB6: 27 | AC6: 28 | AD6: 29 | AE6: 30 | AF6: 31 | AG6: 32 | AH6: 33 | AI6: 34 | AJ6: 35 | AK6: 36 | AL6: 37 | AM6: 38 | AN6: 39 | AO6: 40 | AP6: 41 | AQ6: 42 | AR6: 43 | AS6: 44 | AT6: 45 | AU6: 46 | AV6: 47 | AW6: 48 | AX6: 49 | AY6: 50 | AZ6: 51
B7: 単価上申(円販売一般品) | N7: 案件番号： | R7: SA-PR123456
E8: 過去の申請から内容コピー
C10: 起票日 | F10: ： | H10: 2022/09/29
C11: 所属 | F11: ： | H11: ヒロセ電機株式会社/管理本部/ＩＴ統括部/情報システム企画課
C12: 社員番号 | F12: ： | H12: hirose | L12: 氏名 ： | O12: システム担当者
B13: 1 | C13: 2 | D13: 3 | E13: 4 | F13: 5 | G13: 6 | H13: 7 | I13: 8 | J13: 9 | K13: 10 | L13: 11 | M13: 12 | N13: 13 | O13: 14 | P13: 15 | Q13: 16 | R13: 17 | S13: 18 | T13: 19 | U13: 20 | V13: 21 | W13: 22 | X13: 23 | Y13: 24 | Z13: 25 | AA13: 26 | AB13: 27 | AC13: 28 | AD13: 29 | AE13: 30 | AF13: 31 | AG13: 32 | AH13: 33 | AI13: 34 | AJ13: 35 | AK13: 36 | AL13: 37 | AM13: 38 | AN13: 39 | AO13: 40 | AQ13: 41 | AR13: 42 | AS13: 43 | AT13: 44 | AU13: 45 | AV13: 46 | AW13: 47
B14: 2 | C14: 申請内容
C16: 起票区分 | H16: ◎ 単価上申書
B17: 3 | C17: タイトル*
C18: 得意先コード | T18: 得意先名* | AK18: 客先担当者名
C19: 案件種類* | P19: ▼ | T19: 希望承認期限* | Y19: 2022/9/29
C20: 口銭率 | K20: 0.05 | L20: ☑ 口銭申請有り
B23: 2 | C23: プロジェクト情報
C25: 工事金額 | O25: 万円/月 | T25: 継続期間* | AG25: ヵ月 | AK25: 総工事金額 | AX25: 万円
C26: 海外販社 | T26: SFDC工事番号
C27: 大分類 | H27: 大分類A | P27: ▼ | T27: 中分類 | Y27: 中分類B | AG27: ▼
C28: レップ社名 | T28: 量産時期 | AJ28: 用途(アプリケーション)
C29: 競合名 | P29: ▼ | T29: 生産セット台数 | AJ29: プロジェクトピーク金額 | AW29: 円/月
C30: 申請理由* | AX30: ▲
AX31: ▼
C32: 値引補填工事 | H32: 値引きしなければならない理由を記載してください | AX32: ▲
AX33: ▼
C34: 備考欄 | AX34: ▲
AX35: ▼
B38: 5 | C38: 精算通貨
C40: レートタイプ* | G40: ○経営計画レート ○ 顧客契約レート ◎ その他のレート
B41: 6 | C41: No | D41: 通貨 | H41: レート
B42: 8 | C42: 1 | D42: USD | H42: 110
B43: 9 | C43: 2 | D43: EUR | H43: 125
B45: 10
B46: 5 | C46: 申請価格入力
D48: 原計タイプ* | H48: ○ 技術原計 ○ PPM原計 ◎ コリア原計
B49: 6 | C49: No | D49: CL | H49: 品名* | N49: 形* | R49: 月間数量* | V49: 原計通貨* | Z49: 純原価 | AE49: 申請通貨* | AI49: FOB価格 | AM49: 従来FOB価格* | AQ49: 物流コスト率 | AU49: 販社売価 | AY49: 代理店売価 | BC49: 得意先 | BG49: ピン@FOB | BJ49: 競合名 | BN49: 備考
B50: 7 | AQ50: (%) | AU50: (外貨) | AY50: (外貨) | BC50: 要求価格 | BG50: 価格基準
B51: 8 | C51: 1 | D51: 4800215830 | H51: TF38-20S-0.5SV(830) | N51: KFH | Q51: ▼ | R51: 70000 | V51: USD | Y51: ▼ | Z51: 0.0673 | AE51: USD | AH51: ▼ | AI51: 0.1211 | AM51: 0.12 | AQ51: 0.01 | AU51: 0.1359 | AY51: 0.151 | BC51: 0.151 | BG51: 0.0061 | BJ51: JAE
...
