Workbook
Name txtDatabaseName: "テキスト 8"
Name txtTableName: "テキスト 2"
Name txtUserName: "テキスト 4"

Sheet 表紙
D3: ヒロセ電機株式会社
D4: 4S デジタルトランスフォーメーション・プラットフォーム構築
G7: 画面要件定義書（フロント）
G10: 化学物質データ申請確認画面
G12: =INDEX(改版履歴!B4:B32,COUNTA(改版履歴!B4:B32)) -> 1.20
AH31: =INDEX(改版履歴!D4:D32,COUNTA(改版履歴!D4:D32)) -> 45387
Z33: 株式会社 ＪＳＯＬ

Sheet 改版履歴
B1: 改版履歴
B3: 版数 | C3: 改版者 | D3: 改版日 | E3: 改版頁 | F3: 改版履歴
B4: 1 | C4: JSOL劉 | D4: 43207 | E4: - | F4: 新規作成
B5: 1.01 | C5: JSOL劉 | D5: 43210 | E5: レイアウト（PC) | F5: 顧客レビュー後に以下の修正を行いました。 顧客要望で、ボタン上に表示する言語を【英語[日本語]】のように、修正しました。 顧客要望で、申請リスト上のチェック記号を「YES」に統一しました。 顧客要望で、URL上の言語パラメータによって、画面に表示する言語を切り替える機能を追記しました（ラベル化）。
B6: 1.02 | C6: JSOL劉 | D6: 43210 | E6: レイアウト（PC) | F6: 顧客レビュー後に以下の修正を行いました。 顧客要望で、ボタン上に表示する言語を【英語[日本語]】のように、修正しました。 顧客要望で、申請リスト上のチェック記号を「YES」に統一しました。 顧客要望で、URL上の言語パラメータによって、画面に表示する言語を切り替える機能を追記しました（ラベル化）。
B7: 1.03 | C7: JSOL谷内 | D7: 43276 | E7: レイアウト（PC) | F7: 項目ごとに番号を付与し、説明を右側の欄に記載。
B8: 1.03 | C8: JSOL谷内 | D8: 43276 | E8: 画面項目、画面状態、入力チェック、処理詳細 | F8: 説明を全面的に書き直し
B9: 1.04 | C9: JSOL谷内 | D9: 43279 | E9: レイアウト、処理項目、画面状態 | F9: レイアウト：エラーメッセージ領域、ダイアログに表示する申請件数を追加 処理項目：申請可否の処理をより具体的に記載 画面状態：申請エラー時のケースを追加
B10: 1.05 | C10: JSOL谷内 | D10: 43280 | E10: 申請CSVファイルについて 初期表示処理 チェック結果処理について | F10: シートを新規作成。このほか全シートについて、内部指摘事項を取り込み。
B11: 1.06 | C11: JSOL王 | D11: 43287 | E11: 画面項目、処理詳細、出力編集仕様(DB)、出力編集仕様(申請CSV)、ダウンロードCSVファイルについて、申請CSVファイルについて、初期表示処理 チェック結果処理について | F11: 内部指摘事項を取り込み。
B12: 1.07 | C12: JSOL王 | D12: 43301 | E12: 画面項目、処理詳細、出力編集仕様(DB)、出力編集仕様(申請CSV)、ダウンロードCSVファイルについて、申請CSVファイルについて、初期表示処理 チェック結果処理について | F12: 内部指摘事項を取り込み。
B13: 1.08 | C13: JSOL王 | D13: 43306 | E13: 処理詳細 | F13: ・処理詳細以下の箇所の改修 ■A－１－４－２．取得した製品照明書の情報と画面表示のマッピング ■A－２－３取得した製品証明書の情報とダウンロードCSV項目のマッピング Ａ－３－２．申請CSVファイル出力にて証明書順番情報の導出元
B14: 1.09 | C14: JSOL鈴木 | D14: 43364 | E14: レイアウト（PC） | F14: お客様指摘対応 ・概要の「社員権限」を「販社以上の権限」に修正
B15: 1.1 | C15: JSOL鈴木 | D15: 43386 | E15: レイアウト（PC）、申請CSVファイルについて | F15: 申請書を格納するパスをS3に修正
B16: 1.11 | C16: JSOL水本 | D16: 43469 | E16: レイアウト（PC）、申請CSVファイルについて | F16: 申請書を格納するパスの導出元をシステムマスタからプロパティに変更 パスから/prd_4s_privateを削除
B17: 1.12 | C17: JSOL若林 | D17: 43490 | E17: 処理詳細 | F17: HRS-3963 前画面のCLコード項目に、ハイフンなし形式で入力した場合を考慮した処理を追加
B18: 1.13 | C18: JSOL王 | D18: 43662 | E18: レイアウト（PC）、画面項目、処理詳細 | F18: 4S-1760 ・レイアウト（PC）：代理店権限で利用できるように追加 ・画面項目：2.6と2.7と2.9の備考を修正 ・処理詳細：代理店権限のロジックを追加
B19: 1.14 | C19: JSOL王 | D19: 43698 | E19: レイアウト（PC）、処理詳細 | F19: 4S-1760 ・レイアウト（PC）：'Contact'の説明文を追加 ・処理詳細：代理店申請不可の場合、「Contact」の文字で表示するように修正
B20: 1.15 | C20: JSOL神田 | D20: 43784 | E20: レイアウト（PC） ダウンロードCSVファイルについて | F20: 【4S-1298】 ・レイアウト（PC）：別シート「ダウンロードCSVファイルについて」参照の旨を追記 ・ダウンロードCSVファイルについて：CLコード昇順にて出力する旨を追記
B21: 1.16 | C21: JSOL王 | D21: 44294 | E21: レイアウト（PC） | F21: 4S-1760 ・レイアウト（PC）：テーブルレイアウトを実装に合わせように修正
B22: 1.17 | C22: JSOL王 | D22: 44299 | E22: レイアウト（PC）、処理詳細 | F22: 4S-1987 ・Requestの場合、チェックボックスを出力しないように修正
B23: 1.18 | C23: JSOL王 | D23: 44299 | E23: レイアウト（PC）、処理詳細、ダウンロードCSVファイルについて、申請CSVファイルについて | F23: 4S-2441 SVHC調査報告書の対応で改修
B24: 1.19 | C24: JSOL石井 | D24: 45370 | E24: レイアウト（PC）、画面項目、画面状態、入力チェック、処理詳細、出力編集仕様、ダウンロードCSVファイルについて | F24: 4S-3037 ・「製品名」を用いた申請ができるように変更 ・「製品名」「新製品区分」「製品販売状況」「PCN番号」の確認ができるように変更 ※表示項目として、「製品名」「新製品区分」「製品販売状況」「PCN番号」を追加 ※項目の並び順を「CLコード昇順」から「製品名昇順」「CLコード昇順」に変更 ※申請チェックボックスの件数チェックを追加 ※登録項目として、「製品名」「新製品区分」「製品販売状況」「PCN番号」を追加 ・「システムに製品の該当なし」の時の背景色の赤色について補記 ・軽微な誤記を修正 ・別ブック「SERP110_帳票定義書_環境証明書申請製品一覧.xlsx」に一部の記載を統合
B25: 1.20 | C25: JSOL仲渡 | D25: 45387 | E25: レイアウト（PC）、画面項目、画面状態、出力編集仕様、ダウンロードCSVファイルについて | F25: 4S-3069 得意先コードを提出先企業名に変更

Sheet レイアウト（PC）
A1: 画面要件定義書（レイアウト) | K1: システム名 (System Name) | Q1: 業務名 Business Name | X1: 画面名 Screen Name | AE1: 作成者 Created By | AK1: 作成日 Created On | AQ1: 更新者 Updated By | AW1: 更新日 Updated On
K2: =表紙!D4 -> 4S デジタルトランスフォーメーション・プラットフォーム構築 | Q2: SE | X2: SEFE220 | AE2: =改版履歴!C4 -> JSOL劉 | AK2: =改版履歴!D4 -> 43207 | AQ2: =INDEX(改版履歴!C4:C32,COUNTA(改版履歴!C4:C32)) -> JSOL仲渡 | AW2: =INDEX(改版履歴!D4:D32,COUNTA(改版履歴!D4:D32)) -> 45387
Q3: グリーンマイスター | X3: =表紙!G10 -> 化学物質データ申請確認画面
A5: 概要 (Overview)
A6: 販社代理店以上の権限（社員権限・販社権限・代理店権限）を持つログイン中のユーザーが化学物質データ申請画面にて、「次へ」ボタンを押下すると、化学物質データ申請確認画面に遷移される。 この画面にて、製品選択一覧のCSVダウンロードとDownLoad依頼CSVファイルの作成が可能とする。
A11: JSP
A14: 画面構成 (Screen) | BB14: 機能仕様
BB16: ※画面構成要素のうち、説明が必要な画面項目のみ記載する
BC18: 1. パンくずリストエリア
BD19: 1.1 パンくずリスト
BE20: 以下のようにパンくずリストを表示する。
BE21: 『製品トップ > 化学物質データ申請確認』
BC23: 2. 申請確認エリア
BD24: 2.1 初期申請製品数
BE25: 申請画面で入力した製品名/CL-Noを基に
BE26: 申請確認画面で表示された製品数
BE27: ※重複、製品データ該当なしの件数も含む
BD29: 2.2 申請に対するチェック結果の説明
BE30: 申請画面で申請された内容に対して、
BE31: 化学物質データ製品情報テーブルのデータと照合して
BE32: 得られる、申請可能かどうかの結果データの読み方の
BE33: 説明書き。
BE34: "Non-compliant"は赤字で表示する
BD36: 2.3 提出先企業名
BE37: 申請画面で入力された提出先企業名の値を表示する。
BD39: 2.4 エンドユーザー
BE40: 申請画面で入力されたエンドユーザーの値を表示する。
BD42: 2.5 CSVダウンロードボタン
BE43: 押下すると、一覧内に表示している製品の
BE44: 帳票判定のcsvのダウンロードを行う。
BE45: ※チェックボックスのチェックの有無は問わず全件出力。
BE46: ※詳細は別シート「ダウンロードCSVファイルについて」を参照
BD48: 2.6 申請チェックボックス
BE49: 申請したい製品にチェックを付ける。
BE50: 1つの製品について、申請された証明書種類の証明書に
BE51: 対応しているかどうかをチェックした結果により、
BE53: 表示/非表示が切り替わる
BE54: ["YES"が1つ以上ある場合]
BF55: チェックが付いた状態でチェックボックスが表示される。
BE56: ["YES"の証明書ない場合]
...

Sheet 画面項目
A1: 画面設計書（画面項目) Screen Design Document (Screen Items) | K1: システム名 (System Name) | Q1: システム名 (System Name) | W1: 業務名 Business Name | AD1: 画面名 Screen Name | AK1: 作成者 Created By | AQ1: 作成日 Created On | AW1: 更新者 Updated By | BC1: 更新日 Updated On
K2: 4S デジタルトランスフォーメーション・プラットフォーム構築 | Q2: =表紙!D4 -> 4S デジタルトランスフォーメーション・プラットフォーム構築 | W2: SE | AD2: SEFE220 | AK2: =改版履歴!C4 -> JSOL劉 | AQ2: =改版履歴!D4 -> 43207 | AW2: =INDEX(改版履歴!C4:C32,COUNTA(改版履歴!C4:C32)) -> JSOL仲渡 | BC2: =INDEX(改版履歴!D4:D32,COUNTA(改版履歴!D4:D32)) -> 45387
W3: グリーンマイスター | AD3: =表紙!G10 -> 化学物質データ申請確認画面
A5: 画面項目(Screen Items)
A6: 必須記入 | AF6: OOTB以外 | CT6: 単機能テスト
A7: 項番 (No) | C7: 項目名(Item Name) | Q7: 論理項目種別 (Logical Item Type) | X7: 固定/可変 (Fixed/Variable) | AB7: I/O | AD7: OOTB | AF7: 入力桁数 (Input Digits) | AJ7: 表示ラベルキー （Display Label Key) | AP7: 初期値 (Default Value) | BA7: 導出元 (Source) | BK7: 備考 (Comment) | CT7: 初回 | DD7: 修正後 | DN7: テスト観点 | DV7: 備考
C8: エリア （Area） | J8: 項目名 (Item Name) | CT8: 確認日 | CX8: 確認者 | DB8: 判定 | DD8: 確認日 | DH8: 確認者 | DL8: 判定
A9: 1 | C9: パンくずリストエリア
A10: 1.1 | J10: パンくずリスト | Q10: Anchor Text | X10: Fixed | AB10: O | AD10: ○ | AF10: - | AP10: - | BA10: -
A11: 2 | C11: 申請確認エリア | AP11: - | BA11: -
A12: 2.1 | J12: 初期申請製品数 | Q12: Text Output | X12: Variable | AB12: O | AD12: × | AP12: 申請確認画面で表示された製品数 ※重複、製品データ該当なしの件数も含む | BA12: 申請画面からのHTTPパラメータ
A13: 2.2 | J13: 申請に対するチェック結果の説明 | Q13: Text Output | X13: Fixed | AB13: O | AD13: × | AP13: - | BA13: -
A14: 2.3 | J14: 提出先企業名 | Q14: Text Output | X14: Variable | AB14: O | AD14: × | AP14: 申請画面からフォーム送信される「提出先企業名」パラメータの値 | BA14: 申請画面からのHTTPパラメータ
A15: 2.4 | J15: エンドユーザー | Q15: Text Output | X15: Variable | AB15: O | AD15: × | AP15: 申請画面からフォーム送信される「エンドユーザー」パラメータの値 | BA15: 申請画面からのHTTPパラメータ
A16: 2.5 | J16: CSVダウンロードボタン | Q16: Image Button | X16: Fixed | AB16: O | AD16: × | AP16: - | BA16: -
A17: 2.6 | J17: 申請チェックボックス | Q17: Loop Table | X17: Variable | AB17: I/O | AD17: × | AP17: 申請可否の情報 | BA17: 処理項目：項番1参照 | BK17: ※画面表示フォーマットは「処理詳細」シートの「■A－１－７－２．製品証明書情報取得処理よりエラーハンドリングフォーマット」を参照する
A18: 2.7 | J18: 製品名 | Q18: Loop Table | X18: Variable | AB18: O | AD18: × | AP18: 申請画面からフォーム送信される「製品名/CL-No」の配列パラメータの値、または、「環境証明書申請製品情報」の「製品名」の値 | BA18: 申請画面からのHTTPパラメータ HrsChemicalSubstanceProduct.partNo | BK18: <表示内容>（製品名とCLコード） ①申請画面からフォーム送信される「製品名/CL-No」を基に「環境証明書申請製品情報」を取得できた場合 ・画面項目.製品名：データ「環境証明書申請製品情報」の「製品名」を表示する ・画面項目.CLコード：データ「環境証明書申請製品情報」の「CLコード」を表示する ②上記①でない場合 1）申請画面からフォーム送信される「製品名/CL-No」の配列パラメータ値が 「HrsNo形式」（数値11桁）、または、「CLコード形式」（CL9999-9999-9-99）の場合 ・画面項目.製品名："-"（ハイフン）を表示する ・画面項目.CLコード：申請画面からフォーム送信される「製品名/CL-No」の配列パラメータ値を表示する。 2）上記1）でない場合 ・画面項目.製品名：申請画面からフォーム送信される「製品名/CL-No」の配列パラメータ値を表示する。 ・画面項目.CLコード："-"（ハイフン）を表示する ※値がないときは"-"（ハイフン）を表示する。 （値がないときとはレコードなしや値がnullの場合を指す。従って、例えば値がスペースなどのときは、スペースという値があると判定）
A19: 2.8 | J19: CL（製品番号） | Q19: Loop Table | X19: Variable | AB19: O | AD19: × | AP19: 申請画面からフォーム送信される「製品名/CL-No」の配列パラメータの値、または、「環境証明書申請製品情報」の「CLコード」の値 | BA19: 申請画面からのHTTPパラメータ HrsChemicalSubstanceProduct.clCode | BK19: <表示内容> 上記の「製品名」の「<表示内容>（製品名とCLコード）」を参照 ※画面表示フォーマットは「処理詳細」シートの「■A－１－７－２．製品証明書情報取得処理よりエラーハンドリングフォーマット」を参照する
A20: 2.9 | J20: 新製品区分 | Q20: Loop Table | X20: Variable | AB20: O | AD20: × | AP20: 取得した「製品」の「新製品区分」の値 | BA20: HrsProduct.newProductClass | BK20: ※値がないときは"-"（ハイフン）を表示する。 （値がないときとはレコードなしや値がnullの場合を指す。従って、例えば値がスペースなどのときは、スペースという値があると判定）
A21: 2.10 | J21: 製品販売状況 | Q21: Loop Table | X21: Variable | AB21: O | AD21: × | AP21: 取得した「製品」より判定した「製品販売状況区分」のラベル値 | BA21: HrsProductを基に判定した「製品販売状況」 ※判定方法の詳細は 別ブック「SERP070_帳票定義書_製品一覧（フロント）.xlsx」の「帳票定義」シートの「販売状況」を参照 | BK21: ※値がないときは"-"（ハイフン）を表示する。 （値がないときとはレコードなしや値がnullの場合を指す。従って、例えば値がスペースなどのときは、スペースという値があると判定）
A22: 2.11 | J22: PCN番号 | Q22: Loop Table | X22: Variable | AB22: O | AD22: × | AP22: 取得した「製品」の「変更通知No.」の値 | BA22: HrsProduct.terminationPlanDocumentNo | BK22: ※値がないときは"-"（ハイフン）を表示する。 （値がないときとはnullの場合を指す。従って、例えば値がスペースなどのときは、スペースという値があると判定）
A23: 2.12 | J23: 申請された証明書種類 | Q23: Loop Table | X23: Variable | AB23: O | AD23: × | AP23: 申請画面からフォーム送信される「化学物質データ選択」配列パラメータの値 | BA23: 申請画面からのHTTPパラメータ
A24: 2.13 | J24: 製品毎の申請可否チェック結果 | Q24: Loop Table | X24: Variable | AB24: O | AD24: × | AP24: 2.8の製品番号に対応する証明書毎のチェック結果 | BA24: HrsChemicalSubstanceProduct.available HrsChemicalSubstanceProduct.request HrsChemicalSubstanceProduct.nonCompliant ※処理詳細の「■A－１－２－２取得した製品照明書の情報と画面表示のマッピング」を参照する | BK24: ※画面表示フォーマットは「処理詳細」シートの「■A－１－７－２．製品証明書情報取得処理よりエラーハンドリングフォーマット」を参照する
A25: 2.14 | J25: 戻る | Q25: Image Button | X25: Fixed | AB25: O | AD25: × | AP25: - | BA25: -
A26: 2.15 | J26: 申請 | Q26: Image Button | X26: Fixed | AB26: O | AD26: × | AP26: - | BA26: -
A27: 2.16 | J27: いいえボタン | Q27: Image Button | X27: Fixed | AB27: O | AD27: × | AP27: - | BA27: -
A28: 2.17 | J28: はいボタン | Q28: Image Button | X28: Fixed | AB28: O | AD28: × | AP28: - | BA28: -
A29: 2.18 | J29: 申請製品数 | Q29: Text Output | X29: Variable | AB29: O | AD29: × | AP29: - | BA29: - | BK29: 選択された製品の件数を表示する。
A30: 2.19 | J30: エラーメッセージ | Q30: Text Output | X30: Variable | AB30: O | AD30: × | AP30: - | BA30: -
A33: 処理項目(Process Items) | CT33: 単機能テスト
A34: 項番 (No) | C34: 処理名 (Process Name) | J34: イベント発生元（論理項目名） (Event Source(Logical Item Name)) | X34: イベント (Event) | AE34: サーバ ／クライアント | AM34: 遷移先画面ID (Transition Destination Screen ID) | AW34: 概要 (Comment) | CT34: 初回 | DD34: 修正後 | DN34: テスト観点 | DV34: 備考
CT35: 確認日 | CX35: 確認者 | DB35: 判定 | DD35: 確認日 | DH35: 確認者 | DL35: 判定
A36: 1 | C36: 初期画面表示 | Q36: 本画面に遷移 | X36: Onload | AE36: サーバ | AM36: - | AW36: ※処理詳細の「Ａ－１．画面初期表示について」を参照する | DD36: =IF(EXACT($DB36,"OK"),"-","") | DH36: =IF(EXACT($DB36,"OK"),"-","") | DL36: =IF(EXACT($DB36,"OK"),"-","")
A37: 2 | C37: 申請データダウンロード | Q37: CSVダウンロードボタン | X37: Click | AE37: サーバ | AM37: - | AW37: 申請画面で入力された製品番号をキーとして環境証明書申請製品情報テーブルから各証明書の情報を取得して対応するCSVのフォーマットで出力する。 ※処理詳細の「Ａ－２．CSVダウンロードについて」を参照する。 | DD37: =IF(EXACT($DB37,"OK"),"-","") | DH37: =IF(EXACT($DB37,"OK"),"-","") | DL37: =IF(EXACT($DB37,"OK"),"-","")
A38: 3 | C38: 戻る | Q38: 戻るボタン | X38: Click | AE38: サーバ | AM38: SEFE210_画面要件定義書_化学物質データ申請画面 | DD38: =IF(EXACT($DB38,"OK"),"-","") | DH38: =IF(EXACT($DB38,"OK"),"-","") | DL38: =IF(EXACT($DB38,"OK"),"-","")
A39: 2 | C39: 申請証明書数表示 | J39: 申請確認ダイアログ | Q39: 画面項目2.18 申請製品数 | X39: Click | AE39: クライアント | AM39: - | AW39: 画面項目2.6でチェックが付いているチェック数 | DD39: =IF(EXACT($DB39,"OK"),"-","") | DH39: =IF(EXACT($DB39,"OK"),"-","") | DL39: =IF(EXACT($DB39,"OK"),"-","")
A40: 4 | C40: 申請 | Q40: 申請ボタン | X40: Click | AE40: クライアント | AM40: - | AW40: ■チェックボックスが一つも選択されない場合、 「申請」ボタンは非活性となる。 ■チェックボックスが一つ以上選択さてている場合、 「申請確認ダイアログ」がポップアップで表示される。 | DD40: =IF(EXACT($DB40,"OK"),"-","") | DH40: =IF(EXACT($DB40,"OK"),"-","") | DL40: =IF(EXACT($DB40,"OK"),"-","")
A41: 5 | C41: はいボタン | J41: 申請確認ダイアログ | Q41: はいボタン | X41: Click | AE41: サーバ | AM41: 「申請処理」成功時： SEFE230_画面要件定義書_化学物質データ申請完了画面 「申請処理」エラー時： 遷移なし | AW41: 申請確認ダイアログをクローズする。 ※処理詳細の「Ａ－３．申請について」を参照する。 ※「申請処理」エラー時 ・入力チェックエラーが発生する場合、該当のエラーメッセージを2.19の画面項目に表示する。 ※「入力チェック」シート参照 ・処理エラーが発生する場合、message.E.F.000031で定義されているエラーメッセージを2.19の画面項目に表示する。 | DD41: =IF(EXACT($DB41,"OK"),"-","") | DH41: =IF(EXACT($DB41,"OK"),"-","") | DL41: =IF(EXACT($DB41,"OK"),"-","")
A42: 6 | C42: いいえボタン | J42: 申請確認ダイアログ | Q42: いいえボタン | X42: Click | AE42: クライアント | AM42: - | AW42: 申請確認ダイアログをクローズして、申請処理は実行しない。 | DD42: =IF(EXACT($DB42,"OK"),"-","") | DH42: =IF(EXACT($DB42,"OK"),"-","") | DL42: =IF(EXACT($DB42,"OK"),"-","")
C45: 利用可能な論理項目種別 | P45: 固定/可変 | U45: I/O | Y45: OOTB
...

Sheet 画面状態
A1: 画面設計書（画面状態) Screen Design Document(Screen State) | K1: システム名 (System Name) | Q1: 業務名 Business Name | X1: 画面名 Screen Name | AE1: 作成者 Created By | AK1: 作成日 Created On | AQ1: 更新者 Updated By | AW1: 更新日 Updated On
K2: =表紙!D4 -> 4S デジタルトランスフォーメーション・プラットフォーム構築 | Q2: SE | X2: SEFE220 | AE2: =改版履歴!C4 -> JSOL劉 | AK2: =改版履歴!D4 -> 43207 | AQ2: =INDEX(改版履歴!C4:C32,COUNTA(改版履歴!C4:C32)) -> JSOL仲渡 | AW2: =INDEX(改版履歴!D4:D32,COUNTA(改版履歴!D4:D32)) -> 45387
Q3: グリーンマイスター | X3: =表紙!G10 -> 化学物質データ申請確認画面
A5: 画面状態 (Screen State) | BG5: 単機能テスト
A6: 項番 (No) | C6: 論理項目名 (Logical Item Name) | Q6: 状態 (State) | BG6: 初回 | BQ6: 修正後 | CA6: テスト観点 | CI6: 備考
Q7: 初期表示：チェックボックスが1つ以上ある場合 | X7: 初期表示：チェックボックスが1つもない場合 | AE7: 申請チェックボックスに1つもチェックがない状態 | AL7: 申請チェックボックスに1つ以上チェックが付いている場合 | AS7: 申請ボタン押下 | AZ7: 申請処理にてエラー | BG7: 確認日 | BK7: 確認者 | BO7: 判定 | BQ7: 確認日 | BU7: 確認者 | BY7: 判定
A8: =IF(ISBLANK(画面項目!A9),"",画面項目!A9) -> 1 | C8: パンくずリストエリア | BQ8: - | BU8: - | BY8: -
A9: =IF(ISBLANK(画面項目!A10),"",画面項目!A10) -> 1.1 | J9: パンくずリスト | Q9: ○ | X9: ○ | AE9: ○ | AL9: ○ | AS9: ○ | AZ9: ○ | BQ9: - | BU9: - | BY9: -
A10: =IF(ISBLANK(画面項目!A11),"",画面項目!A11) -> 2 | C10: =IF(ISBLANK(画面項目!C11),"",画面項目!C11) -> 申請確認エリア | BQ10: - | BU10: - | BY10: -
A11: =IF(ISBLANK(画面項目!A12),"",画面項目!A12) -> 2.1 | J11: =IF(ISBLANK(画面項目!J12),"",画面項目!J12) -> 初期申請製品数 | Q11: ○ | X11: ○ | AE11: ○ | AL11: ○ | AS11: ○ | AZ11: ○ | BQ11: - | BU11: - | BY11: -
A12: =IF(ISBLANK(画面項目!A13),"",画面項目!A13) -> 2.2 | J12: =IF(ISBLANK(画面項目!J13),"",画面項目!J13) -> 申請に対するチェック結果の説明 | Q12: ○ | X12: ○ | AE12: ○ | AL12: ○ | AS12: ○ | AZ12: ○ | BQ12: - | BU12: - | BY12: -
A13: =IF(ISBLANK(画面項目!A14),"",画面項目!A14) -> 2.3 | J13: =IF(ISBLANK(画面項目!J14),"",画面項目!J14) -> 提出先企業名 | Q13: ○ | X13: ○ | AE13: ○ | AL13: ○ | AS13: ○ | AZ13: ○ | BQ13: - | BU13: - | BY13: -
A14: =IF(ISBLANK(画面項目!A15),"",画面項目!A15) -> 2.4 | J14: =IF(ISBLANK(画面項目!J15),"",画面項目!J15) -> エンドユーザー | Q14: ○ | X14: ○ | AE14: ○ | AL14: ○ | AS14: ○ | AZ14: ○ | BQ14: - | BU14: - | BY14: -
A15: =IF(ISBLANK(画面項目!A16),"",画面項目!A16) -> 2.5 | J15: =IF(ISBLANK(画面項目!J16),"",画面項目!J16) -> CSVダウンロードボタン | Q15: ○ | X15: ○ | AE15: ○ | AL15: ○ | AS15: ○ | AZ15: ○ | BQ15: - | BU15: - | BY15: -
A16: =IF(ISBLANK(画面項目!A17),"",画面項目!A17) -> 2.6 | J16: =IF(ISBLANK(画面項目!J17),"",画面項目!J17) -> 申請チェックボックス | Q16: ○ | X16: ○ | AE16: ○ | AL16: ○ | AS16: ○ | AZ16: ○ | BQ16: - | BU16: - | BY16: -
A17: =IF(ISBLANK(画面項目!A18),"",画面項目!A18) -> 2.7 | J17: =IF(ISBLANK(画面項目!J18),"",画面項目!J18) -> 製品名 | Q17: ○ | X17: ○ | AE17: ○ | AL17: ○ | AS17: ○ | AZ17: ○ | BQ17: - | BU17: - | BY17: -
A18: =IF(ISBLANK(画面項目!A19),"",画面項目!A19) -> 2.8 | J18: =IF(ISBLANK(画面項目!J19),"",画面項目!J19) -> CL（製品番号） | Q18: ○ | X18: ○ | AE18: ○ | AL18: ○ | AS18: ○ | AZ18: ○ | BQ18: - | BU18: - | BY18: -
A19: =IF(ISBLANK(画面項目!A20),"",画面項目!A20) -> 2.9 | J19: =IF(ISBLANK(画面項目!J20),"",画面項目!J20) -> 新製品区分 | Q19: ○ | X19: ○ | AE19: ○ | AL19: ○ | AS19: ○ | AZ19: ○ | BQ19: - | BU19: - | BY19: -
A20: =IF(ISBLANK(画面項目!A21),"",画面項目!A21) -> 2.10 | J20: =IF(ISBLANK(画面項目!J21),"",画面項目!J21) -> 製品販売状況 | Q20: ○ | X20: ○ | AE20: ○ | AL20: ○ | AS20: ○ | AZ20: ○ | BQ20: - | BU20: - | BY20: -
A21: =IF(ISBLANK(画面項目!A22),"",画面項目!A22) -> 2.11 | J21: =IF(ISBLANK(画面項目!J22),"",画面項目!J22) -> PCN番号 | Q21: ○ | X21: ○ | AE21: ○ | AL21: ○ | AS21: ○ | AZ21: ○ | BQ21: - | BU21: - | BY21: -
A22: =IF(ISBLANK(画面項目!A23),"",画面項目!A23) -> 2.12 | J22: =IF(ISBLANK(画面項目!J23),"",画面項目!J23) -> 申請された証明書種類 | Q22: ○ | X22: ○ | AE22: ○ | AL22: ○ | AS22: ○ | AZ22: ○ | BQ22: - | BU22: - | BY22: -
... A24: =IF(ISBLANK(画面項目!A25),"",画面項目!A25) -> 2.14 | J24: =IF(ISBLANK(画面項目!J25),"",画面項目!J25) -> 戻る | Q24: ○ | X24: ○ | AE24: ○ | AL24: ○ | AS24: ○ | AZ24: ○ | BQ24: - | BU24: - | BY24: -
A25: =IF(ISBLANK(画面項目!A26),"",画面項目!A26) -> 2.15 | C25: =IF(ISBLANK(画面項目!C26),"",画面項目!C26) | J25: =IF(ISBLANK(画面項目!J26),"",画面項目!J26) -> 申請 | Q25: ○ | X25: ● | AE25: ● | AL25: ○ | AS25: ○ | AZ25: ○ | BQ25: - | BU25: - | BY25: -
A26: =IF(ISBLANK(画面項目!A27),"",画面項目!A27) -> 2.16 | J26: =IF(ISBLANK(画面項目!J27),"",画面項目!J27) -> いいえボタン | Q26: × | X26: × | AE26: × | AL26: × | AS26: ○ | AZ26: × | BQ26: - | BU26: - | BY26: -
A27: =IF(ISBLANK(画面項目!A28),"",画面項目!A28) -> 2.17 | J27: =IF(ISBLANK(画面項目!J28),"",画面項目!J28) -> はいボタン | Q27: × | X27: × | AE27: × | AL27: × | AS27: ○ | AZ27: × | BQ27: - | BU27: - | BY27: -
A28: =IF(ISBLANK(画面項目!A29),"",画面項目!A29) -> 2.18 | J28: =IF(ISBLANK(画面項目!J29),"",画面項目!J29) -> 申請製品数 | Q28: ○ | X28: × | AE28: × | AL28: × | AS28: ○ | AZ28: × | BQ28: - | BU28: - | BY28: -
A29: =IF(ISBLANK(画面項目!A30),"",画面項目!A30) -> 2.19 | J29: =IF(ISBLANK(画面項目!J30),"",画面項目!J30) -> エラーメッセージ | Q29: × | X29: × | AE29: × | AL29: × | AS29: ○ | AZ29: ○ | BQ29: - | BU29: - | BY29: -
D32: Legend Name | K32: Legend Value
D33: Display(Active) | K33: ○
D34: Display(In-Active) | K34: ●
D35: Hidden | K35: ×

Sheet 入力チェック
A1: 画面設計書（入力チェック) Screen Design Document(Input Checks) | K1: システム名 (System Name) | Q1: 業務名 Business Name | X1: 画面名 Screen Name | AE1: 作成者 Created By | AK1: 作成日 Created On | AQ1: 更新者 Updated By | AW1: 更新日 Updated On
K2: =表紙!D4 -> 4S デジタルトランスフォーメーション・プラットフォーム構築 | Q2: SE | X2: SEFE220 | AE2: =改版履歴!C4 -> JSOL劉 | AK2: =改版履歴!D4 -> 43207 | AQ2: =INDEX(改版履歴!C4:C32,COUNTA(改版履歴!C4:C32)) -> JSOL仲渡 | AW2: =INDEX(改版履歴!D4:D32,COUNTA(改版履歴!D4:D32)) -> 45387
Q3: グリーンマイスター | X3: =表紙!G10 -> 化学物質データ申請確認画面
A5: 形式チェック | CP5: 単機能テスト
A6: 項番 (No) | C6: 論理項目名 (Logical Item Name) | J6: チェックルール (Check Rule) | P6: パラメータ条件 (Parameter Condition) | X6: メッセージキー (Message Key) | AF6: メッセージ 置換文字列 (Place Holder) | AO6: チェックタイミング (Check Timing) | CH6: 備考 (Comment) | CP6: 初回 | CZ6: 修正後 | DJ6: テスト観点 | DR6: 備考
CP7: 確認日 | CT7: 確認者 | CX7: 判定 | CZ7: 確認日 | DD7: 確認者 | DH7: 判定
A11: 業務チェック | DZ11: 単機能テスト
A12: 項番 (No) | C12: 論理項目名 (Logical Item Name) | Q12: チェック内容 (Check Details) | AM12: メッセージキー (Message Key) | AU12: メッセージ 置換文字列 (Place Holder) | BD12: チェックタイミング (Check Timing) | CW12: 備考 (Comment) | DZ12: 初回 | EJ12: 修正後 | ET12: テスト観点 | FB12: 備考
BD13: 申請ボタン押下 | DZ13: 確認日 | ED13: 確認者 | EH13: 判定 | EJ13: 確認日 | EN13: 確認者 | ER13: 判定
A14: 1 | C14: 申請チェックボックスの件数のチェック | Q14: 申請チェックボックスに付いているチェックが101以上ある場合はエラー | AM14: message.E.F.000051 | BD14: ○
B18: 利用可能なルール | I18: パラメータ1 | O18: パラメータ2 | U18: パラメータ3 | AA18: パラメータ4 | AG18: デフォルトメッセージID | AM18: デフォルトメッセージ
B19: 必須チェック（@NotBlank） | AG19: errors.required | AM19: {0}は入力必須項目です。
B20: 必須チェック（@NotEmpty） | AG20: errors.zenkakuString | AM20: {0}には全角文字を入力してください。
B21: 必須チェック（@NotNull） | AG21: errors.hankakuString | AM21: {0}には半角文字を入力してください。
B22: 半角数字チェック | AG22: errors.alphaNumericString | AM22: {0}には半角英数字で入力してください。
B23: 半角英数字チェック | AG23: errors.capAlphaNumericString | AM23: {0}には英大文字または数字を入力してください。
B24: 半角文字チェック | AG24: errors.numericString | AM24: {0}には数字を入力してください。
B25: 文字数チェック | AG25: errors.zenkakuKanaString | AM25: {0}には全角カナ文字を入力してください。
B26: 日付チェック | AG26: errors.hankakuKanaString | AM26: {0}には半角カナ文字を入力してください。
B27: 数値桁数チェック | I27: Number of Bytes = | O27: Encoding = | AG27: errors.byteLength | AM27: {0}には{1}文字で入力してください。
B28: 最大値チェック | I28: Min Value = | O28: Max Value = | AG28: errors.range | AM28: {0}には{1}から{2}までの範囲で入力してください。
B29: 最小値チェック | I29: Min Value = | O29: Max Value = | U29: Encoding = | AG29: errors.byteRange | AM29: {0}には{1}から{2}までの範囲で入力してください。
B30: メールアドレス形式チェック | I30: Max Length = | AG30: errors.stringLength | AM30: {0}には{1}文字で入力してください。
B31: 区分値チェック（Enum） | I31: Date Format = | AG31: errors.date | AM31: {0}には正しい日付を入力してください。
B32: 区分値チェック（AppEnum） | I32: Date Format = | O32: Start Date = | U32: End Date = | AG32: errors.dateRange | AM32: {0}には{1}から{2}までの範囲で入力してください。
B33: 半角英数ハイフンチェック | AG33: errors.capAlphaNumericString | AM33: {0}には半角英数および半角ハイフンを入力してください。
I34: Numer of Integer Part Digits = | O34: Numer of Decimal Part Digits = | U34: Number of Integer Digists Check = | AA34: Number of Decimal Digits Check = | AG34: errors.number | AM34: {0}には整数部{1}桁、小数部{2}桁までの範囲で入力してください。
I35: Min Number of Characters = | AG35: errors.minlength | AM35: {0}には{1}文字以上で入力してください。
I36: Max Number of Characters = | AG36: errors.maxlength | AM36: {0}には{1}文字以下で入力してください。
AG37: errors.email | AM37: {0}にはｅメールアドレスの形式で入力してください。
AG38: errors.creditcard | AM38: {0}には正しいクレジットカード番号を入力してください。
I39: 全スキーム許可= | O39: "//"許可= | U39: "#"許可= | AA39: 許可スキーム= | AG39: errors.url | AM39: {0}には適切なURL形式で入力してください。
I40: Prohibited Characters = | AG40: errors.prohibited | AM40: {0}に入力禁止文字"{1}"が含まれています。
I41: Regular Expression = | AG41: errors.invalid | AM41: {0}の入力形式が間違っています。
AG42: errors.displayName | AM42: {0}の入力に誤りがあります。

Sheet 処理詳細
A1: 画面設計書（処理詳細）Screen Design Document(Process Detail) | K1: システム名 (System Name) | Q1: 業務名 Business Name | X1: 画面名 Screen Name | AE1: 作成者 Created By | AK1: 作成日 Created On | AQ1: 更新者 Updated By | AW1: 更新日 Updated On
K2: =表紙!D4 -> 4S デジタルトランスフォーメーション・プラットフォーム構築 | Q2: SE | X2: SEFE220 | AE2: =改版履歴!C4 -> JSOL劉 | AK2: =改版履歴!D4 -> 43207 | AQ2: =INDEX(改版履歴!C4:C32,COUNTA(改版履歴!C4:C32)) -> JSOL仲渡 | AW2: =INDEX(改版履歴!D4:D32,COUNTA(改版履歴!D4:D32)) -> 45387
Q3: グリーンマイスター | X3: =表紙!G10 -> 化学物質データ申請確認画面
A5: 処理詳細
B7: Ａ－１．画面初期表示について
E9: ※以下のフロー図を参照する
E96: A－１－１． | I96: 申請画面からのHTTPパラメータで製品名/CLコードリスト取得
E98: A－１－２． | I98: 製品名/CLコードより証明書の情報取得
F100: 主Type | O100: HrsChemicalSubstanceProduct
F101: 抽出条件（OR） | O101: HrsChemicalSubstanceProduct.clCode=入力リスト.製品名/CLコード ※1
O102: HrsChemicalSubstanceProduct.hrsNo=入力リスト.CLコード | AV102: ADDED HRS-3963
O103: HrsChemicalSubstanceProduct.partNo=入力リスト.製品名/CLコード ※2
F104: ※1 入力値の形式がHRS-No（数字11桁）の場合はCLコードの形式（CL9999-9999-9-99）に変換
F105: ※2 入力値に以下の全角記号が含まれる場合は半角に変換
H106: － → -
H107: （ → (
H108: ） → )
H109: ＋ → +
H110: ＊ → *
H111: ／ → /
F113: ■A－１－２－１．環境証明書申請製品情報テーブル（HrsChemicalSubstanceProduct）
F115: No | G115: 修飾子 | O115: 項目名
F116: 1 | G116: clCode | O116: CLコード
F117: 2 | G117: hrsNo | O117: HRS No
F118: 3 | G118: partNo | O118: 製品名
F119: 4 | G119: available | O119: 申請可能
F120: 5 | G120: request | O120: Request
F121: 6 | G121: nonCompliant | O121: Non-compliant
F123: ■A－１－２－２．取得した製品照明書の情報と画面表示のマッピング
E150: A－１－３． | I150: 製品名/CLコードの重複チェック
F152: ・A－１－２．で環境証明書申請製品情報を取得できた場合 | Y152: ： | Z152: 環境証明書申請製品情報の「CLコード」を基に重複チェックを実施
F153: ・A－１－２．で環境証明書申請製品情報を取得できなかった場合 | Y153: ： | Z153: 入力リスト.製品名/CLコードを基に重複チェックを実施
E155: A－１－４． | I155: 製品名/CLコードごとにの存在チェック
E157: A－１－５． | I157: CLコードより製品マスター情報取得
F159: 主Type | O159: HrsProduct
F160: 抽出条件（OR） | O160: HrsProduct.code=A－１－２．で取得した「環境証明書申請製品情報」の「CLコード」
F162: ■A－１－５－１．製品マスターテーブル抜粋（HrsProduct）
F164: No | G164: 修飾子 | O164: 項目名
F165: 1 | G165: code | O165: CLコード
F166: 2 | G166: newProductClass[lang] | O166: 新製品区分
...

Sheet 出力編集仕様
A1: 画面設計書（出力編集仕様) Screen Design Document(Output Specification) | K1: システム名 (System Name) | Q1: 業務名 Business Name | X1: 画面名 Screen Name | AE1: 作成者 Created By | AK1: 作成日 Created On | AQ1: 更新者 Updated By | AW1: 更新日 Updated On
K2: =表紙!D4 -> 4S デジタルトランスフォーメーション・プラットフォーム構築 | Q2: SE | X2: SEFE220 | AE2: =改版履歴!C4 -> JSOL劉 | AK2: =改版履歴!D4 -> 43207 | AQ2: =INDEX(改版履歴!C4:C32,COUNTA(改版履歴!C4:C32)) -> JSOL仲渡 | AW2: =INDEX(改版履歴!D4:D32,COUNTA(改版履歴!D4:D32)) -> 45387
Q3: グリーンマイスター | X3: =表紙!G10 -> 化学物質データ申請確認画面
A5: 出力編集仕様
A6: 化学物質データの環境証明書申請内容をデータベースに登録する。
A9: タイプ | J9: HrsChemicalSubstance, HrsChemicalSubstanceEntry
A10: 説明 | J10: 申請ボタンを押下する時 INSERT（UPDATEは発生しない） | AD10: 備考
A12: No | B12: 修飾子
B13: HrsChemicalSubstance
A14: 1 | B14: appNo | J14: 暦年と5桁の追番の間にハイフン（例：2018-00001） ※追番はhybrisのGeneratorの機構で生成する値（hrsChemicalSubstanceAppNoSeq） | AD14: 画面項目の2.8毎に処理
A15: 2 | B15: member | J15: ログインユーザのHrsCustomer.uid
A16: 3 | B16: requestDate | J16: システムの日付
A17: 4 | B17: clientCode | J17: 画面.提出先企業名 | AD17: 画面項目の2.3
A18: 5 | B18: endUser | J18: 画面.エンドユーザ | AD18: 画面項目の2.4
A19: 6 | B19: status | J19: 未処理（ChemicalSubstanceStatus.unprocessed） | AD19: 申請ファイル取り込みバッチで更新できる
A20: 7 | B20: downloadExpirationDate | J20: - | AD20: 申請ファイル取り込みバッチで更新する
A21: 8 | B21: fileSize | J21: - | AD21: 同上
A22: 9 | B22: folderCount | J22: - | AD22: 同上
A23: 10 | B23: fileCount | J23: - | AD23: 同上
B26: HrsChemicalSubstanceEntry
A27: 1 | B27: clCode | J27: 画面.CLコード | AD27: 画面項目の2.8毎に処理
A28: 2 | B28: requestedCertificates | J28: 画面.申請した証明書種類配列の各証明書 | AD28: 画面項目の2.12
A29: 3 | B29: partNo | J29: 環境証明書申請製品情報.製品名 | AD29: CLコードを基に再取得
A30: 4 | B30: newProductClass | J30: 製品マスター情報.新製品区分 ※1 | AD30: CLコードを基に再取得
A31: 5 | B31: productSalesStatusClass | J31: 製品マスター情報を基に判定した「製品販売状況」 ※判定方法の詳細は 別ブック「SERP070_帳票定義書_製品一覧（フロント）.xlsx」の 「帳票定義」シートの「販売状況」を参照 | AD31: CLコードを基に再取得
A32: 6 | B32: pcnNo | J32: 製品マスター情報.変更通知No. | AD32: CLコードを基に再取得
A34: 備考
A35: ※1 | C35: 登録対象の言語は画面で選択可能な7言語（英語、日本語、韓国語、中国語、フランス語、ドイツ語、ロシア語）
C36: 基本的に、登録元の「製品マスター情報.新製品区分」にはGPDMから連携された言語のみ値が設定されている想定
C37: 値が設定されていない言語の場合は、英語の値（フォールバック値）を設定（該当言語の内容に翻訳などはしない）

Sheet ダウンロードCSVファイルについて
A1: 画面設計書（出力編集仕様) Screen Design Document(Output Specification) | K1: システム名 (System Name) | Q1: 業務名 Business Name | X1: 画面名 Screen Name | AE1: 作成者 Created By | AK1: 作成日 Created On | AQ1: 更新者 Updated By | AW1: 更新日 Updated On
K2: =表紙!D4 -> 4S デジタルトランスフォーメーション・プラットフォーム構築 | Q2: SE | X2: SEFE220 | AE2: =改版履歴!C4 -> JSOL劉 | AK2: =改版履歴!D4 -> 43207 | AQ2: =INDEX(改版履歴!C4:C32,COUNTA(改版履歴!C4:C32)) -> JSOL仲渡 | AW2: =INDEX(改版履歴!D4:D32,COUNTA(改版履歴!D4:D32)) -> 45387
Q3: グリーンマイスター | X3: =表紙!G10 -> 化学物質データ申請確認画面
A5: ダウンロードCSV
A6: 化学物質データ申請確認画面で「CSVダウンロード」ボタンを押下すると該当するファイルを生成する
B9: ◆出力項目について
C11: ■RoHS、ハロゲンフリー、成分表、JAMP、SDS、chemSHERPA、SVHC調査報告書を申請する場合
D13: 例：
D14: Part No | K14: CLコード | R14: New Product Class | Y14: Product Sales Status Class | AF14: PCN No | AM14: CL check | AT14: Name of company to be submitted | BA14: End customer | BH14: Certificate of RoHS Conformity | BO14: Certificate of Halogen Free | BV14: Product Chemical Substances Table | CC14: JAMP AIS | CJ14: SDS | CQ14: chemSHERPA | CX14: SVHC
D15: NameA | K15: CL0123-4567-8-90 | R15: オリジナル | Y15: 生産終了予定品 | AF15: 2024-01 | AT15: B社 | BA15: A社 | BH15: YES | BO15: YES | BV15: YES | CC15: YES | CJ15: YES | CQ15: YES | CX15: YES
D16: NameA | K16: CL0123-4567-8-90 | R16: オリジナル | Y16: 生産終了予定品 | AF16: 2024-01 | AM16: 重複
D17: NameB | K17: CL0123-4567-8-91 | R17: オリジナル(特定社) | Y17: 生産終了品 | AF17: 2023-12 | AT17: B社 | BA17: A社 | BH17: Non-compliant | BO17: Non-compliant | BV17: YES | CC17: YES | CJ17: Request | CQ17: YES | CX17: YES
D18: NameC | K18: CL0123-4567-8-92 | R18: カスタム(他社販売可) | Y18: 新規設計非推奨 | AF18: - | AT18: B社 | BA18: A社 | BH18: YES | BO18: YES | BV18: YES | CC18: YES | CJ18: Request | CQ18: Request | CX18: Request
D19: NameE | K19: CL0123-4567-8-94 | R19: カスタム(他社販売不可) | Y19: 販売品 | AF19: - | AT19: B社 | BA19: A社 | BH19: YES | BO19: YES | BV19: YES | CC19: YES | CJ19: YES | CQ19: YES | CX19: YES
D20: - | K20: CL0123-4567-8-96 | R20: - | Y20: - | AF20: - | AM20: 該当なし | AT20: B社 | BA20: A社 | BH20: Request | BO20: Request | BV20: Request | CC20: Request | CJ20: Request | CQ20: Request | CX20: Request
C23: ■RoHS、ハロゲンフリー、成分表、JAMPを申請する場合
D25: 例：
D26: Part No | K26: CLコード | R26: New Product Class | Y26: Product Sales Status Class | AF26: PCN No | AM26: CL check | AT26: Name of company to be submitted | BA26: End customer | BH26: Certificate of RoHS Conformity | BO26: Certificate of Halogen Free | BV26: Product Chemical Substances Table | CC26: JAMP AIS
D27: NameA | K27: CL0123-4567-8-90 | R27: オリジナル | Y27: 生産終了予定品 | AF27: 2024-01 | AT27: B社 | BA27: A社 | BH27: YES | BO27: YES | BV27: YES | CC27: YES
D28: NameA | K28: CL0123-4567-8-90 | R28: オリジナル | Y28: 生産終了予定品 | AF28: 2024-01 | AM28: 重複
D29: NameB | K29: CL0123-4567-8-91 | R29: オリジナル(特定社) | Y29: 生産終了品 | AF29: 2023-12 | AT29: B社 | BA29: A社 | BH29: Non-compliant | BO29: Non-compliant | BV29: YES | CC29: YES
D30: NameC | K30: CL0123-4567-8-92 | R30: カスタム(他社販売可) | Y30: 新規設計非推奨 | AF30: - | AT30: B社 | BA30: A社 | BH30: YES | BO30: YES | BV30: YES | CC30: YES
D31: NameE | K31: CL0123-4567-8-94 | R31: カスタム(他社販売不可) | Y31: 販売品 | AF31: - | AT31: B社 | BA31: A社 | BH31: YES | BO31: YES | BV31: YES | CC31: YES
D32: - | K32: CL0123-4567-8-96 | R32: - | Y32: - | AF32: - | AM32: 該当なし | AT32: B社 | BA32: A社 | BH32: Request | BO32: Request | BV32: Request | CC32: Request
B34: ※ | C34: ①該当するCSVの内容は画面で表示されるCL製品一覧の項目＋上記の点線で囲まれた項目である。
C35: ②画面でチェックボックスを選択してないデータ、重複したデータまたはNon-compliantのデータもすべて出力される。
C36: ③製品名の昇順、CLコードの昇順（値がない場合は末尾）にて出力する（当画面の表示順と同じ仕様にする）
C37: ④画面から引き渡されているCLコード、提出先企業名、エンドユーザーなどの項目以外について（詳細は別ブック「SERP110_帳票定義書_環境証明書申請製品一覧.xlsx」を参照）、「CSV DOWNLOAD」ボタン押下時に再度出力内容を取得している。

Sheet 申請CSVファイルについて
A1: 画面設計書（出力編集仕様) Screen Design Document(Output Specification) | K1: システム名 (System Name) | Q1: 業務名 Business Name | X1: 画面名 Screen Name | AE1: 作成者 Created By | AK1: 作成日 Created On | AQ1: 更新者 Updated By | AW1: 更新日 Updated On
K2: =表紙!D4 -> 4S デジタルトランスフォーメーション・プラットフォーム構築 | Q2: SE | X2: SEFE220 | AE2: =改版履歴!C4 -> JSOL劉 | AK2: =改版履歴!D4 -> 43207 | AQ2: =INDEX(改版履歴!C4:C32,COUNTA(改版履歴!C4:C32)) -> JSOL仲渡 | AW2: =INDEX(改版履歴!D4:D32,COUNTA(改版履歴!D4:D32)) -> 45387
Q3: グリーンマイスター | X3: =表紙!G10 -> 化学物質データ申請確認画面
A5: 出力編集仕様
A6: 化学物質データの環境証明書申請画面で、製品を選択して、「申請」ボタンを押下する時、出力依頼パラメータをCSVファイルで作成する。
D9: ※帳票出力完了時には、退避フォルダに移動します。
E10: ファイル保持期間は30日間とし、ファイルガベージ機能が削除するものとします。
D12: ◆ファイル名： 依頼番号.csv
D14: ◆ファイル形式：CSV形式。区切り文字はカンマ区切りで値はダブルコーテーションで括り、文字コードはUTF8。
D16: ◆ファイル項目：
F18: 【1行目】
G19: 項目 | L19: 導出元(Source) | V19: 備考
G20: 依頼番号 | L20: HrsChemicalSubstance.appNo | V20: 出力先：[S3バケット]/sys-interface/gm/send/依頼番号.csv
G21: 出力先は、プロパティで管理する。[if.front.aws.s3.directory.path.gm.send=sys-interface/gm/send]
F23: 【2行目※下記の順番固定】
G24: 項目 | L24: 導出元(Source) | V24: 備考
G25: 成分表情報 | L25: 画面.申請された証明書種類と照合した結果 | V25: 0:出力しない、1:出力する。
G26: RoHS証明書情報 | V26: 0:出力しない、1:出力する。
G27: ハロゲンフリー証明書情報 | V27: 0:出力しない、1:出力する。
G28: ICP情報 | V28: 0:出力しない、1:出力する。
G29: SDS情報 | V29: 0:出力しない、1:出力する。
G30: AIS4出力情報 | V30: 0:出力しない、1:出力する。
G31: chemSHERPA | V31: 0:出力しない、1:出力する。
G32: SVHC調査報告書 | V32: 0:出力しない、1:出力する。
F34: 【3行目】
G35: 項目 | L35: 導出元(Source) | V35: 備考
G36: 製品番号 | L36: 画面.CLコード | V36: ダウンロード対象の品目番号の改行区切りで繰り返し
F38: 【4行目】
G39: 項目 | L39: 導出元(Source) | V39: 備考
G40: 終端文字 | L40: - | V40: "[__EOF__]"固定
