Workbook
Name txtDatabaseName: "テキスト 8"
Name txtTableName: "テキスト 2"
Name txtUserName: "テキスト 4"

Sheet 表紙
D3: ヒロセ電機株式会社
D4: 4S デジタルトランスフォーメーション・プラットフォーム構築
G7: 画面要件定義書（フロント）
G10: 化学物質データ画面
G12: =INDEX(改版履歴!B4:B32,COUNTA(改版履歴!B4:B32)) -> 1.15
AH31: =INDEX(改版履歴!D4:D32,COUNTA(改版履歴!D4:D32)) -> 45391
Z33: 株式会社 ＪＳＯＬ

Sheet 改版履歴
B1: 改版履歴
B3: 版数 | C3: 改版者 | D3: 改版日 | E3: 改版頁 | F3: 改版履歴
B4: 1 | C4: JSOL劉 | D4: 43206 | E4: - | F4: 新規作成
B5: 1.01 | C5: JSOL劉 | D5: 43210 | E5: レイアウト（PC) | F5: 顧客レビュー後対応に以下の対応を行いました： 顧客要望で、申請日の表示方法を修正し、値チェックの方法を追加しました。 顧客要望で、申請履歴のDoc情報をCSVで出力機能を追加しました。 指示通りに、CSV出力内容のイメージを追加しました。 顧客要望で、得意先コードとエンドユーザーをテキストボックス入力からプルダウン表示に修正しました。 顧客要望で、一覧上に不要な項目を削除しました。 顧客要望で、URL上の言語パラメータによって、画面に表示する言語を切り替える機能を追記しました（ラベル化）。
B6: 1.02 | C6: JSOL谷内 | D6: 43271 | E6: レイアウト（PC) | F6: 項目ごとに番号を付与し、説明を右側の欄に記載。
B7: 1.02 | C7: JSOL谷内 | D7: 43271 | E7: 画面項目、画面状態、入力チェック、出力編集仕様 | F7: 説明を全面的に書き直し
B8: 1.03 | C8: JSOL谷内 | D8: 43272 | E8: 画面項目 | F8: 検索対象とする申請履歴データは、ログインしている会員ユーザが申請者となっているデータを対象とする旨を記載。
B9: 1.04 | C9: JSOL王 | D9: 43287 | E9: レイアウト（PC)、画面項目、画面状態、出力編集仕様 | F9: 内部指摘事項を取り込み。
B10: 1.05 | C10: JSOL王 | D10: 43306 | E10: 画面項目、処理詳細 | F10: DB設計に関する場所の改修
B11: 1.06 | C11: JSOL鈴木 | D11: 43364 | E11: レイアウト（PC） | F11: お客様指摘対応 ・新規申請ボタンをファーストビューで表示されるよう画面上部に移動 ・概要の「社員権限」を「販社以上の権限」に修正
B12: 1.07 | C12: JSOL水本 | D12: 43432 | E12: 処理詳細 | F12: 申請書ダウンロードの方法が記載されていなかったため、「２）申請書ダウンロード」を追記
B13: 1.08 | C13: JSOL鈴木俊輔 | D13: 43480 | E13: レイアウト（PC） | F13: 【HRS-3866】 ・検索条件のフォームの削除 ・初期表示時に検索結果1ページ目を表示するように修正
B14: 1.09 | C14: JSOL若林 | D14: 43490 | E14: レイアウト（PC） | F14: 【HRS-3866】2.8 新着情報が削除対象となっていた誤りを修正
B15: 1.10 | C15: JSOL小島 | D15: 43503 | E15: 画面項目 処理詳細 | F15: 【HRS-XXXX】 初期表示時、ログインユーザに紐づく申請履歴データのみ検索結果表示エリアに表示するように修正 ■画面項目 ・3.検索結果表示エリア：備考欄にログインユーザの申請履歴を表示対象とする旨を追記 ・処理項目1.初期画面表示：検索処理は処理詳細シート：初期表示時の検索処理 を参照するように注釈を追記 ■処理詳細 ・3） 初期表示時の検索処理：追加
B16: 1.11 | C16: JSOL王 | D16: 43662 | E16: レイアウト（PC） | F16: 【4S-1760】 代理店権限でも利用できるように追加 ・概要 (Overview)：代理店権限追加 ・2.8 新着情報：代理店の場合、案内文は他の権限の案内文を分けて表示
B17: 1.12 | C17: JSOL神田 | D17: 43784 | E17: レイアウト（PC） 画面項目 | F17: 【4S-1299】 一覧項目「ファイルサイズ」の表示フォーマットについて明記。
B18: 1.1３ | C18: JSOL神田 | D18: 44008 | E18: 処理詳細 | F18: 【4S-2322：環境証明書ファイル退避処理追加】 ・２） 申請書ダウンロード のフォルダパスを修正 if.batch.aws.s3.directory.path.gm.receive.cert ↓ if.batch.aws.s3.directory.path.gm.backup.receive.cert ・ダウンロードファイルがバッチ処理にてフォルダに格納される旨を追記。
B19: 1.14 | C19: JSOL石井 | D19: 45370 | E19: レイアウト（PC)、画面項目、画面状態、処理詳細 | F19: 【4S-3037】 ・申請ドキュメントCSVの出力項目として、「製品名」「新製品区分」「製品販売状況」「PCN番号」を追加 ・軽微な誤記を修正 ・別ブック「SERP100_帳票定義書_環境証明書申請内容.xlsx」に一部の記載を統合
B20: 1.15 | C20: JSOL仲渡 | D20: 45391 | E20: レイアウト（PC）、画面項目、画面状態 | F20: 【4S-3069】 得意先コードを提出先企業名に変更

Sheet レイアウト（PC）
A1: 画面要件定義書（レイアウト) | K1: システム名 (System Name) | Q1: 業務名 Business Name | X1: 画面名 Screen Name | AE1: 作成者 Created By | AK1: 作成日 Created On | AQ1: 更新者 Updated By | AW1: 更新日 Updated On
K2: =表紙!D4 -> 4S デジタルトランスフォーメーション・プラットフォーム構築 | Q2: SE | X2: SEFE200 | AE2: =改版履歴!C4 -> JSOL劉 | AK2: =改版履歴!D4 -> 43206 | AQ2: =INDEX(改版履歴!C4:C32,COUNTA(改版履歴!C4:C32)) -> JSOL仲渡 | AW2: =INDEX(改版履歴!D4:D32,COUNTA(改版履歴!D4:D32)) -> 45391
Q3: グリーンマイスター | X3: =表紙!G10 -> 化学物質データ画面
A5: 概要 (Overview)
A6: 販社代理店以上の権限（社員権限・販社権限・代理店権限）を持つログイン中のユーザーが会員機能から、「CHEMICAL SUBSTANCE DATA[化学物質データ]へ」のリンクを押下すると、化学物質データ画面に遷移する。 この画面にて、グリンマイスターの申請履歴の検索/参照とダウンロードが可能とする。
A11: JSP
A14: 画面構成 (Screen) | BB14: 機能仕様
BB16: ※画面構成要素のうち、説明が必要な画面項目のみ記載する
BC18: 1. パンくずリストエリア
BD19: 1.1 パンくずリスト
BE20: 以下のようにパンくずリストを表示する。
BE21: 『製品トップ > 化学物質データ』
BC23: 2. 検索条件設定エリア | BU23: DELETE HRS-3866
BD24: 2.1 申請日期間(from) | BU24: DELETE HRS-3866
BE25: YYYY/MM/DD形式。直接入力することが可能。また、 | BU25: DELETE HRS-3866
BE26: 2.3 の年月日選択カレンダーで選択することも可能。 | BU26: DELETE HRS-3866
BU27: DELETE HRS-3866
BD28: 2.2 申請日期間(to) | BU28: DELETE HRS-3866
BE29: YYYY/MM/DD形式。直接入力することが可能。また、 | BU29: DELETE HRS-3866
BE30: 2.3 の年月日選択カレンダーで選択することも可能。 | BU30: DELETE HRS-3866
BU31: DELETE HRS-3866
BD32: 2.3 年月日選択カレンダー(hybris標準) | BU32: DELETE HRS-3866
BE33: 選択した日付が親画面の申請日に反映される。 | BU33: DELETE HRS-3866
BU34: DELETE HRS-3866
BD35: 2.4 得意先コード | BU35: DELETE HRS-3866
BE36: ログインユーザーの申請履歴に保存されている「得意先コード」を | BU36: DELETE HRS-3866
BE37: がプルダウンより選択可能。 | BU37: DELETE HRS-3866
BU38: DELETE HRS-3866
BD39: 2.5 エンドユーザー | BU39: DELETE HRS-3866
BE40: ログインユーザーの申請履歴に保存されている「エンドユーザ」が | BU40: DELETE HRS-3866
BE41: プルダウンより選択可能 | BU41: DELETE HRS-3866
BU42: DELETE HRS-3866
BD43: 2.6 リセットボタン | BU43: DELETE HRS-3866
BE44: 設定した検索条件をすべてクリアする | BU44: DELETE HRS-3866
BU45: DELETE HRS-3866
BD46: 2.7 検索ボタン | BU46: DELETE HRS-3866
BE47: 検索条件を使って化学物質申請履歴データを検索し、 | BU47: DELETE HRS-3866
BE48: 結果を表示する | BU48: DELETE HRS-3866
BU49: DELETE HRS-3866
BD50: 2.8 新着情報
...

Sheet 画面項目
A1: 画面設計書（画面項目) Screen Design Document (Screen Items) | K1: システム名 (System Name) | Q1: 業務名 Business Name | X1: 画面名 Screen Name | AE1: 作成者 Created By | AK1: 作成日 Created On | AQ1: 更新者 Updated By | AW1: 更新日 Updated On
K2: =表紙!D4 -> 4S デジタルトランスフォーメーション・プラットフォーム構築 | Q2: SE | X2: SEFE200 | AE2: =改版履歴!C4 -> JSOL劉 | AK2: =改版履歴!D4 -> 43206 | AQ2: =INDEX(改版履歴!C4:C32,COUNTA(改版履歴!C4:C32)) -> JSOL仲渡 | AW2: =INDEX(改版履歴!D4:D32,COUNTA(改版履歴!D4:D32)) -> 45391
Q3: グリーンマイスター | X3: =表紙!G10 -> 化学物質データ画面
A5: 画面項目(Screen Items)
A6: 必須記入 | AF6: OOTB以外 | CT6: 単機能テスト
A7: 項番 (No) | C7: 項目名(Item Name) | Q7: 論理項目種別 (Logical Item Type) | X7: 固定/可変 (Fixed/Variable) | AB7: I/O | AD7: OOTB | AF7: 入力桁数 (Input Digits) | AJ7: 表示ラベルキー （Display Label Key) | AP7: 初期値 (Default Value) | BA7: 導出元 (Source) | BK7: 備考 (Comment) | CT7: 初回 | DD7: 修正後 | DN7: テスト観点 | DV7: 備考
C8: エリア （Area） | J8: 項目名 (Item Name) | CT8: 確認日 | CX8: 確認者 | DB8: 判定 | DD8: 確認日 | DH8: 確認者 | DL8: 判定
A9: 1 | C9: パンくずリストエリア
A10: 1.1 | J10: パンくずリスト | Q10: Anchor Text | X10: Fixed | AB10: O | AD10: ○ | AF10: - | AP10: - | BA10: -
A11: 2 | C11: 検索条件設定エリア | ED11: DELETE HRS-3866
A12: 2.1 | J12: 申請日期間(from) | Q12: Time Input | X12: Variable | AB12: I | AD12: × | AP12: - | ED12: DELETE HRS-3866
A13: 2.2 | J13: 申請日期間(to) | Q13: Time Input | X13: Variable | AB13: I | AD13: × | AF13: - | AP13: - | ED13: DELETE HRS-3866
A14: 2.3 | J14: カレンダー | Q14: Calendar | X14: Variable | AB14: I | AD14: ○ | AF14: - | AP14: - | ED14: DELETE HRS-3866
A15: 2.4 | J15: 得意先コード | Q15: Dropdown List | X15: Variable | AB15: I | AD15: × | BA15: HrsChemicalSubstance.clientcode | BK15: ログインしている会員の申請履歴データを対象として、HrsChemicalSubstance.clientcodeの値をDISTINCTした結果を選択肢とする | ED15: DELETE HRS-3866
A16: 2.5 | J16: エンドユーザー | Q16: Dropdown List | X16: Variable | AB16: I | AD16: × | BA16: HrsChemicalSubstance.endUser | BK16: ログインしている会員の申請履歴データを対象として、HrsChemicalSubstance.endUserの値をDISTINCTした結果を選択肢とする | ED16: DELETE HRS-3866
A17: 2.6 | J17: リセット | Q17: Image Button | X17: Fixed | AB17: O | AD17: × | AF17: - | AP17: - | BA17: - | BK17: 設定した検索条件をクリアし、初期状態に戻す（検索条件が何も設定されていない状態） | ED17: DELETE HRS-3866
A18: 2.7 | J18: 検索 | Q18: Image Button | X18: Fixed | AB18: O | AD18: × | AF18: - | AP18: - | BA18: - | BK18: 設定されている検索条件を使って検索処理を行い、結果を表示する。 | ED18: DELETE HRS-3866
A19: 3 | C19: 検索結果表示エリア | BK19: ・ログインユーザの申請履歴を表示対象とする
A20: 3.1 | J20: 検索ヒット件数 | Q20: Text Output | AP20: - | BA20: - | BK20: 取得した件数を表示する。
A21: 3.2 | J21: ページング | Q21: Other | AP21: - | BA21: - | BK21: 検索結果のページング。1ページあたり100件とする。 100件を超える場合、2ページ目(とそれ以降)へのナビゲーションが表示される。
A22: 3.3 | J22: 申請履歴データ | Q22: Loop Table | BA22: List<HrsChemicalSubstance> | BK22: 検索結果が一覧表示される。1ページの上限は100件。 画面の初期表示時はデータがない状態。 受付が最新のものが最上位（日付降順） 暦年-シーケンス番号 *採番については、2019年だけ2018-50000から採番する。 2020年以後は20xx-00000という形で採番される。
A23: 3.4 | J23: 受付番号 | Q23: Text Output | BA23: HrsChemicalSubstance.appNo
A24: 3.5 | J24: 提出先企業名 | Q24: Text Output | BA24: HrsChemicalSubstance.clientCode
A25: 3.6 | J25: エンドユーザー | Q25: Text Output | BA25: HrsChemicalSubstance.endUser
A26: 3.7 | J26: 申請日 | Q26: Text Output | BA26: HrsChemicalSubstance.creationtime
A27: 3.8 | J27: 有効期限日 | Q27: Text Output | BA27: HrsChemicalSubstance.expDate | BK27: ダウンロード有効期限。ステータスが「処理中」の場合はNULL。
A28: 3.9 | J28: ファイルサイズ | Q28: Text Output | BA28: HrsChemicalSubstance.fileSize | BK28: ステータスが「処理中」または「有効期限切れ」の場合は"-"を表示する ステータスが「処理済」の場合の数字表示方式は以下の通り。 ・数字の後に(MB)を追加 ・単位はMB ・小数点第一位まで表記し、第二位を切り上げ ・カンマ付きのフォーマットとする ・右寄せで表示 例）ファイルサイズ：100,000バイト → 100000÷1024÷1024=0.0953… 表示：0.10(MB)
A29: 3.10 | J29: ステータス | Q29: Text Output | BA29: HrsChemicalSubstance.status | BK29: [HrsChemicalSubstance.status == ChemicalSubstanceStatus.processed] [現在日時 < HrsChemicalSubstance.expDate] が表示され、クリックすることでファイルをダウンロード可能。 [現在日時 >= HrsChemicalSubstance.expDate] 「有効期限切れ」を表示する [HrsChemicalSubstance.status == ChemicalSubstanceStatus.processing] 「処理中」を表示する
A30: 3.11 | J30: ドキュメント | Q30: Image Button | BA30: - | BK30: をクリックすると、化学物質のリクエスト内容を記載したCSVをダウンロードする
A31: 3.12 | J31: 新規申請 | Q31: Image Button | X31: Fixed | AB31: O | AD31: × | BA31: - | BK31: 新規申請情報作成用画面に遷移する。
A32: 4 | C32: 申請ドキュメント詳細
A33: 4.2 | J33: CL番号 | Q33: Text Output | X33: Variable | AB33: O | AD33: × | AP33: - | BA33: HrsChemicalSubstanceEntry.clCode | BK33: 指定した受付番号で申請されたCL番号。
A34: 4.6 | J34: 化学物質の申請履歴情報 | Q34: Text Output | X34: Variable | AB34: O | AD34: × | AP34: - | BA34: HrsChemicalSubstanceEntry.requestedCertificates | BK34: 申請においてリクエストした証明書の一覧。 ※詳細は「処理詳細」シートを参照する
A36: 処理項目(Process Items) | CT36: 単機能テスト
A37: 項番 (No) | C37: 処理名 (Process Name) | J37: イベント発生元（論理項目名） (Event Source(Logical Item Name)) | X37: イベント (Event) | AE37: サーバ ／クライアント | AM37: 遷移先画面ID (Transition Destination Screen ID) | AW37: 概要 (Comment) | CT37: 初回 | DD37: 修正後 | DN37: テスト観点 | DV37: 備考
CT38: 確認日 | CX38: 確認者 | DB38: 判定 | DD38: 確認日 | DH38: 確認者 | DL38: 判定
A39: 1 | C39: 初期画面表示 | Q39: 本画面に遷移 | X39: Onload | AE39: サーバ | AM39: - | AW39: ・化学物質申請履歴データ検索処理を実行し、結果セットを検索結果エリアに表示する。 ※検索処理は「処理詳細」シート：初期表示時の検索処理 を参照する ※100件を超える場合はページングを行うので、初期表示時は1ページ目を表示する。 | DD39: =IF(EXACT($DB39,"OK"),"-","") | DH39: =IF(EXACT($DB39,"OK"),"-","") | DL39: =IF(EXACT($DB39,"OK"),"-","")
A40: 2 | C40: リセット | Q40: リセットボタン | X40: Click | AE40: クライアント | AM40: - | AW40: 設定されている検索条件をクリアする（条件が何も設定されていない状態） | DD40: =IF(EXACT($DB40,"OK"),"-","") | DH40: =IF(EXACT($DB40,"OK"),"-","") | DL40: =IF(EXACT($DB40,"OK"),"-","") | ED40: DELETE HRS-3866
A41: 2 | C41: 検索 | Q41: 検索ボタン | X41: Click | AE41: サーバ | AM41: - | AW41: 「申請日From-TO」、「得意先コード」、「エンドユーザ」を検索パラメタとして、化学物質申請履歴データ検索処理を実行し、結果セットを検索結果エリアに表示する。 | DD41: =IF(EXACT($DB41,"OK"),"-","") | DH41: =IF(EXACT($DB41,"OK"),"-","") | DL41: =IF(EXACT($DB41,"OK"),"-","") | ED41: DELETE HRS-3866
A42: 3 | C42: 証明書ダウンロード | X42: Click | AE42: サーバ | AM42: - | AW42: ダウンロードボタンを押下すると、対応する証明書ファイルをダウンロードする。 ※ダウンロードする証明書ファイルの参照方法は「処理詳細」シート：ドキュメントダウンロードを参照する。 | DD42: =IF(EXACT($DB42,"OK"),"-","") | DH42: =IF(EXACT($DB42,"OK"),"-","") | DL42: =IF(EXACT($DB42,"OK"),"-","")
...

Sheet 画面状態
A1: 画面設計書（画面状態) Screen Design Document(Screen State) | K1: システム名 (System Name) | Q1: 業務名 Business Name | X1: 画面名 Screen Name | AE1: 作成者 Created By | AK1: 作成日 Created On | AQ1: 更新者 Updated By | AW1: 更新日 Updated On
K2: =表紙!D4 -> 4S デジタルトランスフォーメーション・プラットフォーム構築 | Q2: SE | X2: SEFE200 | AE2: =改版履歴!C4 -> JSOL劉 | AK2: =改版履歴!D4 -> 43206 | AQ2: =INDEX(改版履歴!C4:C32,COUNTA(改版履歴!C4:C32)) -> JSOL仲渡 | AW2: =INDEX(改版履歴!D4:D32,COUNTA(改版履歴!D4:D32)) -> 45391
Q3: グリーンマイスター | X3: =表紙!G10 -> 化学物質データ画面
A5: 画面状態 (Screen State) | AE5: 単機能テスト
A6: 項番 (No) | C6: 論理項目名 (Logical Item Name) | Q6: 状態 (State) | AE6: 初回 | AO6: 修正後 | AY6: テスト観点 | BG6: 備考
Q7: 初期表示 | X7: 検索結果 （１件以上） | AE7: 確認日 | AI7: 確認者 | AM7: 判定 | AO7: 確認日 | AS7: 確認者 | AW7: 判定
A8: =IF(ISBLANK(画面項目!A9),"",画面項目!A9) -> 1 | C8: パンくずリストエリア | AO8: - | AS8: - | AW8: -
A9: =IF(ISBLANK(画面項目!A10),"",画面項目!A10) -> 1.1 | J9: パンくずリスト | Q9: ○ | X9: ○ | AO9: - | AS9: - | AW9: -
A10: =IF(ISBLANK(画面項目!A11),"",画面項目!A11) -> 2 | C10: =IF(ISBLANK(画面項目!C11),"",画面項目!C11) -> 検索条件設定エリア | AO10: - | AS10: - | AW10: - | BO10: DELETE HRS-3866
A11: =IF(ISBLANK(画面項目!A12),"",画面項目!A12) -> 2.1 | J11: =IF(ISBLANK(画面項目!J12),"",画面項目!J12) -> 申請日期間(from) | Q11: ○ | X11: ○ | AO11: - | AS11: - | AW11: - | BO11: DELETE HRS-3866
A12: =IF(ISBLANK(画面項目!A13),"",画面項目!A13) -> 2.2 | J12: =IF(ISBLANK(画面項目!J13),"",画面項目!J13) -> 申請日期間(to) | Q12: ○ | X12: ○ | AO12: - | AS12: - | AW12: - | BO12: DELETE HRS-3866
A13: =IF(ISBLANK(画面項目!A14),"",画面項目!A14) -> 2.3 | J13: =IF(ISBLANK(画面項目!J14),"",画面項目!J14) -> カレンダー | Q13: ○ | X13: ○ | AO13: - | AS13: - | AW13: - | BO13: DELETE HRS-3866
A14: =IF(ISBLANK(画面項目!A15),"",画面項目!A15) -> 2.4 | J14: =IF(ISBLANK(画面項目!J15),"",画面項目!J15) -> 得意先コード | Q14: ○ | X14: ○ | AO14: - | AS14: - | AW14: - | BO14: DELETE HRS-3866
A15: =IF(ISBLANK(画面項目!A16),"",画面項目!A16) -> 2.5 | J15: =IF(ISBLANK(画面項目!J16),"",画面項目!J16) -> エンドユーザー | Q15: ○ | X15: ○ | AO15: - | AS15: - | AW15: - | BO15: DELETE HRS-3866
A16: =IF(ISBLANK(画面項目!A17),"",画面項目!A17) -> 2.6 | J16: =IF(ISBLANK(画面項目!J17),"",画面項目!J17) -> リセット | Q16: ○ | X16: ○ | AO16: - | AS16: - | AW16: - | BO16: DELETE HRS-3866
A17: =IF(ISBLANK(画面項目!A18),"",画面項目!A18) -> 2.7 | J17: =IF(ISBLANK(画面項目!J18),"",画面項目!J18) -> 検索 | Q17: ○ | X17: ○ | AO17: - | AS17: - | AW17: - | BO17: DELETE HRS-3866
A18: =IF(ISBLANK(画面項目!A19),"",画面項目!A19) -> 3 | C18: =IF(ISBLANK(画面項目!C19),"",画面項目!C19) -> 検索結果表示エリア | J18: =IF(ISBLANK(画面項目!J19),"",画面項目!J19) | AO18: - | AS18: - | AW18: -
A19: =IF(ISBLANK(画面項目!A20),"",画面項目!A20) -> 3.1 | J19: =IF(ISBLANK(画面項目!J20),"",画面項目!J20) -> 検索ヒット件数 | Q19: ● | X19: ○ | AO19: - | AS19: - | AW19: -
A20: =IF(ISBLANK(画面項目!A21),"",画面項目!A21) -> 3.2 | J20: =IF(ISBLANK(画面項目!J21),"",画面項目!J21) -> ページング | Q20: ● | X20: ○ | AO20: - | AS20: - | AW20: -
A21: =IF(ISBLANK(画面項目!A22),"",画面項目!A22) -> 3.3 | J21: =IF(ISBLANK(画面項目!J22),"",画面項目!J22) -> 申請履歴データ | Q21: ● | X21: ○ | AO21: - | AS21: - | AW21: -
A22: =IF(ISBLANK(画面項目!A23),"",画面項目!A23) -> 3.4 | J22: =IF(ISBLANK(画面項目!J23),"",画面項目!J23) -> 受付番号 | Q22: ● | X22: ○ | AO22: - | AS22: - | AW22: -
A23: =IF(ISBLANK(画面項目!A24),"",画面項目!A24) -> 3.5 | J23: =IF(ISBLANK(画面項目!J24),"",画面項目!J24) -> 提出先企業名 | Q23: ● | X23: ○ | AO23: - | AS23: - | AW23: -
A24: =IF(ISBLANK(画面項目!A25),"",画面項目!A25) -> 3.6 | J24: =IF(ISBLANK(画面項目!J25),"",画面項目!J25) -> エンドユーザー | Q24: ● | X24: ○ | AO24: - | AS24: - | AW24: -
A25: =IF(ISBLANK(画面項目!A26),"",画面項目!A26) -> 3.7 | J25: =IF(ISBLANK(画面項目!J26),"",画面項目!J26) -> 申請日 | Q25: ● | X25: ○ | AO25: - | AS25: - | AW25: -
A26: =IF(ISBLANK(画面項目!A27),"",画面項目!A27) -> 3.8 | J26: =IF(ISBLANK(画面項目!J27),"",画面項目!J27) -> 有効期限日 | Q26: ● | X26: ○ | AO26: - | AS26: - | AW26: -
A27: =IF(ISBLANK(画面項目!A28),"",画面項目!A28) -> 3.9 | J27: =IF(ISBLANK(画面項目!J28),"",画面項目!J28) -> ファイルサイズ | Q27: ● | X27: ○ | AO27: - | AS27: - | AW27: -
A28: =IF(ISBLANK(画面項目!A29),"",画面項目!A29) -> 3.10 | J28: =IF(ISBLANK(画面項目!J29),"",画面項目!J29) -> ステータス | Q28: ● | X28: ○ | AO28: - | AS28: - | AW28: - | AY28: 証明書ファイルがダウンロードできる場合は、 が表示される
A29: =IF(ISBLANK(画面項目!A30),"",画面項目!A30) -> 3.11 | J29: =IF(ISBLANK(画面項目!J30),"",画面項目!J30) -> ドキュメント | Q29: ● | X29: ○ | AO29: - | AS29: - | AW29: - | AY29: を押下することが可能
A30: =IF(ISBLANK(画面項目!A31),"",画面項目!A31) -> 3.12 | J30: =IF(ISBLANK(画面項目!J31),"",画面項目!J31) -> 新規申請 | Q30: ○ | X30: ○ | AO30: - | AS30: - | AW30: -
A31: =IF(ISBLANK(画面項目!A32),"",画面項目!A32) -> 4 | C31: =IF(ISBLANK(画面項目!C32),"",画面項目!C32) -> 申請ドキュメント詳細 | AO31: - | AS31: - | AW31: -
A32: =IF(ISBLANK(画面項目!A33),"",画面項目!A33) -> 4.2 | J32: =IF(ISBLANK(画面項目!J33),"",画面項目!J33) -> CL番号 | Q32: ● | X32: ○ | AO32: - | AS32: - | AW32: -
A33: =IF(ISBLANK(画面項目!A34),"",画面項目!A34) -> 4.6 | J33: =IF(ISBLANK(画面項目!J34),"",画面項目!J34) -> 化学物質の申請履歴情報 | Q33: ● | X33: ○ | AO33: - | AS33: - | AW33: -
D36: Legend Name | K36: Legend Value
D37: Display(Active) | K37: ○
D38: Display(In-Active) | K38: ●
D39: Hidden | K39: ×

Sheet 入力チェック
A1: 画面設計書（入力チェック) Screen Design Document(Input Checks) | K1: システム名 (System Name) | Q1: 業務名 Business Name | X1: 画面名 Screen Name | AE1: 作成者 Created By | AK1: 作成日 Created On | AQ1: 更新者 Updated By | AW1: 更新日 Updated On
K2: =表紙!D4 -> 4S デジタルトランスフォーメーション・プラットフォーム構築 | Q2: SE | X2: SEFE200 | AE2: =改版履歴!C4 -> JSOL劉 | AK2: =改版履歴!D4 -> 43206 | AQ2: =INDEX(改版履歴!C4:C32,COUNTA(改版履歴!C4:C32)) -> JSOL仲渡 | AW2: =INDEX(改版履歴!D4:D32,COUNTA(改版履歴!D4:D32)) -> 45391
Q3: グリーンマイスター | X3: =表紙!G10 -> 化学物質データ画面
A5: 形式チェック | CP5: 単機能テスト
A6: 項番 (No) | C6: 論理項目名 (Logical Item Name) | J6: チェックルール (Check Rule) | P6: パラメータ条件 (Parameter Condition) | X6: メッセージキー (Message Key) | AF6: メッセージ 置換文字列 (Place Holder) | AO6: チェックタイミング (Check Timing) | CH6: 備考 (Comment) | CP6: 初回 | CZ6: 修正後 | DJ6: テスト観点 | DR6: 備考
AO7: 入力欄フォーカスアウト時 | AT7: サーバサイドバリデーション | AY7: 検索ボタン押下時 | CP7: 確認日 | CT7: 確認者 | CX7: 判定 | CZ7: 確認日 | DD7: 確認者 | DH7: 判定
A8: 1 | C8: 申請日(from) | J8: 日付チェック | P8: - | U8: - | X8: errors.date | AF8: - | AO8: - | AT8: - | AY8: ○ | DZ8: DELETE HRS-3866
A9: 2 | C9: 申請日(to) | J9: 日付チェック | P9: - | U9: - | X9: errors.date | AF9: - | AO9: - | AT9: - | AY9: ○ | DZ9: DELETE HRS-3866
A16: 業務チェック | DZ16: 単機能テスト
A17: 項番 (No) | C17: 論理項目名 (Logical Item Name) | Q17: チェック内容 (Check Details) | AM17: メッセージキー (Message Key) | AU17: メッセージ 置換文字列 (Place Holder) | BD17: チェックタイミング (Check Timing) | CW17: 備考 (Comment) | DZ17: 初回 | EJ17: 修正後 | ET17: テスト観点 | FB17: 備考
BD18: 検索ボタン押下時 | DZ18: 確認日 | ED18: 確認者 | EH18: 判定 | EJ18: 確認日 | EN18: 確認者 | ER18: 判定
A19: 1 | C19: 申請日(from) と申請日(to)の相関チェック | Q19: どちらも設定されている場合、 申請日(from)の値 > 申請日(to) の場合はエラーとする | AM19: message.E.B.000001 | BD19: ○ | FJ19: DELETE HRS-3866
B26: 利用可能なルール | I26: パラメータ1 | O26: パラメータ2 | U26: パラメータ3 | AA26: パラメータ4 | AG26: デフォルトメッセージID | AM26: デフォルトメッセージ
B27: 必須チェック（@NotBlank） | AG27: errors.required | AM27: {0}は入力必須項目です。
B28: 必須チェック（@NotEmpty） | AG28: errors.zenkakuString | AM28: {0}には全角文字を入力してください。
B29: 必須チェック（@NotNull） | AG29: errors.hankakuString | AM29: {0}には半角文字を入力してください。
B30: 半角数字チェック | AG30: errors.alphaNumericString | AM30: {0}には半角英数字で入力してください。
B31: 半角英数字チェック | AG31: errors.capAlphaNumericString | AM31: {0}には英大文字または数字を入力してください。
B32: 半角文字チェック | AG32: errors.numericString | AM32: {0}には数字を入力してください。
B33: 文字数チェック | AG33: errors.zenkakuKanaString | AM33: {0}には全角カナ文字を入力してください。
B34: 日付チェック | AG34: errors.hankakuKanaString | AM34: {0}には半角カナ文字を入力してください。
B35: 数値桁数チェック | I35: Number of Bytes = | O35: Encoding = | AG35: errors.byteLength | AM35: {0}には{1}文字で入力してください。
B36: 最大値チェック | I36: Min Value = | O36: Max Value = | AG36: errors.range | AM36: {0}には{1}から{2}までの範囲で入力してください。
B37: 最小値チェック | I37: Min Value = | O37: Max Value = | U37: Encoding = | AG37: errors.byteRange | AM37: {0}には{1}から{2}までの範囲で入力してください。
B38: メールアドレス形式チェック | I38: Max Length = | AG38: errors.stringLength | AM38: {0}には{1}文字で入力してください。
B39: 区分値チェック（Enum） | I39: Date Format = | AG39: errors.date | AM39: {0}には正しい日付を入力してください。
B40: 区分値チェック（AppEnum） | I40: Date Format = | O40: Start Date = | U40: End Date = | AG40: errors.dateRange | AM40: {0}には{1}から{2}までの範囲で入力してください。
I41: Numer of Integer Part Digits = | O41: Numer of Decimal Part Digits = | U41: Number of Integer Digists Check = | AA41: Number of Decimal Digits Check = | AG41: errors.number | AM41: {0}には整数部{1}桁、小数部{2}桁までの範囲で入力してください。
I42: Min Number of Characters = | AG42: errors.minlength | AM42: {0}には{1}文字以上で入力してください。
I43: Max Number of Characters = | AG43: errors.maxlength | AM43: {0}には{1}文字以下で入力してください。
AG44: errors.email | AM44: {0}にはｅメールアドレスの形式で入力してください。
AG45: errors.creditcard | AM45: {0}には正しいクレジットカード番号を入力してください。
I46: 全スキーム許可= | O46: "//"許可= | U46: "#"許可= | AA46: 許可スキーム= | AG46: errors.url | AM46: {0}には適切なURL形式で入力してください。
I47: Prohibited Characters = | AG47: errors.prohibited | AM47: {0}に入力禁止文字"{1}"が含まれています。
I48: Regular Expression = | AG48: errors.invalid | AM48: {0}の入力形式が間違っています。
AG49: errors.displayName | AM49: {0}の入力に誤りがあります。

Sheet 処理詳細
A1: 画面設計書（処理詳細）Screen Design Document(Process Detail) | K1: システム名 (System Name) | Q1: 業務名 Business Name | X1: 画面名 Screen Name | AE1: 作成者 Created By | AK1: 作成日 Created On | AQ1: 更新者 Updated By | AW1: 更新日 Updated On
K2: =表紙!D4 -> 4S デジタルトランスフォーメーション・プラットフォーム構築 | Q2: SE | X2: SEFE200 | AE2: =改版履歴!C4 -> JSOL劉 | AK2: =改版履歴!D4 -> 43206 | AQ2: =INDEX(改版履歴!C4:C32,COUNTA(改版履歴!C4:C32)) -> JSOL仲渡 | AW2: =INDEX(改版履歴!D4:D32,COUNTA(改版履歴!D4:D32)) -> 45391
Q3: グリーンマイスター | X3: =表紙!G10 -> 化学物質データ画面
A5: 処理詳細
B7: １） 化学物質の申請履歴情報の取得
D9: 主Type | M9: HrsChemicalSubstance、HrsChemicalSubstanceEntry
D10: 抽出条件 | M10: HrsChemicalSubstance.appNo=検索結果対象明細.申請番号
D12: 画面で検索結果一覧の各申請番号を利用して申請番号ごとの環境証明書申請詳細情報を取得する。
D14: １－１）CSVヘッダーのファイル出力例と導出元
F16: 項目 | L16: 導出元(Source)
F17: CLコード | L17: CL Code（固定）
F18: 証明書種類 | L18: 証明書種類画面表示順序（AppEnumGroup.ChemicalSubstanceDataで定義されたもの）
D20: １－２）CSV本文のファイル出力例と導出元
F22: 項目 | L22: 導出元(Source) | N22: 導出元(Source)
F23: CLコード | L23: 環境証明書申請詳細.CLコード（※１）から取得したデータ）
F24: 証明書種類結果 | L24: 対応する証明書がHrsChemicalSubstanceEntry.requestedCertificatesに存在する場合、「YES」を出力する。 対応する証明書がHrsChemicalSubstanceEntry.requestedCertificatesに存在しない場合、「ー」（ハイフォン）を出力する。
B26: ２） 申請書ダウンロード
D28: 以下の通りS3から申請書ファイルロードする。
E29: パス：[S3バケット][フォルダパス]/{受付番号}.zip
F30: 受付番号 | J30: ： | K30: 該当のHrsChemicalSubstance.appNo
E31: 上記パスはlocal.propertiesから取得すること
E32: 取得キーは、以下の通り。
F33: S3バケット | J33: ： | K33: if.batch.aws.s3.gm.bucketName
F34: フォルダパス | J34: ： | K34: if.batch.aws.s3.directory.path.gm.backup.receive.cert
F35: 例：S3バケット：/sys-interface/gm/data/rcv/cert/2019-00001.zip
F36: ※プロパティ名は ~backup.receive.cert となっているがフォルダはデータ取込済みフォルダを定義している。
F37: ※ダウンロードファイルはバッチ処理にてフォルダパスに配置される。
F38: バッチ処理の詳細についてはバッチ定義書を参照。
F39: 参照ファイル：「SEBT060_バッチ機能定義書_環境証明書取込みバッチ.xlsx」
B42: 3） 初期表示時の検索処理
C44: ログインユーザに紐付く申請履歴データを取得する。
C46: 主Type | L46: HrsChemicalSubstance
C47: 抽出条件 | L47: HrsChemicalSubstance.member = ログインユーザ
